Workbook

Sheet Main
C3: Price | D3: 78 | G3: Innoscripta takes a commission of R&D Tax credit received
C4: Shares | D4: =+Model!Q49 -> 10000 | G4: I gues ist between 5-8%
C5: MC | D5: =+D3*D4 -> 780000 | G5: I would take 5% as an estimate as this is a nice number
C6: Net Cash | D6: =+Model!T56 -> 17386 | G6: SaaS does not have that much of a moat itself.
C7: EV | D7: =+D5+D6 -> 797386 | G7: Focus on enterprise customers with their sales team
C9: EV/FCF | D9: =+D7/Model!G58 -> 19.543775
C10: FCF Yield | D10: =1/D9 -> 0.051167189 | G10: 1052 companies in germany with >5M R&D Spent

Sheet Model
D2: =+E2-1 -> 2022 | E2: 2023 | F2: =+E2+1 -> 2024 | G2: =+F2+1 -> 2025 | H2: =+G2+1 -> 2026 | I2: =+H2+1 -> 2027 | J2: =+I2+1 -> 2028 | K2: =+J2+1 -> 2029 | L2: =+K2+1 -> 2030 | M2: =+L2+1 -> 2031 | ... Q2: =+P2+1 -> 2035
B4: R&D Companies DE | G4: 43000 | H4: =+G4*1.03 -> 44290 | I4: =+H4*1.03 -> 45618.7 | J4: =+I4*1.03 -> 46987.261 | K4: =+J4*1.03 -> 48396.879 | L4: =+K4*1.03 -> 49848.785 | M4: =+L4*1.03 -> 51344.249 | N4: =+M4*1.03 -> 52884.576 | O4: =+N4*1.03 -> 54471.113 | ... Q4: =+P4*1.03 -> 57788.404
B5: TAM | G5: =+G4*0.9 -> 38700 | H5: =+H4*0.9 -> 39861 | I5: =+I4*0.9 -> 41056.83 | J5: =+J4*0.9 -> 42288.535 | K5: =+K4*0.9 -> 43557.191 | L5: =+L4*0.9 -> 44863.907 | M5: =+M4*0.9 -> 46209.824 | N5: =+N4*0.9 -> 47596.119 | ... Q5: =+Q4*0.9 -> 52009.564
B6: Marktanteil | G6: =+G29/G5 -> 0.054263566 | H6: =+H29/H5 -> 0 | I6: =+I29/I5 -> 0 | J6: =+J29/J5 -> 0 | K6: =+K29/K5 -> 0 | L6: =+L29/L5 -> 0 | M6: =+M29/M5 -> 0 | N6: =+N29/N5 -> 0 | ... Q6: =+Q29/Q5 -> 0
B8: <50 Mitarbeiter | G8: =+G4*0.05 -> 2150
B9: 50-250 | G9: =+G4-G10-G8 -> 34787
B10: >250 | G10: =+G4*0.141 -> 6063
B11: Gesamt ex kleinst | G11: =+G10+G9+G8 -> 43000
A13: bn | B13: GDP Germany | D13: 3989.4 | E13: 4219.3 | F13: 4329 | G13: 4469.9
A14: mn | B14: Total R&D spent DE | D14: 121421 | E14: 132008 | F14: =+F13*0.0313*1000 -> 135497.7 | G14: =+G13*0.031*1000 -> 138566.9
B15: % of GDP | D15: =+D14/(D13*1000) -> 0.030435905 | E15: =+E14/(E13*1000) -> 0.031286706 | F15: =+F14/(F13*1000) -> 0.0313 | G15: =+G14/(G13*1000) -> 0.031
B16: Wirtchaft | D16: 81809 | E16: 90408 | F16: =+F14-F17-F18 -> 93769.18 | G16: =+G14-G17-G18 -> 96702.43 | H16: =+G16*1.04 -> 100570.53 | I16: =+H16*1.04 -> 104593.35 | J16: =+I16*1.04 -> 108777.08 | K16: =+J16*1.04 -> 113128.17 | L16: =+K16*1.04 -> 117653.29 | M16: =+L16*1.04 -> 122359.42 | N16: =+M16*1.04 -> 127253.8 | O16: =+N16*1.04 -> 132343.95 | ... Q16: =+P16*1.04 -> 143143.22
B17: Hochschulen | D17: 22007 | E17: 23026 | F17: =+E17+500 -> 23526 | G17: =+F17+500 -> 24026
B18: Staat | D18: 17605 | E18: 18574 | F18: =+E18*0.98 -> 18202.52 | G18: =+F18*0.98 -> 17838.47
B19: Credit Allegible | F19: =+'R&D Spent'!H13 -> 24578.93 | G19: =+G16*0.26 -> 25142.632 | H19: =+H16*0.26 -> 26148.337 | I19: =+I16*0.26 -> 27194.271 | J19: =+J16*0.26 -> 28282.041 | K19: =+K16*0.26 -> 29413.323 | L19: =+L16*0.26 -> 30589.856 | M19: =+M16*0.26 -> 31813.45 | N19: =+N16*0.26 -> 33085.988 | ... Q19: =+Q16*0.26 -> 37217.237
B20: 1INN Share | F20: =+F32/F19 -> 0.17550533 | G20: =+G32/G19 -> 0.27576005 | H20: =+H32/H19 -> 0.35183882 | I20: =+I32/I19 -> 0.43391493 | J20: =+J32/J19 -> 0.5303719 | K20: =+K32/K19 -> 0.6 | L20: =+L32/L19 -> 0.6 | M20: =+M32/M19 -> 0.6 | ... Q20: =+Q32/Q19 -> 0.6
B22: >75 in R&D employed | F22: 98
B23: 25-75 | F23: 343
B24: <25 | F24: 1341
B25: SME | F25: =+F24+F23/2 -> 1512.5 | G25: 1550
B26: As % of Customer | F26: =+F25/F29 -> 0.84876543 | G26: =+G25/G29 -> 0.73809524
B27: Credit Ratio | F27: =+F26*0.35+(1-F26)*0.25 -> 0.33487654 | G27: =+G26*0.35+(1-G26)*0.25 -> 0.32380952
B29: Zahlende Kunden | F29: =+F24+F23+F22 -> 1782 | G29: 2100
B30: Revenue/Kunde | F30: =+F34/F29 -> 36.310887 | G30: =+G34/G29 -> 49.52381
B31: R&D/Kunde | F31: =+F30*4*20 -> 2904.8709 | G31: =+G30*4*20 -> 3961.9048
B32: Total R&D | F32: =+(F34/0.05)/0.3 /1000 -> 4313.7333 | G32: =+(G34/0.05)/0.3 /1000 -> 6933.3333 | H32: =+(H34/0.05)/0.3 /1000 -> 9200 | I32: =+(I34/0.05)/0.3 /1000 -> 11800 | J32: =+(J34/0.05)/0.3 /1000 -> 15000 | K32: =+K19*0.6 -> 17647.994 | L32: =+L19*0.6 -> 18353.914 | M32: =+M19*0.6 -> 19088.07 | N32: =+N19*0.6 -> 19851.593 | O32: =+O19*0.6 -> 20645.657 | P32: =+P19*0.6 -> 21471.483 | Q32: =+Q19*0.6 -> 22330.342
B34: Revenue | D34: 27274 | E34: 39374 | F34: 64706 | G34: =+G65 -> 104000 | H34: 138000 | I34: 177000 | J34: 225000 | K34: =+K32*0.3*0.05*1000 -> 264719.91 | L34: =+L32*0.3*0.05*1000 -> 275308.7 | M34: =+M32*0.3*0.05*1000 -> 286321.05 | N34: =+N32*0.3*0.05*1000 -> 297773.9 | O34: =+O32*0.3*0.05*1000 -> 309684.85 | P34: =+P32*0.3*0.05*1000 -> 322072.24 | Q34: =+Q32*0.3*0.05*1000 -> 334955.13
B35: Other Income | D35: =188-901 -> -713 | E35: =-95+191 -> 96 | F35: =358+194 -> 552 | G35: =-68+368 -> 300 | H35: 200 | I35: 200 | J35: 200 | K35: 200 | L35: 200 | M35: 200 | N35: 200 | O35: 200 | P35: 200 | Q35: 200
B36: COGS | D36: 671 | E36: 1302 | F36: 1809 | G36: =3093.515*1.33 -> 4114.375 | H36: =+H34*0.05 -> 6900 | I36: =+I34*0.05 -> 8850 | J36: =+J34*0.05 -> 11250 | K36: =+K34*0.05 -> 13235.995 | L36: =+L34*0.05 -> 13765.435 | M36: =+M34*0.05 -> 14316.053 | N36: =+N34*0.05 -> 14888.695 | O36: =+O34*0.05 -> 15484.243 | ... Q36: =+Q34*0.05 -> 16747.757
B37: Gross Profit | D37: =+D34+D35-D36 -> 25890 | E37: =+E34+E35-E36 -> 38168 | F37: =+F34+F35-F36 -> 63449 | G37: =+G34+G35-G36 -> 100185.63 | H37: =+H34+H35-H36 -> 131300 | I37: =+I34+I35-I36 -> 168350 | J37: =+J34+J35-J36 -> 213950 | K37: =+K34+K35-K36 -> 251683.91 | ... Q37: =+Q34+Q35-Q36 -> 318407.38
B38: Gehälter | D38: 10029 | E38: 14480 | F38: 15237 | G38: =16478.369*1.33 -> 21916.231 | H38: =+H34*0.22 -> 30360 | I38: =+I34*0.22 -> 38940 | J38: =+J34*0.22 -> 49500 | K38: =+K34*0.22 -> 58238.38 | L38: =+L34*0.22 -> 60567.915 | M38: =+M34*0.22 -> 62990.632 | N38: =+N34*0.22 -> 65510.257 | O38: =+O34*0.22 -> 68130.667 | ... Q38: =+Q34*0.22 -> 73690.13
B39: Lohnnebenkosten | D39: 1689 | E39: 2308 | F39: 2729 | G39: =2781.293*1.33 -> 3699.1197 | H39: =+H38*0.18 -> 5464.8 | I39: =+I38*0.18 -> 7009.2 | J39: =+J38*0.18 -> 8910 | K39: =+K38*0.18 -> 10482.908 | L39: =+L38*0.18 -> 10902.225 | M39: =+M38*0.18 -> 11338.314 | N39: =+N38*0.18 -> 11791.846 | O39: =+O38*0.18 -> 12263.52 | ... Q39: =+Q38*0.18 -> 13264.223
B40: D&A | D40: 153 | E40: 151 | F40: 182 | G40: 158.247 | H40: 150 | I40: 150 | J40: 150 | K40: 150 | L40: 150 | M40: 150 | N40: 150 | O40: 150 | P40: 150 | Q40: 150
B41: Other Expenses | D41: 4841 | E41: 5758 | F41: 8023 | G41: =7627.759*1.33 -> 10144.919 | H41: =+H34*0.1 -> 13800 | I41: =+I34*0.1 -> 17700 | J41: =+J34*0.1 -> 22500 | K41: =+K34*0.1 -> 26471.991 | L41: =+L34*0.1 -> 27530.87 | M41: =+M34*0.1 -> 28632.105 | N41: =+N34*0.1 -> 29777.39 | O41: =+O34*0.1 -> 30968.485 | ... Q41: =+Q34*0.1 -> 33495.513
B42: EBIT | D42: =+D37-D38-D39-D40-D41 -> 9178 | E42: =+E37-E38-E39-E40-E41 -> 15471 | F42: =+F37-F38-F39-F40-F41 -> 37278 | G42: =+G37-G38-G39-G40-G41 -> 64267.108 | H42: =+H37-H38-H39-H40-H41 -> 81525.2 | I42: =+I37-I38-I39-I40-I41 -> 104550.8 | J42: =+J37-J38-J39-J40-J41 -> 132890 | K42: =+K37-K38-K39-K40-K41 -> 156340.63 | ... Q42: =+Q37-Q38-Q39-Q40-Q41 -> 197807.51
B43: Interest Income | D43: 125 | E43: 60 | F43: 226 | G43: 152 | H43: 150 | I43: 150 | J43: 150 | K43: 150 | L43: 150 | M43: 150 | N43: 150 | O43: 150 | P43: 150 | Q43: 150
B44: Interest Expenses | D44: 57 | E44: 78 | F44: 88 | G44: =34.608+0.717 -> 35.325 | H44: 50 | I44: 50 | J44: 50 | K44: 50 | L44: 50 | M44: 50 | N44: 50 | O44: 50 | P44: 50 | Q44: 50
B45: Pretax | D45: =+D42+D43-D44 -> 9246 | E45: =+E42+E43-E44 -> 15453 | F45: =+F42+F43-F44 -> 37416 | G45: =+G42+G43-G44 -> 64383.783 | H45: =+H42+H43-H44 -> 81625.2 | I45: =+I42+I43-I44 -> 104650.8 | J45: =+J42+J43-J44 -> 132990 | K45: =+K42+K43-K44 -> 156440.63 | ... Q45: =+Q42+Q43-Q44 -> 197907.51
B46: Taxes | D46: 3146 | E46: 5178 | F46: 12323 | G46: =+G45*0.33 -> 21246.648 | H46: =+H45*0.33 -> 26936.316 | I46: =+I45*0.33 -> 34534.764 | J46: =+J45*0.33 -> 43886.7 | K46: =+K45*0.33 -> 51625.409 | L46: =+L45*0.33 -> 53688.446 | M46: =+M45*0.33 -> 55834.003 | N46: =+N45*0.33 -> 58065.384 | ... Q46: =+Q45*0.33 -> 65309.479
B47: Net Income | D47: =+D45-D46 -> 6100 | E47: =+E45-E46 -> 10275 | F47: =+F45-F46 -> 25093 | G47: =+G45-G46 -> 43137.135 | H47: =+H45-H46 -> 54688.884 | I47: =+I45-I46 -> 70116.036 | J47: =+J45-J46 -> 89103.3 | K47: =+K45-K46 -> 104815.22 | ... Q47: =+Q45-Q46 -> 132598.03 | R47: =+Q47*(1+$T54) -> 136575.97 | S47: =+R47*(1+$T54) -> 140673.25 | T47: =+S47*(1+$T54) -> 144893.45 | U47: =+T47*(1+$T54) -> 149240.25 | V47: =+U47*(1+$T54) -> 153717.46 | W47: =+V47*(1+$T54) -> 158328.99 | X47: =+W47*(1+$T54) -> 163078.86 | Y47: =+X47*(1+$T54) -> 167971.22 | ... DE47: =+DD47*(1+$T54) -> 2011693.2
...

Sheet R&D Spent
C2: 2024 | D2: DE Share | E2: DE Spent | F2: Alleg.
B4: VW | C4: 21779 | D4: 0.55 | E4: =+D4*C4 -> 11978.45 | G4: Total | H4: =+SUM(E:E) -> 64426.25
B5: MBG | C5: 9980 | D5: 0.55 | E5: =+D5*C5 -> 5489
B6: Bosch | C6: 7564 | D6: 0.6 | E6: =+D6*C6 -> 4538.4 | G6: Bucket A | H6: =+H4-H7-H8 -> 54919.55 | I6: Companies that are to big
B7: BMW | C7: 7755 | D7: 0.6 | E7: =+D7*C7 -> 4653 | G7: Bucket B | H7: =+SUM(E33:E79) -> 7707.7 | I7: Companies that would use Clusterix for their software and not primarily to get tax credits
B8: Bayer | C8: 5461 | D8: 0.5 | E8: =+D8*C8 -> 2730.5 | G8: Bucket C | H8: =+SUM(E80:E109) -> 1799 | I8: Companies that would use Clusterix for tax credits
B9: SAP | C9: 6282 | D9: 0.35 | E9: =+D9*C9 -> 2198.7
B10: Siemens | C10: 6183 | D10: 0.4 | E10: =+D10*C10 -> 2473.2
B11: Boehringer | C11: 5766 | D11: 0.65 | E11: =+D11*C11 -> 3747.9 | G11: Total R&D | H11: =+Model!F16 -> 93769.18 | I11: in 2024
B12: Continental | C12: 2876 | D12: 0.55 | E12: =+D12*C12 -> 1581.8 | G12: w/o A & B | H12: =+H11-H6-H7 -> 31141.93
B13: ZF | C13: 2730 | D13: 0.6 | E13: =+D13*C13 -> 1638 | G13: Credit all. | H13: =+H12-H19 -> 24578.93
B14: Merck | C14: 2438 | D14: 0.55 | E14: =+D14*C14 -> 1340.9 | G14: Share | H14: =+H13/H11 -> 0.26212163
B15: Infineon | C15: 2190 | D15: 0.55 | E15: =+D15*C15 -> 1204.5
B16: BASF | C16: 2170 | D16: 0.55 | E16: =+D16*C16 -> 1193.5 | G16: Bucket D | H16: 9000 | I16: approx. 323 companies. Avg R&D Spent estimated
B17: Daimler Trucks | C17: 1956 | D17: 0.6 | E17: =+D17*C17 -> 1173.6 | G17: C+D | H17: =+H16+H8 -> 10799
B18: Biontech | C18: 1780 | D18: 0.8 | E18: =+D18*C18 -> 1424 | G18: C+D alleg. | H18: =+SUM(F80:F251)+323*12 -> 4236
B19: Carl Zeiss | C19: 1600 | D19: 0.8 | E19: =+D19*C19 -> 1280 | G19: C+D non | H19: =+H17-H18 -> 6563
B20: Deutsche Bank | C20: 1314 | D20: 0.4 | E20: =+D20*C20 -> 525.6
B21: Siemens Energy | C21: 1313 | D21: 0.6 | E21: =+D21*C21 -> 787.8
B22: Hella | C22: 882 | D22: 0.65 | E22: =+D22*C22 -> 573.3
B23: Vitesco | C23: 842 | D23: 0.6 | E23: =+D23*C23 -> 505.2
B24: Schaeffler | C24: 769 | D24: 0.7 | E24: =+D24*C24 -> 538.3
B25: Deutsche Telekom | C25: 733 | D25: 0.7 | E25: =+D25*C25 -> 513.1
B26: Mahle | C26: 733 | D26: 0.7 | E26: =+D26*C26 -> 513.1
B27: Fesnius | C27: 666 | D27: 0.7 | E27: =+D27*C27 -> 466.2
B28: Henkel | C28: 581 | D28: 0.7 | E28: =+D28*C28 -> 406.7
B29: Knorr Bremse | C29: 544 | D29: 0.7 | E29: =+D29*C29 -> 380.8
B30: Delivery Hero | C30: 535 | D30: 0.7 | E30: =+D30*C30 -> 374.5
B31: Freudenberg | C31: 500 | D31: 0.7 | E31: =+D31*C31 -> 350
... B79: SMA Solar Tech | C79: 120 | D79: 0.7 | E79: =+D79*C79 -> 84
B80: Heideldruck | C80: 113 | D80: 0.7 | E80: =+D80*C80 -> 79.1 | F80: 12
B81: Mann + Hummel | C81: 113 | D81: 0.7 | E81: =+D81*C81 -> 79.1 | F81: 12
B82: Schott | C82: 108 | D82: 0.7 | E82: =+D82*C82 -> 75.6 | F82: 12
B83: Lanxess | C83: 99 | D83: 0.7 | E83: =+D83*C83 -> 69.3 | F83: 12
B84: Wacker | C84: 97 | D84: 0.7 | E84: =+D84*C84 -> 67.9 | F84: 12
B85: Deutz | C85: 93 | D85: 0.7 | E85: =+D85*C85 -> 65.1 | F85: 12
B86: Hensoldt | C86: 92 | D86: 0.7 | E86: =+D86*C86 -> 64.4 | F86: 12
B87: Erlingklinger | C87: 91 | D87: 0.7 | E87: =+D87*C87 -> 63.7 | F87: 12
B88: DMG | C88: 90 | D88: 0.7 | E88: =+D88*C88 -> 63 | F88: 12
B89: New Work | C89: 90 | D89: 0.7 | E89: =+D89*C89 -> 63 | F89: 12
...
