Workbook
Name MV: Modell!$AM$41

Sheet Main
D2: Price | E2: 250 | H2: Proj. Buybacks | I2: 10000 | M2: Adobe Creative Cloud Pro
D3: Shares | E3: =+Modell!Z35 -> 426 | H3: Buyback Yield | I3: =+I2/E4 -> 0.093896714 | M3: Adobe Photoshop and Lightroom
D4: Market Cap | E4: =+E2*E3 -> 106500 | H4: Years till all | I4: =1/I3 -> 10.65 | M4: Adobe Illustrator
D5: Net Cash | E5: =+Modell!Z58-Modell!Z59 -> 385 | M5: Adobe Premiere Pro
D6: EV | E6: =+E4-E5 -> 106115 | M6: Adobe After Effects
M7: Adobe Substance 3D Collection
D8: FCF pS | E8: =+Modell!Z55/Main!E3 -> 18.253521 | M8: Adobe Stock
D9: EV/FCF | E9: =+E6/Modell!Z55 -> 13.646476 | M9: Adobe Firefly Solutions
D10: FCF Yield | E10: =1/E9 -> 0.07327899 | M10: Adobe GenStudio

Sheet Modell
C2: Q124 | D2: Q224 | E2: Q324 | F2: Q424 | G2: Q125 | H2: Q225 | I2: Q325 | J2: Q425 | P2: FY15 | Q2: FY16 | R2: FY17 | S2: FY18 | T2: FY19 | U2: FY20 | V2: FY21 | W2: FY22 | X2: FY23 | Y2: FY24 | Z2: FY25 | AA2: FY26 | AB2: FY27 | AC2: FY28 | AD2: FY29 | AE2: FY30 | AF2: FY31 | AG2: FY32 | AH2: FY33 | AI2: FY34 | AJ2: FY35
B5: Digital Media | X5: 14220 | Y5: 15860 | Z5: 17650
B6: Subs | X6: 13840 | Y6: 15550 | Z6: 17390
B7: Digital Experience | X7: 4890 | Y7: 5370 | Z7: 5860
B8: Subs | X8: 4330 | Y8: 4860 | Z8: 5410
B9: Publishing | X9: 300 | Y9: 280 | Z9: 260
B10: Creative & Marketing | X10: 13425 | Y10: 14749 | Z10: 16303
B11: Businesses | X11: 4744 | Y11: 5662 | Z11: 6495
B12: Sales from Subs | C12: 5483 | G12: 6198 | P12: 3223.904 | Q12: 4584.833 | R12: 6133.869 | S12: 7604 | T12: 9634 | U12: 11626 | V12: =+SUM(G12:J12) -> 6198 | W12: 16388 | X12: 18284 | Y12: 20521 | Z12: 22904 | AA12: =+Z12*1.1 -> 25194.4 | AB12: =+AA12*1.09 -> 27461.896 | AC12: =+AB12*1.09 -> 29933.467 | AD12: =+AC12*1.09 -> 32627.479 | AE12: =+AD12*1.09 -> 35563.952 | AF12: =+AE12*1.09 -> 38764.707 | AG12: =+AF12*1.09 -> 42253.531 | AH12: =+AG12*1.09 -> 46056.349 | AI12: =+AH12*1.09 -> 50201.42 | AJ12: =+AI12*1.09 -> 54719.548
B13: Sales from Product | C13: 95 | G13: 90 | P13: 1125.146 | Q13: 800.498 | R13: 706.767 | S13: 622 | T13: 648 | U13: 507 | V13: =+SUM(G13:J13) -> 90 | W13: 532 | X13: 460 | Y13: 386 | Z13: 325 | AA13: =+Z13*0.9 -> 292.5 | AB13: =+AA13*0.9 -> 263.25 | AC13: =+AB13*0.9 -> 236.925 | AD13: =+AC13*0.9 -> 213.2325 | AE13: =+AD13*0.9 -> 191.90925 | AF13: =+AE13*0.9 -> 172.71833 | AG13: =+AF13*0.9 -> 155.44649 | AH13: =+AG13*0.9 -> 139.90184 | ... AJ13: =+AI13*0.9 -> 113.32049
B14: Sales from Service | C14: 136 | G14: 110 | P14: 446.461 | Q14: 469.099 | R14: 460.869 | S14: 804 | T14: 889 | U14: 735 | V14: =+SUM(G14:J14) -> 110 | W14: 686 | X14: 665 | Y14: 598 | Z14: 540 | AA14: =+Z14*0.98 -> 529.2 | AB14: =+AA14*0.98 -> 518.616 | AC14: =+AB14*0.98 -> 508.24368 | AD14: =+AC14*0.98 -> 498.07881 | AE14: =+AD14*0.98 -> 488.11723 | AF14: =+AE14*0.98 -> 478.35489 | AG14: =+AF14*0.98 -> 468.78779 | AH14: =+AG14*0.98 -> 459.41203 | ... AJ14: =+AI14*0.98 -> 441.21932
B15: Total Revenue | C15: =+C12+C13+C14 -> 5714 | D15: =+D12+D13+D14 -> 0 | E15: =+E12+E13+E14 -> 0 | F15: =+F12+F13+F14 -> 0 | G15: =+G12+G13+G14 -> 6398 | H15: =+H12+H13+H14 -> 0 | I15: =+I12+I13+I14 -> 0 | J15: =+J12+J13+J14 -> 0 | P15: =+P12+P13+P14 -> 4795.511 | Q15: =+Q12+Q13+Q14 -> 5854.43 | R15: =+R12+R13+R14 -> 7301.505 | S15: =+S12+S13+S14 -> 9030 | T15: =+T12+T13+T14 -> 11171 | U15: =+U12+U13+U14 -> 12868 | V15: =+V12+V13+V14 -> 6398 | W15: =+W12+W13+W14 -> 17606 | ... AJ15: =+AJ12+AJ13+AJ14 -> 55274.088
B16: Cost of Subs | C16: 490 | G16: 540 | P16: 409.194 | Q16: 461.86 | R16: 623.048 | S16: 574 | T16: 926 | U16: 1108 | V16: =+SUM(G16:J16) -> 540 | W16: 1646 | X16: 1822 | Y16: 1799 | Z16: 2027 | AA16: =+AA12*(1-0.9) -> 2519.44 | AB16: =+AB12*(1-0.87) -> 3570.0465 | AC16: =+AC12*(1-0.87) -> 3891.3507 | AD16: =+AD12*(1-0.88) -> 3915.2974 | AE16: =+AE12*(1-0.88) -> 4267.6742 | AF16: =+AF12*(1-0.88) -> 4651.7649 | AG16: =+AG12*(1-0.885) -> 4859.1561 | AH16: =+AH12*(1-0.885) -> 5296.4801 | AI16: =+AI12*(1-0.885) -> 5773.1633 | AJ16: =+AJ12*(1-0.885) -> 6292.748
B17: Cost of Product | C17: 6 | G17: 6 | P17: 90.035 | Q17: 68.917 | R17: 57.082 | S17: 46 | T17: 40 | U17: 36 | V17: =+SUM(G17:J17) -> 6 | W17: 35 | X17: 29 | Y17: 25 | Z17: 23 | AA17: =+AA13*0.07 -> 20.475 | AB17: =+AB13*0.07 -> 18.4275 | AC17: =+AC13*0.07 -> 16.58475 | AD17: =+AD13*0.07 -> 14.926275 | AE17: =+AE13*0.07 -> 13.433648 | AF17: =+AF13*0.07 -> 12.090283 | AG17: =+AG13*0.07 -> 10.881254 | AH17: =+AH13*0.07 -> 9.793129 | ... AJ17: =+AJ13*0.07 -> 7.9324345
B18: Cost of Service | C18: 126 | G18: 118 | P18: 245.088 | Q18: 289.131 | R18: 330.361 | S18: 575 | T18: 707 | U18: 578 | V18: =+SUM(G18:J18) -> 118 | W18: 484 | X18: 503 | Y18: 534 | Z18: 501 | AA18: =+AA14*0.9 -> 476.28 | AB18: =+AB14*0.9 -> 466.7544 | AC18: =+AC14*0.9 -> 457.41931 | AD18: =+AD14*0.9 -> 448.27093 | AE18: =+AE14*0.9 -> 439.30551 | AF18: =+AF14*0.9 -> 430.5194 | AG18: =+AG14*0.9 -> 421.90901 | AH18: =+AH14*0.9 -> 413.47083 | ... AJ18: =+AJ14*0.9 -> 397.09738
B19: COGS | C19: =+C16+C17+C18 -> 622 | D19: =+D16+D17+D18 -> 0 | E19: =+E16+E17+E18 -> 0 | F19: =+F16+F17+F18 -> 0 | G19: =+G16+G17+G18 -> 664 | H19: =+H16+H17+H18 -> 0 | I19: =+I16+I17+I18 -> 0 | J19: =+J16+J17+J18 -> 0 | P19: =+P16+P17+P18 -> 744.317 | Q19: =+Q16+Q17+Q18 -> 819.908 | R19: =+R16+R17+R18 -> 1010.491 | S19: =+S16+S17+S18 -> 1195 | T19: =+T16+T17+T18 -> 1673 | U19: =+U16+U17+U18 -> 1722 | V19: =+V16+V17+V18 -> 664 | W19: =+W16+W17+W18 -> 2165 | ... AJ19: =+AJ16+AJ17+AJ18 -> 6697.7778
B20: Gross Profit | C20: =+C15-C19 -> 5092 | D20: =+D15-D19 -> 0 | E20: =+E15-E19 -> 0 | F20: =+F15-F19 -> 0 | G20: =+G15-G19 -> 5734 | H20: =+H15-H19 -> 0 | I20: =+I15-I19 -> 0 | J20: =+J15-J19 -> 0 | P20: =+P15-P19 -> 4051.194 | Q20: =+Q15-Q19 -> 5034.522 | R20: =+R15-R19 -> 6291.014 | S20: =+S15-S19 -> 7835 | T20: =+T15-T19 -> 9498 | U20: =+U15-U19 -> 11146 | V20: =+V15-V19 -> 5734 | W20: =+W15-W19 -> 15441 | ... AJ20: =+AJ15-AJ19 -> 48576.31
B21: R&D | C21: 1026 | G21: 1110 | P21: 862.73 | Q21: 975.987 | R21: 1224.059 | S21: 1538 | T21: 1930 | U21: 2188 | V21: =+SUM(G21:J21) -> 1110 | W21: 2987 | X21: 3473 | Y21: 3944 | Z21: 4294 | AA21: =+AA12*0.2 -> 5038.88 | AB21: =+AB12*0.2 -> 5492.3792 | AC21: =+AC12*0.2 -> 5986.6933 | AD21: =+AD12*0.2 -> 6525.4957 | AE21: =+AE12*0.2 -> 7112.7903 | AF21: =+AF12*0.2 -> 7752.9415 | AG21: =+AG12*0.2 -> 8450.7062 | AH21: =+AH12*0.2 -> 9211.2698 | ... AJ21: =+AJ12*0.2 -> 10943.91
B22: Sales and Marketing | C22: 1495 | G22: 1708 | P22: 1683.242 | Q22: 1910.197 | R22: 2197.592 | S22: 2621 | T22: 3244 | U22: 3591 | V22: =+SUM(G22:J22) -> 1708 | W22: 4968 | X22: 5351 | Y22: 5764 | Z22: 6488 | AA22: =+Z22*1.07 -> 6942.16 | AB22: =+AA22*1.07 -> 7428.1112 | AC22: =+AB22*1.07 -> 7948.079 | AD22: =+AD12*0.24 -> 7830.5949 | AE22: =+AE12*0.24 -> 8535.3484 | AF22: =+AF12*0.24 -> 9303.5298 | AG22: =+AG12*0.24 -> 10140.847 | AH22: =+AH12*0.24 -> 11053.524 | AI22: =+AI12*0.24 -> 12048.341 | AJ22: =+AJ12*0.24 -> 13132.692
B23: G&A | C23: 367 | G23: 463 | P23: 533.478 | Q23: 576.202 | R23: 624.706 | S23: 745 | T23: 881 | U23: 968 | V23: =+SUM(G23:J23) -> 463 | W23: 1219 | X23: 1413 | Y23: 1529 | Z23: 1573 | AA23: =+Z23*1.08 -> 1698.84 | AB23: =+AB15*0.065 -> 1835.8445 | AC23: =+AC15*0.065 -> 1994.1113 | AD23: =+AD15*0.065 -> 2167.0213 | AE23: =+AE15*0.065 -> 2355.8586 | AF23: =+AF15*0.065 -> 2562.0257 | AG23: =+AG15*0.065 -> 2787.0547 | AH23: =+AH15*0.065 -> 3032.6181 | AI23: =+AI15*0.065 -> 3300.5411 | AJ23: =+AJ15*0.065 -> 3592.8157
B24: Amortization | C24: 41 | G24: 35 | P24: 68.649 | Q24: 78.534 | R24: 76.562 | S24: 91 | T24: 175 | U24: 162 | V24: =+SUM(G24:J24) -> 35 | W24: 169 | X24: 168 | Y24: 169 | Z24: 157 | AA24: =+Z24*1.03 -> 161.71 | AB24: =+AA24*1.03 -> 166.5613 | AC24: =+AB24*1.03 -> 171.55814 | AD24: =+AC24*1.03 -> 176.70488 | AE24: =+AD24*1.03 -> 182.00603 | AF24: =+AE24*1.03 -> 187.46621 | AG24: =+AF24*1.03 -> 193.0902 | AH24: =+AG24*1.03 -> 198.8829 | ... AJ24: =+AI24*1.03 -> 210.99487
B25: Operating Expense | C25: =+C21+C22+C23+C24 -> 2929 | D25: =+D21+D22+D23+D24 -> 0 | E25: =+E21+E22+E23+E24 -> 0 | F25: =+F21+F22+F23+F24 -> 0 | G25: =+G21+G22+G23+G24 -> 3316 | H25: =+H21+H22+H23+H24 -> 0 | I25: =+I21+I22+I23+I24 -> 0 | J25: =+J21+J22+J23+J24 -> 0 | P25: =+P21+P22+P23+P24 -> 3148.099 | Q25: =+Q21+Q22+Q23+Q24 -> 3540.92 | R25: =+R21+R22+R23+R24 -> 4122.919 | S25: =+S21+S22+S23+S24 -> 4995 | T25: =+T21+T22+T23+T24 -> 6230 | U25: =+U21+U22+U23+U24 -> 6909 | V25: =+V21+V22+V23+V24 -> 3316 | W25: =+W21+W22+W23+W24 -> 9343 | ... AJ25: =+AJ21+AJ22+AJ23+AJ24 -> 27880.412
B26: Operating Income | C26: =+C20-C25 -> 2163 | D26: =+D20-D25 -> 0 | E26: =+E20-E25 -> 0 | F26: =+F20-F25 -> 0 | G26: =+G20-G25 -> 2418 | H26: =+H20-H25 -> 0 | I26: =+I20-I25 -> 0 | J26: =+J20-J25 -> 0 | P26: =+P20-P25 -> 903.095 | Q26: =+Q20-Q25 -> 1493.602 | R26: =+R20-R25 -> 2168.095 | S26: =+S20-S25 -> 2840 | T26: =+T20-T25 -> 3268 | U26: =+U20-U25 -> 4237 | V26: =+V20-V25 -> 2418 | W26: =+W20-W25 -> 6098 | ... AJ26: =+AJ20-AJ25 -> 20695.898
B27: Interest | C27: 62 | G27: 63 | P27: 64.184 | Q27: 70.442 | R27: 74.402 | S27: 89 | T27: 157 | U27: 116 | V27: =+SUM(G27:J27) -> 63 | W27: 112 | X27: 113 | Y27: 169 | Z27: 263 | AA27: =+Z27*0.98 -> 257.74 | AB27: =+AA27*0.98 -> 252.5852 | AC27: =+AB27*0.98 -> 247.5335 | AD27: =+AC27*0.98 -> 242.58283 | AE27: =+AD27*0.98 -> 237.73117 | AF27: =+AE27*0.98 -> 232.97655 | AG27: =+AF27*0.98 -> 228.31702 | AH27: =+AG27*0.98 -> 223.75067 | ... AJ27: =+AI27*0.98 -> 214.89015
B28: Investment | C28: 6 | G28: 5 | P28: 0.961 | Q28: -1.57 | R28: 7.553 | S28: 3 | T28: 52 | U28: 13 | V28: =+SUM(G28:J28) -> 5 | W28: -19 | X28: 16 | Y28: 48 | Z28: 43 | AA28: =+Z28*1.015 -> 43.645 | AB28: =+AA28*1.015 -> 44.299675 | AC28: =+AB28*1.015 -> 44.96417 | AD28: =+AC28*1.015 -> 45.638633 | AE28: =+AD28*1.015 -> 46.323212 | AF28: =+AE28*1.015 -> 47.01806 | AG28: =+AF28*1.015 -> 47.723331 | AH28: =+AG28*1.015 -> 48.439181 | ... AJ28: =+AI28*1.015 -> 49.903255
B29: Other income | C29: 75 | G29: 62 | P29: 33.909 | Q29: 13.548 | R29: 36.395 | S29: 40 | T29: 42 | U29: 42 | V29: 42 | W29: 41 | X29: 246 | Y29: =311-1000 -> -689 | Z29: 248 | AA29: 42 | AB29: 42 | AC29: 42 | AD29: 42 | AE29: 42 | AF29: 43 | AG29: 44 | AH29: 45 | AI29: 46 | AJ29: 47
B30: EBITDA | C30: =+C20-C25+C28+C29 -> 2244 | D30: =+D20-D25+D28+D29 -> 0 | E30: =+E20-E25+E28+E29 -> 0 | F30: =+F20-F25+F28+F29 -> 0 | G30: =+G20-G25+G28+G29 -> 2485 | H30: =+H20-H25+H28+H29 -> 0 | I30: =+I20-I25+I28+I29 -> 0 | J30: =+J20-J25+J28+J29 -> 0 | P30: =+P20-P25+P28+P29 -> 937.965 | Q30: =+Q20-Q25+Q28+Q29 -> 1505.58 | R30: =+R20-R25+R28+R29 -> 2212.043 | S30: =+S20-S25+S28+S29 -> 2883 | T30: =+T20-T25+T28+T29 -> 3362 | U30: =+U20-U25+U28+U29 -> 4292 | V30: =+V20-V25+V28+V29 -> 2465 | W30: =+W20-W25+W28+W29 -> 6120 | ... AJ30: =+AJ20-AJ25+AJ28+AJ29 -> 20792.802
B31: Income b4 Taxes | C31: =+C30-C27 -> 2182 | D31: =+D30-D27 -> 0 | E31: =+E30-E27 -> 0 | F31: =+F30-F27 -> 0 | G31: =+G30-G27 -> 2422 | H31: =+H30-H27 -> 0 | I31: =+I30-I27 -> 0 | J31: =+J30-J27 -> 0 | P31: =+P30-P27 -> 873.781 | Q31: =+Q30-Q27 -> 1435.138 | R31: =+R30-R27 -> 2137.641 | S31: =+S30-S27 -> 2794 | T31: =+T30-T27 -> 3205 | U31: =+U30-U27 -> 4176 | V31: =+V30-V27 -> 2402 | W31: =+W30-W27 -> 6008 | ... AJ31: =+AJ30-AJ27 -> 20577.911
B32: Taxes | C32: 372 | G32: 533 | P32: 244.23 | Q32: 266.256 | R32: 443.687 | S32: 203 | T32: 254 | U32: -1084 | V32: =+SUM(G32:J32) -> 533 | W32: 1252 | X32: 1371 | Y32: 1371 | Z32: 1604 | AA32: =+AA31*0.2 -> 1797.244 | AB32: =+AB31*0.2 -> 1819.8704 | AC32: =+AC31*0.2 -> 2010.4539 | AD32: =+AD31*0.2 -> 2421.1069 | AE32: =+AE31*0.2 -> 2637.6307 | AF32: =+AF31*0.2 -> 2874.4969 | AG32: =+AG31*0.2 -> 3175.5053 | AH32: =+AH31*0.2 -> 3461.8625 | ... AJ32: =+AJ31*0.2 -> 4115.5823
B33: Net Income | C33: =+C31-C32 -> 1810 | D33: =+D31-D32 -> 0 | E33: =+E31-E32 -> 0 | F33: =+F31-F32 -> 0 | G33: =+G31-G32 -> 1889 | H33: =+H31-H32 -> 0 | I33: =+I31-I32 -> 0 | J33: =+J31-J32 -> 0 | P33: =+P31-P32 -> 629.551 | Q33: =+Q31-Q32 -> 1168.882 | R33: =+R31-R32 -> 1693.954 | S33: =+S31-S32 -> 2591 | T33: =+T31-T32 -> 2951 | U33: =+U31-U32 -> 5260 | V33: =+V31-V32 -> 1869 | W33: =+W31-W32 -> 4756 | ... AJ33: =+AJ31-AJ32 -> 16462.329 | AK33: =+AJ33*(1+MV) -> 16956.199 | AL33: =+AK33*(1+MV) -> 17464.885 | AM33: =+AL33*(1+MV) -> 17988.832 | AN33: =+AM33*(1+MV) -> 18528.496 | AO33: =+AN33*(1+MV) -> 19084.351 | AP33: =+AO33*(1+MV) -> 19656.882 | AQ33: =+AP33*(1+MV) -> 20246.588 | AR33: =+AQ33*(1+MV) -> 20853.986 | ... DP33: =+DO33*(1+MV) -> 197159.7
B34: EPS | C34: =+C33/C35 -> 4.1324201 | G34: =+G33/G35 -> 4.5961071 | X34: =+X33/X35 -> 11.877462 | Y34: =+Y33/Y35 -> 12.438479 | Z34: =+Z33/Z35 -> 16.737089 | AA34: =+AA33/AA35 -> 17.491426 | AB34: =+AB33/AB35 -> 17.711634 | AC34: =+AC33/AC35 -> 19.566461 | AD34: =+AD33/AD35 -> 23.563084 | AE34: =+AE33/AE35 -> 25.670372 | ... AJ34: =+AJ33/AJ35 -> 40.054329
B35: Shares | C35: 438 | G35: 411 | X35: 457 | Y35: 447 | Z35: 426 | AA35: =+G35 -> 411 | AB35: =+AA35 -> 411 | AC35: =+AB35 -> 411 | AD35: =+AC35 -> 411 | AE35: =+AD35 -> 411 | AF35: =+AE35 -> 411 | AG35: =+AF35 -> 411 | AH35: =+AG35 -> 411 | AI35: =+AH35 -> 411 | AJ35: =+AI35 -> 411
B37: Gross Margin | C37: =+C20/C15 -> 0.89114456 | D37: =+D20/D15 -> #DIV/0! | E37: =+E20/E15 -> #DIV/0! | F37: =+F20/F15 -> #DIV/0! | G37: =+G20/G15 -> 0.89621757 | H37: =+H20/H15 -> #DIV/0! | I37: =+I20/I15 -> #DIV/0! | J37: =+J20/J15 -> #DIV/0! | P37: =+P20/P15 -> 0.8447888 | Q37: =+Q20/Q15 -> 0.85995084 | R37: =+R20/R15 -> 0.86160511 | S37: =+S20/S15 -> 0.86766334 | T37: =+T20/T15 -> 0.85023722 | U37: =+U20/U15 -> 0.86617967 | V37: =+V20/V15 -> 0.89621757 | W37: =+W20/W15 -> 0.87703056 | ... AJ37: =+AJ20/AJ15 -> 0.87882608
B38: Sub Margin | C38: =+(C12-C16)/C12 -> 0.91063287 | G38: =+(G12-G16)/G12 -> 0.91287512 | P38: =+(P12-P16)/P12 -> 0.873075 | Q38: =+(Q12-Q16)/Q12 -> 0.89926351 | R38: =+(R12-R16)/R12 -> 0.89842496 | S38: =+(S12-S16)/S12 -> 0.92451341 | T38: =+(T12-T16)/T12 -> 0.90388208 | U38: =+(U12-U16)/U12 -> 0.90469637 | V38: =+(V12-V16)/V12 -> 0.91287512 | W38: =+(W12-W16)/W12 -> 0.89956065 | ... AJ38: =+(AJ12-AJ16)/AJ12 -> 0.885
B39: Operating Margins | C39: =+C26/C15 -> 0.37854393 | G39: =+G26/G15 -> 0.3779306 | P39: =+P26/P15 -> 0.18832091 | Q39: =+Q26/Q15 -> 0.25512339 | R39: =+R26/R15 -> 0.2969381 | S39: =+S26/S15 -> 0.3145072 | T39: =+T26/T15 -> 0.29254319 | U39: =+U26/U15 -> 0.3292664 | V39: =+V26/V15 -> 0.3779306 | W39: =+W26/W15 -> 0.3463592 | ... AJ39: =+AJ26/AJ15 -> 0.37442315
B40: Net Income Margin | C40: =+C33/C15 -> 0.31676584 | D40: =+D33/D15 -> #DIV/0! | E40: =+E33/E15 -> #DIV/0! | F40: =+F33/F15 -> #DIV/0! | G40: =+G33/G15 -> 0.29524852 | H40: =+H33/H15 -> #DIV/0! | I40: =+I33/I15 -> #DIV/0! | J40: =+J33/J15 -> #DIV/0! | P40: =+P33/P15 -> 0.13127923 | Q40: =+Q33/Q15 -> 0.1996577 | R40: =+R33/R15 -> 0.23200066 | S40: =+S33/S15 -> 0.28693245 | T40: =+T33/T15 -> 0.26416614 | U40: =+U33/U15 -> 0.40876593 | V40: =+V33/V15 -> 0.29212254 | W40: =+W33/W15 -> 0.27013518 | ... AJ40: =+AJ33/AJ15 -> 0.29783086
B41: Taxes | C41: =+C32/C31 -> 0.17048579 | D41: =+D32/D31 -> #DIV/0! | E41: =+E32/E31 -> #DIV/0! | F41: =+F32/F31 -> #DIV/0! | G41: =+G32/G31 -> 0.22006606 | H41: =+H32/H31 -> #DIV/0! | I41: =+I32/I31 -> #DIV/0! | J41: =+J32/J31 -> #DIV/0! | P41: =+P32/P31 -> 0.2795094 | Q41: =+Q32/Q31 -> 0.18552641 | R41: =+R32/R31 -> 0.20755917 | S41: =+S32/S31 -> 0.072655691 | T41: =+T32/T31 -> 0.07925117 | U41: =+U32/U31 -> -0.25957854 | V41: =+V32/V31 -> 0.22189842 | W41: =+W32/W31 -> 0.20838881 | ... AJ41: =+AJ32/AJ31 -> 0.2 | AL41: Maturiy | AM41: 0.03
B42: Creative & Marketing | X42: =+X10/X15 -> 0.69168942 | Y42: =+Y10/Y15 -> 0.6858405 | Z42: =+Z10/Z15 -> 0.68589339 | AL42: Discount | AM42: 0.1
B43: Businesses | X43: =+X11/X15 -> 0.24442269 | Y43: =+Y11/Y15 -> 0.26328761 | Z43: =+Z11/Z15 -> 0.27325508 | AL43: NPV | AM43: =NPV(AM42,AA53:DT53) -> 155552.35
AL44: Net Cash | AM44: =+Main!E5 -> 385
...

Sheet Products
C3: Creative & Marketing Professionals
B5: Digital Media | C5: Adobe Creative Cloud Pro
B6: Digital Media | C6: Adobe Photoshop and Lightroom
B7: Digital Media | C7: Adobe Illustrator
B8: Digital Media | C8: Adobe Premiere Pro
B9: Digital Media | C9: Adobe After Effects
B10: Digital Media | C10: Adobe Substance 3D Collection
B11: Digital Media | C11: Adobe Stock
B12: Digital Media | C12: Adobe Firefly Solutions
B13: Digital Exp. | C13: Adobe GenStudio
B14: Digital Exp. | C14: Adobe Experience Platform
B15: Digital Exp. | C15: Adobe Agent Orchestrator
B16: Digital Exp. | C16: Adobe Brand Concierge
... B25: Digital Exp. | C25: Adobe Workfront
C28: Business Professionals & Consumers
B29: Digital Media | C29: Acrobat Studio
B30: Digital Media | C30: Adobe Acrobat
B31: Digital Media | C31: Adobe Acrobat Reader
B32: Digital Media | C32: Adobe Express
