Workbook

Sheet Main
C20: Price | D20: 4035
C21: Shares | D21: 32.233815
C22: MC | D22: =+D20*D21 -> 130063.44
C23: Net Cash | D23: =+Model!AC28 -> -1533
C24: EV | D24: =+D22-D23 -> 131596.44
C27: FCF Yield | D27: =+Model!Q35/Main!D24 -> 0.058003034
C28: EV/E | D28: =+D24/Model!Q21 -> 18.764662

Sheet Model
C2: Q124 | D2: Q224 | E2: Q324 | F2: Q424 | G2: Q125 | H2: Q225 | I2: Q325 | J2: Q425 | M2: 2022 | N2: =+M2+1 -> 2023 | O2: =+N2+1 -> 2024 | P2: =+O2+1 -> 2025 | Q2: =+P2+1 -> 2026 | R2: =+Q2+1 -> 2027 | S2: =+R2+1 -> 2028 | T2: =+S2+1 -> 2029 | U2: =+T2+1 -> 2030 | ... Z2: =+Y2+1 -> 2035
B5: Merchant Revenue | C5: 2388 | D5: 3446 | E5: 4972 | F5: =+O5-E5-D5-C5 -> 3336 | G5: 2918 | H5: 4457 | I5: 6131 | J5: =+F5*1.2 -> 4003.2 | M5: 7193 | N5: 10936 | O5: 14142 | P5: 17755 | Q5: =+P5*1.15 -> 20418.25 | R5: =+Q5*1.12 -> 22868.44 | S5: =+R5*1.12 -> 25612.653 | T5: =+S5*1.1 -> 28173.918 | U5: =+T5*1.1 -> 30991.31 | V5: =+U5*1.1 -> 34090.441 | W5: =+V5*1.1 -> 37499.485 | X5: =+W5*1.1 -> 41249.433 | Y5: =+X5*1.1 -> 45374.377 | Z5: =+Y5*1.1 -> 49911.814
B6: Agency Revenue | C6: 1763 | D6: 2144 | E6: 2753 | F6: =+O6-E6-D6-C6 -> 1864 | G6: 1564 | H6: 2044 | I6: 2569 | J6: =+F6*0.95 -> 1770.8 | M6: 9003 | N6: 9414 | O6: 8524 | P6: 7968 | Q6: =+P6*0.95 -> 7569.6 | R6: =+Q6*0.95 -> 7191.12 | S6: =+R6*0.95 -> 6831.564 | T6: =+S6*0.95 -> 6489.9858 | U6: =+T6*0.95 -> 6165.4865 | V6: =+U6*0.95 -> 5857.2122 | W6: =+V6*0.95 -> 5564.3516 | X6: =+W6*0.95 -> 5286.134 | ... Z6: =+Y6*0.95 -> 4770.7359
B7: Ads and other | C7: 264 | D7: 269 | E7: 269 | F7: =+O7-E7-D7-C7 -> 271 | G7: 280 | H7: 297 | I7: 308 | J7: 300 | M7: 894 | N7: 1015 | O7: 1073 | P7: 1194 | Q7: =+P7*1.05 -> 1253.7 | R7: =+Q7*1.05 -> 1316.385 | S7: =+R7*1.05 -> 1382.2043 | T7: =+S7*1.05 -> 1451.3145 | U7: =+T7*1.05 -> 1523.8802 | V7: =+U7*1.05 -> 1600.0742 | W7: =+V7*1.05 -> 1680.0779 | X7: =+W7*1.05 -> 1764.0818 | ... Z7: =+Y7*1.05 -> 1944.9002
B8: Total Revenue | C8: =+SUM(C5:C7) -> 4415 | D8: =+SUM(D5:D7) -> 5859 | E8: =+SUM(E5:E7) -> 7994 | F8: =+SUM(F5:F7) -> 5471 | G8: =+SUM(G5:G7) -> 4762 | H8: =+SUM(H5:H7) -> 6798 | I8: =+SUM(I5:I7) -> 9008 | J8: =+SUM(J5:J7) -> 6074 | M8: =+SUM(M5:M7) -> 17090 | N8: =+SUM(N5:N7) -> 21365 | O8: =+SUM(O5:O7) -> 23739 | P8: =+SUM(P5:P7) -> 26917 | Q8: =+SUM(Q5:Q7) -> 29241.55 | R8: =+SUM(R5:R7) -> 31375.945 | S8: =+SUM(S5:S7) -> 33826.421 | T8: =+SUM(T5:T7) -> 36115.218 | ... Z8: =+SUM(Z5:Z7) -> 56627.451
B9: Marketing | C9: 1610 | D9: 1939 | E9: 2151 | F9: =+O9-E9-D9-C9 -> 1578 | G9: 1777 | H9: 2139 | I9: 2340 | J9: 1700 | M9: 5993 | N9: 6773 | O9: 7278 | P9: 8186 | Q9: =+Q8*0.3 -> 8772.465 | R9: =+R8*0.3 -> 9412.7835 | S9: =+S8*0.3 -> 10147.926 | T9: =+T8*0.3 -> 10834.566 | U9: =+U8*0.3 -> 11604.203 | V9: =+V8*0.3 -> 12464.318 | W9: =+W8*0.3 -> 13423.174 | X9: =+X8*0.3 -> 14489.895 | ... Z9: =+Z8*0.3 -> 16988.235
B10: Sales & Other | C10: 678 | D10: 820 | E10: 872 | F10: =+O10-E10-D10-C10 -> 750 | G10: 702 | H10: 899 | I10: 1022 | J10: 900 | M10: 1986 | N10: 2744 | O10: 3120 | P10: 3453 | Q10: =+Q8*0.13 -> 3801.4015 | R10: =+R8*0.13 -> 4078.8729 | S10: =+S8*0.13 -> 4397.4347 | T10: =+T8*0.13 -> 4694.9784 | U10: =+U8*0.13 -> 5028.488 | V10: =+V8*0.13 -> 5401.2045 | W10: =+W8*0.13 -> 5816.7089 | X10: =+X8*0.13 -> 6278.9544 | ... Z10: =+Z8*0.13 -> 7361.5686
B11: Personnel | C11: 826 | D11: 807 | E11: 868 | F11: =+O11-E11-D11-C11 -> 853 | G11: 693 | H11: 896 | I11: 945 | J11: 950 | M11: 2465 | N11: 3294 | O11: 3354 | P11: 3403 | Q11: =+Q8*0.12 -> 3508.986 | R11: =+R8*0.12 -> 3765.1134 | S11: =+S8*0.12 -> 4059.1705 | T11: =+T8*0.12 -> 4333.8262 | U11: =+U8*0.12 -> 4641.6812 | V11: =+V8*0.12 -> 4985.7273 | W11: =+W8*0.12 -> 5369.2697 | X11: =+X8*0.12 -> 5795.9579 | ... Z11: =+Z8*0.12 -> 6795.2941
B12: G&A | C12: 186 | D12: 112 | E12: 575 | F12: =+O12-E12-D12-C12 -> 163 | G12: 142 | H12: 199 | I12: 254 | J12: 250 | M12: 766 | N12: 1555 | O12: 1036 | P12: 857 | Q12: =+Q8*0.035 -> 1023.4543 | R12: =+R8*0.035 -> 1098.1581 | S12: =+S8*0.035 -> 1183.9247 | T12: =+T8*0.035 -> 1264.0326 | U12: =+U8*0.035 -> 1353.8237 | V12: =+V8*0.035 -> 1454.1705 | W12: =+W8*0.035 -> 1566.037 | X12: =+X8*0.035 -> 1690.4877 | ... Z12: =+Z8*0.035 -> 1981.9608
B13: IT | C13: 187 | D13: 183 | E13: 194 | F13: =+O13-E13-D13-C13 -> 207 | G13: 200 | H13: 219 | I13: 242 | J13: 250 | M13: 526 | N13: 655 | O13: 771 | P13: 908 | Q13: =+Q8*0.04 -> 1169.662 | R13: =+R8*0.04 -> 1255.0378 | S13: =+S8*0.04 -> 1353.0568 | T13: =+T8*0.04 -> 1444.6087 | U13: =+U8*0.04 -> 1547.2271 | V13: =+V8*0.04 -> 1661.9091 | W13: =+W8*0.04 -> 1789.7566 | X13: =+X8*0.04 -> 1931.986 | ... Z13: =+Z8*0.04 -> 2265.098
B14: D&A | C14: 137 | D14: 142 | E14: 155 | F14: =+O14-E14-D14-C14 -> 157 | G14: 154 | H14: 158 | I14: 160 | J14: 162 | M14: 451 | N14: 504 | O14: 591 | P14: 623 | Q14: 650 | R14: 650 | S14: 650 | T14: 650 | U14: 650 | V14: 650 | W14: 650 | X14: 650 | Y14: 650 | Z14: 650
B15: Operating Income | C15: =+C8-SUM(C9:C14) -> 791 | D15: =+D8-SUM(D9:D14) -> 1856 | E15: =+E8-SUM(E9:E14) -> 3179 | F15: =+F8-SUM(F9:F14) -> 1763 | G15: =+G8-SUM(G9:G14) -> 1094 | H15: =+H8-SUM(H9:H14) -> 2288 | I15: =+I8-SUM(I9:I14) -> 4045 | J15: =+J8-SUM(J9:J14) -> 1862 | M15: =+M8-SUM(M9:M14) -> 4903 | N15: =+N8-SUM(N9:N14) -> 5840 | O15: =+O8-SUM(O9:O14) -> 7589 | P15: =+P8-SUM(P9:P14) -> 9487 | Q15: =+Q8-SUM(Q9:Q14) -> 10315.581 | R15: =+R8-SUM(R9:R14) -> 11115.979 | S15: =+S8-SUM(S9:S14) -> 12034.908 | T15: =+T8-SUM(T9:T14) -> 12893.207 | ... Z15: =+Z8-SUM(Z9:Z14) -> 20585.294
B16: Interest Expense | C16: 219 | D16: 264 | E16: 305 | F16: =+O16-E16-D16-C16 -> 507 | G16: 649 | H16: 418 | I16: 301 | J16: 500 | M16: 391 | N16: 897 | O16: 1295 | P16: 1617 | Q16: =+P16*1.02 -> 1649.34 | R16: =+Q16*1.02 -> 1682.3268 | S16: =+R16*1.02 -> 1715.9733 | T16: =+S16*1.02 -> 1750.2928 | U16: =+T16*1.02 -> 1785.2987 | V16: =+U16*1.02 -> 1821.0046 | W16: =+V16*1.02 -> 1857.4247 | X16: =+W16*1.02 -> 1894.5732 | ... Z16: =+Y16*1.02 -> 1971.114
B17: Interest Income | C17: 243 | D17: 293 | E17: 327 | F17: =+O17-E17-D17-C17 -> 251 | G17: 241 | H17: 234 | I17: 248 | J17: 250 | M17: 219 | N17: 1020 | O17: 1114 | P17: 921 | Q17: 900 | R17: 900 | S17: 900 | T17: 900 | U17: 900 | V17: 900 | W17: 900 | X17: 900 | Y17: 900 | Z17: 900
B18: Other Income, net | C18: 122 | D18: 37 | E18: -332 | F18: =+O18-E18-D18-C18 -> 91 | G18: -258 | H18: -962 | I18: =39-457 -> -418 | J18: 90 | M18: -1007 | N18: -477 | O18: -82 | P18: =-1297-457-205 -> -1959 | Q18: -800 | R18: -800 | S18: -800 | T18: -800 | U18: -800 | V18: -800 | W18: -800 | X18: -800 | Y18: -800 | Z18: -800
B19: Pretax | C19: =+C15-C16+C17+C18 -> 937 | D19: =+D15-D16+D17+D18 -> 1922 | E19: =+E15-E16+E17+E18 -> 2869 | F19: =+F15-F16+F17+F18 -> 1598 | G19: =+G15-G16+G17+G18 -> 428 | H19: =+H15-H16+H17+H18 -> 1142 | I19: =+I15-I16+I17+I18 -> 3574 | J19: =+J15-J16+J17+J18 -> 1702 | M19: =+M15-M16+M17+M18 -> 3724 | N19: =+N15-N16+N17+N18 -> 5486 | O19: =+O15-O16+O17+O18 -> 7326 | P19: =+P15-P16+P17+P18 -> 6832 | Q19: =+Q15-Q16+Q17+Q18 -> 8766.2412 | R19: =+R15-R16+R17+R18 -> 9533.6526 | S19: =+S15-S16+S17+S18 -> 10418.935 | T19: =+T15-T16+T17+T18 -> 11242.914 | ... Z19: =+Z15-Z16+Z17+Z18 -> 18714.18
B20: Taxes | C20: 161 | D20: 401 | E20: 352 | F20: =+O20-E20-D20-C20 -> 496 | G20: 63 | H20: 209 | I20: 721 | J20: =+J19*0.2 -> 340.4 | M20: 865 | N20: 1192 | O20: 1410 | P20: 1428 | Q20: =+Q19*0.2 -> 1753.2482 | R20: =+R19*0.2 -> 1906.7305 | S20: =+S19*0.2 -> 2083.7869 | T20: =+T19*0.2 -> 2248.5828 | U20: =+U19*0.2 -> 2433.991 | V20: =+V19*0.2 -> 2641.8786 | W20: =+W19*0.2 -> 2874.3086 | X20: =+X19*0.2 -> 3133.5591 | ... Z20: =+Z19*0.2 -> 3742.836
B21: Net Income | C21: =+C19-C20 -> 776 | D21: =+D19-D20 -> 1521 | E21: =+E19-E20 -> 2517 | F21: =+F19-F20 -> 1102 | G21: =+G19-G20 -> 365 | H21: =+H19-H20 -> 933 | I21: =+I19-I20 -> 2853 | J21: =+J19-J20 -> 1361.6 | M21: =+M19-M20 -> 2859 | N21: =+N19-N20 -> 4294 | O21: =+O19-O20 -> 5916 | P21: =+P19-P20 -> 5404 | Q21: =+Q19-Q20 -> 7012.993 | R21: =+R19-R20 -> 7626.9221 | S21: =+S19-S20 -> 8335.1476 | T21: =+T19-T20 -> 8994.3313 | ... Z21: =+Z19-Z20 -> 14971.344 | AA21: =+Z21*(1+$AC26) -> 15420.484 | AB21: =+AA21*(1+$AC26) -> 15883.099 | AC21: =+AB21*(1+$AC26) -> 16359.592 | AD21: =+AC21*(1+$AC26) -> 16850.38 | AE21: =+AD21*(1+$AC26) -> 17355.891 | AF21: =+AE21*(1+$AC26) -> 17876.568 | AG21: =+AF21*(1+$AC26) -> 18412.865 | AH21: =+AG21*(1+$AC26) -> 18965.251 | ... EE21: =+ED21*(1+$AC26) -> 375420.76
B22: EPS | C22: =+C21/C23 -> 22.359246 | D22: =+D21/D23 -> 44.386728 | E22: =+E21/E23 -> 74.326719 | F22: =+F21/F23 -> 33.582203 | G22: =+G21/G23 -> 11.029523 | H22: =+H21/H23 -> 28.602961 | I22: =+I21/I23 -> 87.628233 | M22: =+M21/M23 -> 71.382203 | N22: =+N21/N23 -> 117.54722 | O22: =+O21/O23 -> 173.67309 | P22: =+P21/P23 -> 165.5688 | Q22: =+Q21/Q23 -> 215.39999 | R22: =+R21/R23 -> 234.25647 | S22: =+S21/S23 -> 256.0092 | T22: =+T21/T23 -> 276.25564 | ... Z22: =+Z21/Z23 -> 459.83611
B23: Shares | C23: 34.706 | D23: 34.267 | E23: 33.864 | F23: 32.815 | G23: 33.093 | H23: 32.619 | I23: 32.558 | M23: 40.052 | N23: 36.53 | O23: 34.064 | P23: 32.639 | Q23: 32.558 | R23: =+Q23+0 -> 32.558 | S23: =+R23+0 -> 32.558 | T23: =+S23+0 -> 32.558 | U23: =+T23+0 -> 32.558 | V23: =+U23+0 -> 32.558 | W23: =+V23+0 -> 32.558 | X23: =+W23+0 -> 32.558 | Y23: =+X23+0 -> 32.558 | Z23: =+Y23+0 -> 32.558
B25: Operating Margin | C25: =+C15/C8 -> 0.17916195 | D25: =+D15/D8 -> 0.31677761 | E25: =+E15/E8 -> 0.39767325 | F25: =+F15/F8 -> 0.32224456 | G25: =+G15/G8 -> 0.22973541 | H25: =+H15/H8 -> 0.33656958 | I25: =+I15/I8 -> 0.44904529 | M25: =+M15/M8 -> 0.28689292 | N25: =+N15/N8 -> 0.27334425 | O25: =+O15/O8 -> 0.31968491 | P25: =+P15/P8 -> 0.35245384 | Q25: =+Q15/Q8 -> 0.35277136 | R25: =+R15/R8 -> 0.35428349 | S25: =+S15/S8 -> 0.35578425 | T25: =+T15/T8 -> 0.35700205 | ... Z25: =+Z15/Z8 -> 0.36352147 | AB25: Discount | AC25: 0.1
B26: Net Margin | C26: =+C21/C8 -> 0.17576444 | D26: =+D21/D8 -> 0.25960061 | E26: =+E21/E8 -> 0.31486115 | F26: =+F21/F8 -> 0.2014257 | G26: =+G21/G8 -> 0.076648467 | H26: =+H21/H8 -> 0.13724625 | I26: =+I21/I8 -> 0.31671847 | M26: =+M21/M8 -> 0.16729081 | N26: =+N21/N8 -> 0.20098292 | O26: =+O21/O8 -> 0.24921016 | P26: =+P21/P8 -> 0.20076532 | Q26: =+Q21/Q8 -> 0.23982973 | R26: =+R21/R8 -> 0.24308183 | S26: =+S21/S8 -> 0.24640939 | T26: =+T21/T8 -> 0.24904546 | ... Z26: =+Z21/Z8 -> 0.26438315 | AB26: Terminal | AC26: 0.03
B27: Revenue Y/Y | G27: =+G8/C8 -1 -> 0.078595696 | H27: =+H8/D8 -1 -> 0.16026626 | I27: =+I8/E8 -1 -> 0.12684513 | N27: =+N8/M8 -1 -> 0.25014628 | O27: =+O8/N8 -1 -> 0.11111631 | P27: =+P8/O8 -1 -> 0.13387253 | Q27: =+Q8/P8 -1 -> 0.086359921 | R27: =+R8/Q8 -1 -> 0.072991856 | S27: =+S8/R8 -1 -> 0.07810047 | T27: =+T8/S8 -1 -> 0.067663005 | U27: =+U8/T8 -1 -> 0.07103538 | ... Z27: =+Z8/Y8 -1 -> 0.083810281 | AB27: NPV | AC27: =NPV(AC25,Q38:EP38) -> 161066.55
B28: Merchant Y/Y | G28: =+G5/C5 -1 -> 0.22194305 | H28: =+H5/D5 -1 -> 0.29338363 | I28: =+I5/E5 -1 -> 0.23310539 | N28: =+N5/M5 -1 -> 0.52036702 | O28: =+O5/N5 -1 -> 0.2931602 | P28: =+P5/O5 -1 -> 0.25548013 | Q28: =+Q5/P5 -1 -> 0.15 | R28: =+R5/Q5 -1 -> 0.12 | S28: =+S5/R5 -1 -> 0.12 | T28: =+T5/S5 -1 -> 0.1 | U28: =+U5/T5 -1 -> 0.1 | ... Z28: =+Z5/Y5 -1 -> 0.1 | AB28: Net Cash | AC28: =+P47-P48 -> -1533
B29: Agency Y/Y | G29: =+G6/C6 -1 -> -0.11287578 | H29: =+H6/D6 -1 -> -0.046641791 | I29: =+I6/E6 -1 -> -0.066836179 | N29: =+N6/M6 -1 -> 0.04565145 | O29: =+O6/N6 -1 -> -0.094540047 | P29: =+P6/O6 -1 -> -0.065227593 | Q29: =+Q6/P6 -1 -> -0.05 | R29: =+R6/Q6 -1 -> -0.05 | S29: =+S6/R6 -1 -> -0.05 | T29: =+T6/S6 -1 -> -0.05 | U29: =+U6/T6 -1 -> -0.05 | ... Z29: =+Z6/Y6 -1 -> -0.05 | AB29: Value | AC29: =+AC27+AC28 -> 159533.55
AB30: Price | AC30: =+AC29/Z23 -> 4899.98
B31: D&A | O31: 591 | P31: 623 | Q31: =+Q14 -> 650 | R31: =+R14 -> 650 | S31: =+S14 -> 650 | T31: =+T14 -> 650 | U31: =+U14 -> 650 | V31: =+V14 -> 650 | W31: =+W14 -> 650 | X31: =+X14 -> 650 | ... Z31: =+Z14 -> 650 | AB31: Diff | AC31: =+AC30/Main!D20 -1 -> 0.21436926
B32: Credit Loss Prov. | O32: 412 | P32: 416 | Q32: 420 | R32: 420 | S32: 420 | T32: 420 | U32: 420 | V32: 420 | W32: 420 | X32: 420 | Y32: 420 | Z32: 420 | AC32: =+AC30*0.7 -> 3429.986
B33: CFFO | C33: 2704 | D33: =5229-C33 -> 2525 | E33: =7602-D33-C33 -> 2373 | F33: =+O33-E33-D33-C33 -> 721 | G33: 3283 | H33: =6484-G33 -> 3201 | I33: =7919-H33-G33 -> 1435 | J33: =+J21+J14 -> 1523.6 | M33: 6554 | N33: 7344 | O33: 8323 | P33: 9409 | Q33: =+Q21+Q31+Q32 -> 8082.993 | R33: =+R21+R31+R32 -> 8696.9221 | S33: =+S21+S31+S32 -> 9405.1476 | T33: =+T21+T31+T32 -> 10064.331 | U33: =+U21+U31+U32 -> 10805.964 | V33: =+V21+V31+V32 -> 11637.514 | W33: =+W21+W31+W32 -> 12567.235 | X33: =+X21+X31+X32 -> 13604.236 | ... Z33: =+Z21+Z31+Z32 -> 16041.344
B34: CapEx | C34: 130 | D34: =276-C34 -> 146 | E34: =353-D34-C34 -> 77 | F34: =+O34-E34-D34-C34 -> 76 | G34: 121 | H34: =185-G34 -> 64 | I34: =249-H34-G34 -> 64 | J34: 65 | M34: 368 | N34: 345 | O34: 429 | P34: 322 | Q34: 450 | R34: =+Q34*1.02 -> 459 | S34: =+R34*1.02 -> 468.18 | T34: =+S34*1.02 -> 477.5436 | U34: =+T34*1.02 -> 487.09447 | V34: =+U34*1.02 -> 496.83636 | W34: =+V34*1.02 -> 506.77309 | X34: =+W34*1.02 -> 516.90855 | Y34: =+X34*1.02 -> 527.24672 | Z34: =+Y34*1.02 -> 537.79166
B35: FCF | C35: =+C33-C34 -> 2574 | D35: =+D33-D34 -> 2379 | E35: =+E33-E34 -> 2296 | F35: =+F33-F34 -> 645 | G35: =+G33-G34 -> 3162 | H35: =+H33-H34 -> 3137 | I35: =+I33-I34 -> 1371 | J35: =+J33-J34 -> 1458.6 | M35: =+M33-M34 -> 6186 | N35: =+N33-N34 -> 6999 | O35: =+O33-O34 -> 7894 | P35: =+P33-P34 -> 9087 | Q35: =+Q33-Q34 -> 7632.993 | R35: =+R33-R34 -> 8237.9221 | S35: =+S33-S34 -> 8936.9676 | T35: =+T33-T34 -> 9586.7877 | ... Z35: =+Z33-Z34 -> 15503.552
B36: Stock Based Comps. | C36: 144 | D36: =284-C36 -> 140 | E36: =432-D36-C36 -> 148 | F36: =+O36-E36-D36-C36 -> 167 | G36: 143 | H36: =297-G36 -> 154 | I36: =450-H36-G36 -> 153 | J36: 155 | M36: 404 | N36: 530 | O36: 599 | P36: 617
B37: Adj. FCF | C37: =+C35-C36 -> 2430 | D37: =+D35-D36 -> 2239 | E37: =+E35-E36 -> 2148 | F37: =+F35-F36 -> 478 | G37: =+G35-G36 -> 3019 | H37: =+H35-H36 -> 2983 | I37: =+I35-I36 -> 1218 | J37: =+J35-J36 -> 1303.6 | M37: =+M35-M36 -> 5782 | N37: =+N35-N36 -> 6469 | O37: =+O35-O36 -> 7295 | P37: =+P35-P36 -> 8470
B38: FCFF | Q38: =+Q35+(Q16-Q17)*(1-0.2) -> 8232.465 | R38: =+R35+(R16-R17)*(1-0.2) -> 8863.7835 | S38: =+S35+(S16-S17)*(1-0.2) -> 9589.7463 | T38: =+T35+(T16-T17)*(1-0.2) -> 10267.022 | U38: =+U35+(U16-U17)*(1-0.2) -> 11027.109 | V38: =+V35+(V16-V17)*(1-0.2) -> 11877.482 | W38: =+W35+(W16-W17)*(1-0.2) -> 12826.401 | X38: =+X35+(X16-X17)*(1-0.2) -> 13882.986 | ... Z38: =+Z35+(Z16-Z17)*(1-0.2) -> 16360.444 | AA38: =+Z38*(1+$AC26) -> 16851.257 | AB38: =+AA38*(1+$AC26) -> 17356.795 | AC38: =+AB38*(1+$AC26) -> 17877.498 | AD38: =+AC38*(1+$AC26) -> 18413.823 | AE38: =+AD38*(1+$AC26) -> 18966.238 | AF38: =+AE38*(1+$AC26) -> 19535.225 | AG38: =+AF38*(1+$AC26) -> 20121.282 | AH38: =+AG38*(1+$AC26) -> 20724.92 | ... ED38: =+EC38*(1+$AC26) -> 398304.62
B40: Stock Buybacks | C40: 1856 | D40: =3518-C40 -> 1662 | E40: =5282-D40-C40 -> 1764 | G40: 2170 | H40: =3668-G40 -> 1498 | I40: =4321-H40-G40 -> 653 | M40: 6621 | N40: 10377 | O40: 6509 | P40: 6440
B41: Dividends Paid | C41: 299 | D41: =594-C41 -> 295 | E41: =885-C41-D41 -> 291 | G41: 319 | H41: =631-G41 -> 312 | I41: =941-H41-G41 -> 310 | O41: 1174 | P41: 1248
B42: Total | M42: =+M40+M41 -> 6621 | N42: =+N40+N41 -> 10377 | O42: =+O40+O41 -> 7683 | P42: =+P40+P41 -> 7688
B44: Shares Removed | N44: =+M23-N23 -> 3.522 | O44: =+N23-O23 -> 2.466 | P44: =+O23-P23 -> 1.425 | Q44: =+P40/Main!D22 *Q23 -> 1.6120865
B45: % | N45: =+N23/M23 -1 -> -0.087935684 | O45: =+O23/N23 -1 -> -0.067506159 | P45: =+P23/O23 -1 -> -0.04183302
B47: Cash | N47: 12107 | O47: 16164 | P47: 17203
...
