Workbook

Sheet Main
D3: Price | E3: 183
D4: Shares | E4: =+Model!K23 -> 937
D5: Market Cap | E5: =+E3*E4 -> 171471
D6: Net Cash | E6: =+Model!X32 -> 2885
D7: EV | E7: =+E5+E6 -> 174356

Sheet Model
D2: =+E2-1 -> 2018 | E2: =+F2-1 -> 2019 | F2: =+G2-1 -> 2020 | G2: =+H2-1 -> 2021 | H2: =+I2-1 -> 2022 | I2: 2023 | J2: =+I2+1 -> 2024 | K2: =+J2+1 -> 2025 | L2: =+K2+1 -> 2026 | M2: =+L2+1 -> 2027 | N2: =+M2+1 -> 2028 | O2: =+N2+1 -> 2029 | P2: =+O2+1 -> 2030 | Q2: =+P2+1 -> 2031 | ... AP2: =+AO2+1 -> 2056
B4: Subscription | D4: 9766 | E4: 12413 | F4: 16043 | G4: 19976 | H4: 24657 | I4: 29021 | J4: 32537 | K4: 35679 | L4: =+L6-L5 -> 39250 | M4: =+L4*1.08 -> 42390 | N4: =+M4*1.08 -> 45781.2 | O4: =+N4*1.08 -> 49443.696 | P4: =+O4*1.08 -> 53399.192 | Q4: =+P4*1.08 -> 57671.127 | R4: =+Q4*1.08 -> 62284.817 | S4: =+R4*1.08 -> 67267.603 | T4: =+S4*1.08 -> 72649.011 | U4: =+T4*1.08 -> 78460.932
B5: Services | D5: 774 | E5: 869 | F5: 1055 | G5: 1276 | H5: 1835 | I5: 2331 | J5: 2320 | K5: 2216 | L5: 2200 | M5: 2300 | N5: 2300 | O5: 2300 | P5: 2300 | Q5: 2300 | R5: 2300 | S5: 2300 | T5: 2300 | U5: 2300
B6: Total Revenue | D6: =D4+D5 -> 10540 | E6: =E4+E5 -> 13282 | F6: =F4+F5 -> 17098 | G6: =G4+G5 -> 21252 | H6: =H4+H5 -> 26492 | I6: =+I4+I5 -> 31352 | J6: =+J4+J5 -> 34857 | K6: =+K4+K5 -> 37895 | L6: 41450 | M6: =+M4+M5 -> 44690 | N6: =+N4+N5 -> 48081.2 | O6: =+O4+O5 -> 51743.696 | P6: =+P4+P5 -> 55699.192 | Q6: =+Q4+Q5 -> 59971.127 | R6: =+R4+R5 -> 64584.817 | S6: =+S4+S5 -> 69567.603 | T6: =+T4+T5 -> 74949.011 | U6: =+U4+U5 -> 80760.932
B7: Subscription | I7: 5821 | J7: 6177 | K7: 6198 | L7: =4921*1.33 -> 6544.93 | M7: =+M4*0.17 -> 7206.3 | N7: =+N4*0.17 -> 7782.804 | O7: =+O4*0.17 -> 8405.4283 | P7: =+P4*0.17 -> 9077.8626 | Q7: =+Q4*0.17 -> 9804.0916 | R7: =+R4*0.17 -> 10588.419 | S7: =+S4*0.17 -> 11435.492 | T7: =+T4*0.17 -> 12350.332 | U7: =+U4*0.17 -> 13338.358
B8: Services | I8: 2539 | J8: 2364 | K8: 2445 | L8: =1841*1.33 -> 2448.53 | M8: =+M5*1.1 -> 2530 | N8: =+N5*1.1 -> 2530 | O8: =+O5*1.1 -> 2530 | P8: =+P5*1.1 -> 2530 | Q8: =+Q5*1.1 -> 2530 | R8: =+R5*1.1 -> 2530 | S8: =+S5*1.1 -> 2530 | T8: =+T5*1.1 -> 2530 | U8: =+U5*1.1 -> 2530
B9: COGS | I9: =+I7+I8 -> 8360 | J9: =+J7+J8 -> 8541 | K9: =+K7+K8 -> 8643 | L9: =+L7+L8 -> 8993.46 | M9: =+M7+M8 -> 9736.3 | N9: =+N7+N8 -> 10312.804 | O9: =+O7+O8 -> 10935.428 | P9: =+P7+P8 -> 11607.863 | ... U9: =+U7+U8 -> 15868.358
B10: Gross Profit | I10: =+I6-I9 -> 22992 | J10: =+J6-J9 -> 26316 | K10: =+K6-K9 -> 29252 | L10: =+L6-L9 -> 32456.54 | M10: =+M6-M9 -> 34953.7 | N10: =+N6-N9 -> 37768.396 | O10: =+O6-O9 -> 40808.268 | P10: =+P6-P9 -> 44091.329 | ... U10: =+U6-U9 -> 64892.573
B11: R&D | I11: 5055 | J11: 4906 | K11: 5493 | L11: =4374*1.33 -> 5817.42 | M11: =+L11*1.05 -> 6108.291 | N11: =+M11*1.05 -> 6413.7056 | O11: =+N11*1.05 -> 6734.3908 | P11: =+O11*1.05 -> 7071.1104 | Q11: =+P11*1.04 -> 7353.9548 | R11: =+Q11*1.04 -> 7648.113 | S11: =+R11*1.04 -> 7954.0375 | T11: =+S11*1.04 -> 8272.199 | U11: =+T11*1.04 -> 8603.087
B12: S&M | I12: 13526 | J12: 12877 | K12: 13257 | L12: =10328*1.33 -> 13736.24 | M12: =+L12*1.02 -> 14010.965 | N12: =+N6*0.3 -> 14424.36 | O12: =+O6*0.3 -> 15523.109 | P12: =+P6*0.3 -> 16709.758 | Q12: =+Q6*0.3 -> 17991.338 | R12: =+R6*0.3 -> 19375.445 | S12: =+S6*0.3 -> 20870.281 | T12: =+T6*0.3 -> 22484.703 | U12: =+U6*0.3 -> 24228.279
B13: G&A | I13: 2553 | J13: 2534 | K13: 2836 | L13: =2098*1.33 -> 2790.34 | M13: =+M6*0.07 -> 3128.3 | N13: =+N6*0.07 -> 3365.684 | O13: =+O6*0.07 -> 3622.0587 | P13: =+P6*0.07 -> 3898.9434 | Q13: =+Q6*0.07 -> 4197.9789 | R13: =+R6*0.07 -> 4520.9372 | S13: =+S6*0.07 -> 4869.7322 | T13: =+T6*0.07 -> 5246.4308 | U13: =+U6*0.07 -> 5653.2652
B14: Restructuring | I14: 828 | J14: 988 | K14: 461 | L14: 400 | M14: 400 | N14: 400 | O14: 400 | P14: 400 | Q14: 400 | R14: 400 | S14: 400 | T14: 400 | U14: 400
B15: Operating Expenses | I15: =+SUM(I11:I14) -> 21962 | J15: =+SUM(J11:J14) -> 21305 | K15: =+SUM(K11:K14) -> 22047 | L15: =+SUM(L11:L14) -> 22744 | M15: =+SUM(M11:M14) -> 23647.556 | N15: =+SUM(N11:N14) -> 24603.75 | O15: =+SUM(O11:O14) -> 26279.558 | P15: =+SUM(P11:P14) -> 28079.811 | ... U15: =+SUM(U11:U14) -> 38884.632
B16: Operating Income | I16: =+I10-I15 -> 1030 | J16: =+J10-J15 -> 5011 | K16: =+K10-K15 -> 7205 | L16: =+L10-L15 -> 9712.54 | M16: =+M10-M15 -> 11306.144 | N16: =+N10-N15 -> 13164.646 | O16: =+O10-O15 -> 14528.709 | P16: =+P10-P15 -> 16011.518 | ... U16: =+U10-U15 -> 26007.942
B17: Investments, net | I17: -239 | J17: -277 | K17: -121 | L17: =206*1.33 -> 273.98 | M17: 300 | N17: 300 | O17: 300 | P17: 300 | Q17: 300 | R17: 300 | S17: 300 | T17: 300 | U17: 300
B18: Other Income | I18: -131 | J18: 216 | K18: 354 | L18: =224*1.33 -> 297.92 | M18: 300 | N18: 300 | O18: 300 | P18: 300 | Q18: 300 | R18: 300 | S18: 300 | T18: 300 | U18: 300
B19: Pretax | I19: =+I16+I17+I18 -> 660 | J19: =+J16+J17+J18 -> 4950 | K19: =+K16+K17+K18 -> 7438 | L19: =+L16+L17+L18 -> 10284.44 | M19: =+M16+M17+M18 -> 11906.144 | N19: =+N16+N17+N18 -> 13764.646 | O19: =+O16+O17+O18 -> 15128.709 | P19: =+P16+P17+P18 -> 16611.518 | ... U19: =+U16+U17+U18 -> 26607.942
B20: Taxes | I20: 452 | J20: 814 | K20: 1241 | L20: 1378 | M20: =+M19*0.15 -> 1785.9216 | N20: =+N19*0.15 -> 2064.697 | O20: =+O19*0.15 -> 2269.3064 | P20: =+P19*0.15 -> 2491.7277 | Q20: =+Q19*0.15 -> 2744.0645 | R20: =+R19*0.15 -> 3018.2854 | S20: =+S19*0.15 -> 3316.209 | T20: =+T19*0.15 -> 3639.8019 | U20: =+U19*0.15 -> 3991.1912
B21: Net Income | I21: =+I19-I20 -> 208 | J21: =+J19-J20 -> 4136 | K21: =+K19-K20 -> 6197 | L21: =+L19-L20 -> 8906.44 | M21: =+M19-M20 -> 10120.223 | N21: =+N19-N20 -> 11699.949 | O21: =+O19-O20 -> 12859.403 | P21: =+P19-P20 -> 14119.79 | ... U21: =+U19-U20 -> 22616.75 | V21: =+U21*(1+$X30) -> 23069.085 | W21: =+V21*(1+$X30) -> 23530.467 | X21: =+W21*(1+$X30) -> 24001.076 | Y21: =+X21*(1+$X30) -> 24481.098 | Z21: =+Y21*(1+$X30) -> 24970.72 | AA21: =+Z21*(1+$X30) -> 25470.134 | AB21: =+AA21*(1+$X30) -> 25979.537 | AC21: =+AB21*(1+$X30) -> 26499.128 | ... DB21: =+DA21*(1+$X30) -> 121743.23
B22: EPS | K22: =+K21/K23 -> 6.6136606 | L22: =+L21/L23 -> 9.5052721 | M22: =+M21/M23 -> 10.800664 | N22: =+N21/N23 -> 12.486606 | O22: =+O21/O23 -> 13.724016 | P22: =+P21/P23 -> 15.069146 | Q22: =+Q21/Q23 -> 16.595196 | R22: =+R21/R23 -> 18.253594 | ... U22: =+U21/U23 -> 24.137407
B23: Shares | K23: 937 | L23: =+K23+0 -> 937 | M23: =+L23+0 -> 937 | N23: =+M23+0 -> 937 | O23: =+N23+0 -> 937 | P23: =+O23+0 -> 937 | Q23: =+P23+0 -> 937 | R23: =+Q23+0 -> 937 | S23: =+R23+0 -> 937 | ... U23: =+T23+0 -> 937
B25: Gross Margin | I25: =+I10/I6 -> 0.73335034 | J25: =+J10/J6 -> 0.75497031 | K25: =+K10/K6 -> 0.77192242 | L25: =+L10/L6 -> 0.78302871 | M25: =+M10/M6 -> 0.78213694 | N25: =+N10/N6 -> 0.78551276 | O25: =+O10/O6 -> 0.78866163 | P25: =+P10/P6 -> 0.79159729 | ... U25: =+U10/U6 -> 0.80351442
B26: Sub Cost | I26: =+I7/I4 -> 0.20057889 | J26: =+J7/J4 -> 0.18984541 | K26: =+K7/K4 -> 0.17371563 | L26: =+L7/L4 -> 0.16674981
B27: Service Cost | I27: =+I8/I5 -> 1.0892321 | J27: =+J8/J5 -> 1.0189655 | K27: =+K8/K5 -> 1.1033394 | L27: =+L8/L5 -> 1.1129682
B28: Operating Margin | I28: =+I16/I6 -> 0.032852769 | J28: =+J16/J6 -> 0.14375879 | K28: =+K16/K6 -> 0.19013062 | L28: =+L16/L6 -> 0.23431942 | M28: =+M16/M6 -> 0.25299047 | N28: =+N16/N6 -> 0.27380029 | O28: =+O16/O6 -> 0.28078221 | P28: =+P16/P6 -> 0.2874641 | ... U28: =+U16/U6 -> 0.32203618
B29: Net Margin | I29: =+I21/I6 -> 0.0066343455 | J29: =+J21/J6 -> 0.11865622 | K29: =+K21/K6 -> 0.16353081 | L29: =+L21/L6 -> 0.21487189 | M29: =+M21/M6 -> 0.22645385 | N29: =+N21/N6 -> 0.2433373 | O29: =+O21/O6 -> 0.24852115 | P29: =+P21/P6 -> 0.25350081 | ... U29: =+U21/U6 -> 0.28004568 | W29: Discount | X29: 0.1
B30: Revenue Y/Y | E30: =+E6/D6 -1 -> 0.2601518 | F30: =+F6/E6 -1 -> 0.28730613 | G30: =+G6/F6 -1 -> 0.24295239 | H30: =+H6/G6 -1 -> 0.24656503 | I30: =+I6/H6 -1 -> 0.18345161 | J30: =+J6/I6 -1 -> 0.1117951 | K30: =+K6/J6 -1 -> 0.087156095 | L30: =+L6/K6 -1 -> 0.093811849 | ... U30: =+U6/T6 -1 -> 0.077544998 | W30: Terminal | X30: 0.02
B31: R&D | I31: =+I11/I$6 -> 0.16123373 | J31: =+J11/J$6 -> 0.14074648 | K31: =+K11/K$6 -> 0.14495316 | L31: =+L11/L$6 -> 0.14034789 | M31: =+M11/M$6 -> 0.13668138 | N31: =+N11/N$6 -> 0.13339321 | O31: =+O11/O$6 -> 0.13014901 | P31: =+P11/P$6 -> 0.12695176 | ... U31: =+U11/U$6 -> 0.10652536 | W31: NPV | X31: =NPV(X29,L21:DB21) -> 197584.36
B32: S&M | I32: =+I12/I$6 -> 0.43142383 | J32: =+J12/J$6 -> 0.36942365 | K32: =+K12/K$6 -> 0.34983507 | L32: =+L12/L$6 -> 0.331393 | M32: =+M12/M$6 -> 0.31351454 | N32: =+N12/N$6 -> 0.3 | O32: =+O12/O$6 -> 0.3 | P32: =+P12/P$6 -> 0.3 | ... U32: =+U12/U$6 -> 0.3 | W32: cash | X32: =+L43-L46+L44 -> 2885
B33: G&A | I33: =+I13/I$6 -> 0.081430212 | J33: =+J13/J$6 -> 0.072697019 | K33: =+K13/K$6 -> 0.074838369 | L33: =+L13/L$6 -> 0.067318215 | M33: =+M13/M$6 -> 0.07 | N33: =+N13/N$6 -> 0.07 | O33: =+O13/O$6 -> 0.07 | P33: =+P13/P$6 -> 0.07 | ... U33: =+U13/U$6 -> 0.07 | W33: Value | X33: =+X31+X32 -> 200469.36
W34: Shares | X34: 937
B35: CFFO | I35: 7111 | J35: 10234 | K35: 13092 | L35: =9532*1.33 -> 12677.56 | W35: Price | X35: =+X33/X34 -> 213.94809
B36: CapEx | I36: 798 | J36: 736 | K36: 658 | L36: 1446
B37: FCF | I37: =+I35-I36 -> 6313 | J37: =+J35-J36 -> 9498 | K37: =+K35-K36 -> 12434 | L37: =+L35-L36 -> 11231.56 | W37: EV/FCF | X37: =+Main!E7/Model!K39 -> 18.84726
B38: SBC | I38: 3279 | J38: 2787 | K38: 3183 | L38: =2426*1.33 -> 3226.58 | W38: FCF Yield | X38: =+K39/Main!E7 -> 0.053058111
B39: Adj. FCF | I39: =+I37-I38 -> 3034 | J39: =+J37-J38 -> 6711 | K39: =+K37-K38 -> 9251 | L39: =+L37-L38 -> 8004.98 | W39: EV/E | X39: =+Main!E7/Model!L21 -> 19.576396
B41: Strategic Investment | I41: 550 | J41: 496 | K41: 539
B43: Cash | K43: 8848 | L43: 8978
B44: Securities | K44: 5184 | L44: 2345
B45: PP&E | K45: 3236 | L45: 3147
...
