Workbook
Name TR: Model!$AF$88

Sheet Main
B3: 2023 | C3: Trucks NA | D3: Mercedes | E3: Trucks Asia | F3: Daimler Buses | G3: Financials | H3: Total | I3: Recon
B4: Europe | C4: 180 | D4: 14397 | E4: 480 | F4: 3039 | G4: 104 | H4: =+SUM(C4:G4) -> 18200 | I4: 1046 | J4: =+H4-I4 -> 17154
B5: NA | C5: 22964 | D5: 1197 | E5: 108 | F5: 440 | G5: 37 | H5: =+SUM(C5:G5) -> 24746 | I5: 1288 | J5: =+H5-I5 -> 23458
B6: Asia | C6: 6 | D6: 1953 | E6: 5721 | F6: 94 | G6: 15 | H6: =+SUM(C6:G6) -> 7789 | I6: 716 | J6: =+H6-I6 -> 7073
B7: Latin America | C7: 122 | D7: 2281 | E7: 171 | F7: 700 | G7: 21 | H7: =+SUM(C7:G7) -> 3295 | I7: 249 | J7: =+H7-I7 -> 3046
B8: Other Markets | C8: 190 | D8: 1157 | E8: 533 | F8: 102 | G8: 39 | H8: =+SUM(C8:G8) -> 2021 | I8: 42 | J8: =+H8-I8 -> 1979
B9: Other Revenue | C9: 29 | D9: 652 | E9: 47 | F9: 192 | G9: 2458 | H9: =+SUM(C9:G9) -> 3378 | I9: 199 | J9: =+H9-I9 -> 3179
B10: Total | C10: =+SUM(C4:C9) -> 23491 | D10: =+SUM(D4:D9) -> 21637 | E10: =+SUM(E4:E9) -> 7060 | F10: =+SUM(F4:F9) -> 4567 | G10: =+SUM(G4:G9) -> 2674 | H10: =+SUM(H4:H9) -> 59429 | I10: =+SUM(I4:I9) -> 3540 | J10: =+SUM(J4:J9) -> 55889
B13: 2022 | C13: Trucks NA | D13: Mercedes | E13: Trucks Asia | F13: Daimler Buses | G13: Financials | H13: Total | I13: Recon
B14: Europe | C14: 207 | D14: 12213 | E14: 381 | F14: 2456 | G14: 42 | H14: =+SUM(C14:G14) -> 15299 | I14: 864 | J14: =+H14-I14 -> 14435
B15: NA | C15: 21408 | D15: 1182 | E15: 130 | F15: 256 | G15: 46 | H15: =+SUM(C15:G15) -> 23022 | I15: 1285 | J15: =+H15-I15 -> 21737
B16: Asia | C16: 8 | D16: 1905 | E16: 5166 | F16: 62 | G16: 17 | H16: =+SUM(C16:G16) -> 7158 | I16: 689 | J16: =+H16-I16 -> 6469
B17: Latin America | C17: 175 | D17: 3442 | E17: 222 | F17: 643 | G17: 22 | H17: =+SUM(C17:G17) -> 4504 | I17: 253 | J17: =+H17-I17 -> 4251
B18: Other Markets | C18: 187 | D18: 908 | E18: 567 | F18: 77 | G18: 49 | H18: =+SUM(C18:G18) -> 1788 | I18: 48 | J18: =+H18-I18 -> 1740
B19: Other Revenue | C19: 54 | D19: 563 | E19: 33 | F19: 195 | G19: 1583 | H19: =+SUM(C19:G19) -> 2428 | I19: 115 | J19: =+H19-I19 -> 2313
B20: Total | C20: =+SUM(C14:C19) -> 22039 | D20: =+SUM(D14:D19) -> 20213 | E20: =+SUM(E14:E19) -> 6499 | F20: =+SUM(F14:F19) -> 3689 | G20: =+SUM(G14:G19) -> 1759 | H20: =+SUM(H14:H19) -> 54199 | I20: =+SUM(I14:I19) -> 3254 | J20: =+SUM(J14:J19) -> 50945

Sheet Model
C2: H1 23 | D2: H2 23 | E2: H1 24 | F2: H2 24 | O2: 2022 | P2: =+O2+1 -> 2023 | Q2: =+P2+1 -> 2024 | R2: =+Q2+1 -> 2025 | S2: =+R2+1 -> 2026 | T2: =+S2+1 -> 2027 | U2: =+T2+1 -> 2028 | V2: =+U2+1 -> 2029 | W2: =+V2+1 -> 2030 | ... AB2: =+AA2+1 -> 2035
B4: Units | O4: =+SUM(O5:O8) -> 533156 | P4: =+SUM(P5:P8) -> 540864 | Q4: =+SUM(Q5:Q8) -> 468785 | R4: =+SUM(R5:R8) -> 424698.8 | S4: =+SUM(S5:S8) -> 453496.57 | T4: =+SUM(T5:T8) -> 561567.27 | U4: =+SUM(U5:U8) -> 584304.93 | V4: =+SUM(V5:V8) -> 588948.82 | ... AB4: =+SUM(AB5:AB8) -> 687309.21
B5: Trucks NA | C5: 99509 | D5: =+P5-C5 -> 95505 | E5: 94450 | F5: 93000 | O5: 186779 | P5: 195014 | Q5: 190428 | R5: =+Q5*0.75 -> 142821 | S5: =+R5*1.125 -> 160673.62 | T5: =+S5*1.6 -> 257077.8 | U5: =+T5*1.04 -> 267360.91 | V5: =+U5*0.97 -> 259340.08 | W5: =+V5*1.02 -> 264526.89 | X5: =+W5*1.015 -> 268494.79 | Y5: =+X5*1.015 -> 272522.21 | Z5: =+Y5*1.015 -> 276610.04 | AA5: =+Z5*1.015 -> 280759.2 | AB5: =+AA5*1.015 -> 284970.58
B6: Mercedes Trucks | C6: 73728 | D6: =+P6-C6 -> 84783 | E6: 62489 | F6: 60000 | O6: 166369 | P6: 158511 | Q6: 126477 | R6: =+Q6*0.96 -> 121417.92 | S6: =+R6*1.035 -> 125667.55 | T6: =+S6*1.035 -> 130065.91 | U6: =+T6*1.035 -> 134618.22 | V6: =+U6*1.035 -> 139329.86 | W6: =+V6*1.035 -> 144206.4 | X6: =+W6*1.035 -> 149253.62 | Y6: =+X6*1.035 -> 154477.5 | Z6: =+Y6*1.035 -> 159884.21 | ... AB6: =+AA6*1.035 -> 171271.97
B7: Trucks Asia | C7: 80307 | D7: =+P7-C7 -> 80864 | E7: 65799 | F7: 60000 | O7: 155967 | P7: 161171 | Q7: 125234 | R7: =+Q7*1.06 -> 132748.04 | S7: =+R7*1.04 -> 138057.96 | T7: =+S7*1.04 -> 143580.28 | U7: =+T7*1.04 -> 149323.49 | V7: =+U7*1.04 -> 155296.43 | W7: =+V7*1.04 -> 161508.29 | X7: =+W7*1.03 -> 166353.54 | Y7: =+X7*1.03 -> 171344.14 | Z7: =+Y7*1.03 -> 176484.47 | AA7: =+Z7*1.03 -> 181779 | AB7: =+AA7*1.03 -> 187232.37
B8: Daimler Buses | C8: 11751 | D8: =+P8-C8 -> 14417 | E8: 12252 | F8: 15000 | O8: 24041 | P8: 26168 | Q8: 26646 | R8: =+Q8*1.04 -> 27711.84 | S8: =+R8*1.05 -> 29097.432 | T8: =+S8*1.06 -> 30843.278 | U8: =+T8*1.07 -> 33002.307 | V8: =+U8*1.06 -> 34982.446 | W8: =+V8*1.05 -> 36731.568 | X8: =+W8*1.04 -> 38200.831 | Y8: =+X8*1.04 -> 39728.864 | Z8: =+Y8*1.04 -> 41318.019 | AA8: =+Z8*1.03 -> 42557.559 | AB8: =+AA8*1.03 -> 43834.286
B10: Revenue/Unit | O10: =+O82/O4 *1000000 -> 95553.647 | P10: =+P82/P4 *1000000 -> 103334.66 | Q10: =+Q82/Q4 *1000000 -> 115355.65 | R10: =+R82/R4 *1000000 -> 111520.76 | S10: =+S82/S4 *1000000 -> 113864.16 | T10: =+T82/T4 *1000000 -> 119569.58 | U10: =+U82/U4 *1000000 -> 123437.84 | V10: =+V82/V4 *1000000 -> 127035.91 | ... AB10: =+AB82/AB4 *1000000 -> 152894.51
B11: Trucks NA | C11: =+C30/C5 *1000000 -> 118361.15 | D11: =+D30/D5 *1000000 -> 122642.79 | E11: =+E30/E5 *1000000 -> 125177.34 | F11: 125000 | O11: =+O30/O5 *1000000 -> 117995.06 | P11: =+P30/P5 *1000000 -> 120458.02 | Q11: =+Q30/Q5 *1000000 -> 124881.85 | R11: 135000 | S11: 135000 | T11: =+S11*1.03 -> 139050 | U11: =+T11*1.03 -> 143221.5 | V11: =+U11*1.03 -> 147518.14 | W11: =+V11*1.03 -> 151943.69 | X11: =+W11*1.03 -> 156502 | Y11: =+X11*1.03 -> 161197.06 | Z11: =+Y11*1.03 -> 166032.97 | AA11: =+Z11*1.03 -> 171013.96 | AB11: =+AA11*1.03 -> 176144.38
B12: Mercedes | C12: =+C31/C6 *1000000 -> 142998.59 | D12: =+D31/D6 *1000000 -> 130851.7 | E12: =+E31/E6 *1000000 -> 150554.5 | F12: 150000 | O12: =+O31/O6 *1000000 -> 121494.99 | P12: =+P31/P6 *1000000 -> 136501.57 | Q12: =+Q31/Q6 *1000000 -> 150976.07 | R12: 130000 | S12: 135000 | T12: =+S12*1.03 -> 139050 | U12: =+T12*1.03 -> 143221.5 | V12: =+U12*1.03 -> 147518.14 | W12: =+V12*1.03 -> 151943.69 | X12: =+W12*1.03 -> 156502 | Y12: =+X12*1.03 -> 161197.06 | Z12: =+Y12*1.03 -> 166032.97 | AA12: =+Z12*1.03 -> 171013.96 | AB12: =+AA12*1.03 -> 176144.38
B13: Trucks Asia | C13: =+C32/C7 *1000000 -> 42922.784 | D13: =+D32/D7 *1000000 -> 44679.956 | E13: =+E32/E7 *1000000 -> 44286.387 | F13: 44000 | O13: =+O32/O7 *1000000 -> 41669.071 | P13: =+P32/P7 *1000000 -> 43804.406 | Q13: =+Q32/Q7 *1000000 -> 48796.653 | R13: 46000 | S13: 45000 | T13: =+S13*1.03 -> 46350 | U13: =+T13*1.03 -> 47740.5 | V13: =+U13*1.03 -> 49172.715 | W13: =+V13*1.03 -> 50647.896 | X13: =+W13*1.03 -> 52167.333 | Y13: =+X13*1.03 -> 53732.353 | Z13: =+Y13*1.03 -> 55344.324 | AA13: =+Z13*1.03 -> 57004.654 | AB13: =+AA13*1.03 -> 58714.793
B14: Daimler Buses | C14: =+C33/C8 *1000000 -> 164071.14 | D14: =+D33/D8 *1000000 -> 183047.79 | E14: =+E33/E8 *1000000 -> 199314.4 | F14: 200000 | O14: =+O33/O8 *1000000 -> 153446.2 | P14: =+P33/P8 *1000000 -> 174526.14 | Q14: =+Q33/Q8 *1000000 -> 196915.11 | R14: 213000 | S14: =+R14*1.06 -> 225780 | T14: =+S14*1.05 -> 237069 | U14: =+T14*1.05 -> 248922.45 | V14: =+U14*1.05 -> 261368.57 | W14: =+V14*1.05 -> 274437 | X14: =+W14*1.05 -> 288158.85 | Y14: =+X14*1.05 -> 302566.79 | Z14: =+Y14*1.05 -> 317695.13 | AA14: =+Z14*1.05 -> 333579.89 | AB14: =+AA14*1.05 -> 350258.88
B16: EBIT/Unit
B17: Trucks NA | C17: =+C74/C5 *1000000 -> 14651.941 | D17: =+D74/D5 *1000000 -> 14962.567 | E17: =+E74/E5 *1000000 -> 16919.005 | F17: =+F74/F5 *1000000 -> 16875 | O17: =+O74/O5 *1000000 -> 12720.916 | P17: =+P74/P5 *1000000 -> 14804.065 | Q17: =+Q74/Q5 *1000000 -> 15795.996 | R17: =+R74/R5 *1000000 -> 16875 | S17: =+S74/S5 *1000000 -> 16875 | T17: =+T74/T5 *1000000 -> 17381.25 | U17: =+U74/U5 *1000000 -> 17902.688 | V17: =+V74/V5 *1000000 -> 18439.768 | ... Y17: =+Y74/Y5 *1000000 -> 20149.633
B18: Mercedes | C18: =+C75/C6 *1000000 -> 12858.073 | D18: =+D75/D6 *1000000 -> 12856.351 | E18: =+E75/E6 *1000000 -> 10033.766 | F18: =+F75/F6 *1000000 -> 10500 | O18: =+O75/O6 *1000000 -> 7140.7534 | P18: =+P75/P6 *1000000 -> 12857.152 | Q18: =+Q75/Q6 *1000000 -> 8554.9151 | R18: =+R75/R6 *1000000 -> 7800 | S18: =+S75/S6 *1000000 -> 8100 | T18: =+T75/T6 *1000000 -> 8343 | U18: =+U75/U6 *1000000 -> 8593.29 | V18: =+V75/V6 *1000000 -> 8851.0887 | ... Y18: =+Y75/Y6 *1000000 -> 9671.8236
B19: Trucks Asia | C19: =+C76/C7 *1000000 -> 2129.3287 | D19: =+D76/D7 *1000000 -> 1966.2643 | E19: =+E76/E7 *1000000 -> -501.52738 | F19: =+F76/F7 *1000000 -> -440 | O19: =+O76/O7 *1000000 -> 1032.2696 | P19: =+P76/P7 *1000000 -> 2047.5148 | Q19: =+Q76/Q7 *1000000 -> 503.05827 | R19: =+R76/R7 *1000000 -> 920 | S19: =+S76/S7 *1000000 -> 900 | T19: =+T76/T7 *1000000 -> 1158.75 | U19: =+U76/U7 *1000000 -> 1432.215 | V19: =+V76/V7 *1000000 -> 1475.1815 | ... Y19: =+Y76/Y7 *1000000 -> 1611.9706
B20: Daimler Buses | C20: =+C77/C8 *1000000 -> 3574.1639 | D20: =+D77/D8 *1000000 -> 11930.36 | E20: =+E77/E8 *1000000 -> 14201.763 | F20: =+F77/F8 *1000000 -> 15000 | O20: =+O77/O8 *1000000 -> -2162.9716 | P20: =+P77/P8 *1000000 -> 8177.9272 | Q20: =+Q77/Q8 *1000000 -> 16024.919 | R20: =+R77/R8 *1000000 -> 17040 | S20: =+S77/S8 *1000000 -> 18513.96 | T20: =+T77/T8 *1000000 -> 19913.796 | U20: =+U77/U8 *1000000 -> 21407.331 | V20: =+V77/V8 *1000000 -> 23000.434 | ... Y20: =+Y77/Y8 *1000000 -> 28441.279
B22: EBIT Margin
B23: Trucks NA | C23: =+C74/C30 -> 0.12379012 | D23: =+D74/D30 -> 0.1220012 | E23: =+E74/E30 -> 0.13516028 | F23: 0.135 | O23: =+O74/O30 -> 0.10780888 | P23: =+P74/P30 -> 0.12289813 | Q23: =+Q74/Q30 -> 0.12648753 | R23: 0.125 | S23: 0.125 | T23: 0.125 | U23: 0.125 | V23: 0.125 | W23: 0.125 | X23: 0.125 | Y23: 0.125 | Z23: 0.125 | AA23: 0.125 | AB23: 0.125
B24: Mercedes | C24: =+C75/C31 -> 0.089917481 | D24: =+D75/D31 -> 0.098251307 | E24: =+E75/E31 -> 0.066645408 | F24: 0.07 | O24: =+O75/O31 -> 0.058774056 | P24: =+P75/P31 -> 0.094190507 | Q24: =+Q75/Q31 -> 0.056664048 | R24: 0.06 | S24: 0.06 | T24: 0.06 | U24: 0.06 | V24: 0.06 | W24: 0.06 | X24: 0.06 | Y24: 0.06 | Z24: 0.06 | AA24: 0.06 | AB24: 0.06
B25: Trucks Asia | C25: =+C76/C32 -> 0.049608355 | D25: =+D76/D32 -> 0.04400775 | E25: =+E76/E32 -> -0.01132464 | F25: -0.01 | O25: =+O76/O32 -> 0.024773042 | P25: =+P76/P32 -> 0.04674221 | Q25: =+Q76/Q32 -> 0.010309278 | R25: 0.02 | S25: 0.02 | T25: 0.025 | U25: 0.03 | V25: 0.03 | W25: 0.03 | X25: 0.03 | Y25: 0.03 | Z25: 0.03 | AA25: 0.03 | AB25: 0.03
B26: Daimler Buses | C26: =+C77/C33 -> 0.021784232 | D26: =+D77/D33 -> 0.065176203 | E26: =+E77/E33 -> 0.071253071 | F26: 0.075 | O26: =+O77/O33 -> -0.014095961 | P26: =+P77/P33 -> 0.046857894 | Q26: =+Q77/Q33 -> 0.081379836 | R26: 0.08 | S26: =+R26+0.002 -> 0.082 | T26: =+S26+0.002 -> 0.084 | U26: =+T26+0.002 -> 0.086 | V26: =+U26+0.002 -> 0.088 | W26: =+V26+0.002 -> 0.09 | X26: =+W26+0.002 -> 0.092 | Y26: =+X26+0.002 -> 0.094 | Z26: =+Y26+0.002 -> 0.096 | ... AB26: =+AA26+0.002 -> 0.1
B27: Financial Service | C27: =+C78/C34 -> 0.079581994 | D27: =+D78/D34 -> 0.060839161 | E27: =+E78/E34 -> 0.037888199 | F27: 0.035 | O27: =+O78/O34 -> 0.1762365 | P27: =+P78/P34 -> 0.069558714 | Q27: =+Q78/Q34 -> 0.031793641 | R27: 0.035 | S27: 0.035 | T27: 0.035 | U27: 0.035 | V27: 0.035 | W27: 0.035 | X27: 0.035 | Y27: 0.035 | Z27: 0.035 | AA27: 0.035 | AB27: 0.035
B29: Revenue
B30: Trucks NA | C30: 11778 | D30: =+P30-C30 -> 11713 | E30: 11823 | F30: =+F11*F5/1000000 -> 11625 | O30: =+Main!C20 -> 22039 | P30: =+Main!C10 -> 23491 | Q30: 23781 | R30: =+R5*R11/1000000 -> 19280.835 | S30: =+S5*S11/1000000 -> 21690.939 | T30: =+T5*T11/1000000 -> 35746.668 | U30: =+U5*U11/1000000 -> 38291.831 | V30: =+V5*V11/1000000 -> 38257.368 | W30: =+W5*W11/1000000 -> 40193.191 | X30: =+X5*X11/1000000 -> 42019.972 | Y30: =+Y5*Y11/1000000 -> 43929.779 | ... AB30: =+AB5*AB11/1000000 -> 50195.967
B31: Mercedes | C31: 10543 | D31: =+P31-C31 -> 11094 | E31: 9408 | F31: =+F12*F6/1000000 -> 9000 | O31: =+Main!D20 -> 20213 | P31: =+Main!D10 -> 21637 | Q31: 19095 | R31: =+R6*R12/1000000 -> 15784.33 | S31: =+S6*S12/1000000 -> 16965.119 | T31: =+T6*T12/1000000 -> 18085.665 | U31: =+U6*U12/1000000 -> 19280.223 | V31: =+V6*V12/1000000 -> 20553.682 | W31: =+W6*W12/1000000 -> 21911.253 | X31: =+X6*X12/1000000 -> 23358.491 | Y31: =+Y6*Y12/1000000 -> 24901.319 | ... AB31: =+AB6*AB12/1000000 -> 30168.594
B32: Trucks Asia | C32: 3447 | D32: =+P32-C32 -> 3613 | E32: 2914 | F32: =+F13*F7/1000000 -> 2640 | O32: =+Main!E20 -> 6499 | P32: =+Main!E10 -> 7060 | Q32: 6111 | R32: =+R7*R13/1000000 -> 6106.4098 | S32: =+S7*S13/1000000 -> 6212.6083 | T32: =+T7*T13/1000000 -> 6654.946 | U32: =+U7*U13/1000000 -> 7128.7781 | V32: =+V7*V13/1000000 -> 7636.3471 | W32: =+W7*W13/1000000 -> 8180.0551 | X32: =+X7*X13/1000000 -> 8678.2204 | Y32: =+Y7*Y13/1000000 -> 9206.724 | ... AB32: =+AB7*AB13/1000000 -> 10993.31
B33: Daimler Buses | C33: 1928 | D33: =+P33-C33 -> 2639 | E33: 2442 | F33: =+F14*F8/1000000 -> 3000 | O33: =+Main!F20 -> 3689 | P33: =+Main!F10 -> 4567 | Q33: 5247 | R33: =+R8*R14/1000000 -> 5902.6219 | S33: =+S8*S14/1000000 -> 6569.6182 | T33: =+T8*T14/1000000 -> 7311.9851 | U33: =+U8*U14/1000000 -> 8215.0152 | V33: =+V8*V14/1000000 -> 9143.3119 | W33: =+W8*W14/1000000 -> 10080.501 | X33: =+X8*X14/1000000 -> 11007.908 | Y33: =+Y8*Y14/1000000 -> 12020.635 | ... AB33: =+AB8*AB14/1000000 -> 15353.348
B34: Financial Service | C34: 1244 | D34: =+P34-C34 -> 1430 | E34: 1610 | F34: 1700 | O34: =+Main!G20 -> 1759 | P34: =+Main!G10 -> 2674 | Q34: 3334 | R34: 3500 | S34: =+R34+200 -> 3700 | T34: =+S34+200 -> 3900 | U34: =+T34+200 -> 4100 | V34: =+U34+200 -> 4300 | W34: =+V34+200 -> 4500 | X34: =+W34+200 -> 4700 | Y34: =+X34+200 -> 4900 | Z34: =+Y34+200 -> 5100 | ... AB34: =+AA34+200 -> 5500
B35: Reconsiliation | O35: =-Main!I20 -> -3254 | P35: =-Main!I10 -> -3540 | Q35: =-0.0635*SUM(Q30:Q34) -> -3655.568 | R35: =-0.0635*SUM(R30:R34) -> -3211.4615 | S35: =-0.0635*SUM(S30:S34) -> -3501.2811 | T35: =-0.0635*SUM(T30:T34) -> -4552.9033 | U35: =-0.0635*SUM(U30:U34) -> -4890.5063 | V35: =-0.0635*SUM(V30:V34) -> -5073.06 | W35: =-0.0635*SUM(W30:W34) -> -5388.9275 | X35: =-0.0635*SUM(X30:X34) -> -5700.0515 | ... AB35: =-0.0635*SUM(AB30:AB34) -> -7125.4124
B37: COGS
B38: Trucks NA | O38: 18178 | P38: 18922
B39: Mercedes | O39: 16533 | P39: 16750
B40: Trucks Asia | O40: 5353 | P40: 5732
B41: Daimler Buses | O41: 3261 | P41: 3846
B43: Gross Profit
B44: Trucks NA | O44: =+O30-O38 -> 3861 | P44: =+P30-P38 -> 4569
B45: Mercedes | O45: =+O31-O39 -> 3680 | P45: =+P31-P39 -> 4887
B46: Trucks Asia | O46: =+O32-O40 -> 1146 | P46: =+P32-P40 -> 1328
B47: Daimler Buses | O47: =+O33-O41 -> 428 | P47: =+P33-P41 -> 721
B49: Selling
...
