Workbook
Name MV: Model!$AA$38

Sheet Main
B3: Porjects | C3: plus 17 oil&gas plants
C4: 138 Wind turbines for 2 GW | J4: 17B $ in 2023 | L4: Price | M4: 31
J5: =17000/M6 -> 0.16852707 | K5: Yield | L5: Shares | M5: 3254
C6: 7 complete 2021 | L6: Cap | M6: =+M4*M5 -> 100874
C7: 20 completions | J7: 2026 Supply come in (Qatar&Russia) | L7: Net Cash | M7: =+Model!AA40 -> 0
J8: Cashflow of 20B per year | L8: EV | M8: =+M6-M7 -> 100874
C9: 2020 | D9: 2021 | E9: =+D9+1 -> 2022 | G9: 35 exploration plants | J9: for the next Decade | M9: =+M8/M5 -> 31
G10: 3% production increase | N10: Oil&Gas: | Q10: 2021
B11: Exploration & Production Norway | J11: Dividend of | K11: =0.9*3+0.2 -> 2.9 | N11: Plant: | O11: Location | P11: Exp. Date | Q11: Production
B12: Revenue | C12: 11895 | D12: 39241 | E12: 75930 | J12: Dividend yield | K12: =+K11/M4 -> 0.093548387 | N12: Johan Sverdrup | O12: The North Sea | P12: 37 | Q12: 231
B13: Operating Income | C13: 3097 | D13: 30471 | E13: 67614 | N13: Troll Phase 1 | O13: The North Sea | P13: 30 | Q13: 198
B14: Assets involved | C14: 35301 | D14: 37733 | J14: unprofitable under 50$ curde oil | N14: Oseberg | O14: The North Sea | P14: 31 | Q14: 126
B15: Operating Expense | C15: =+C12-C13 -> 8798 | D15: =+D12-D13 -> 8770 | N15: Gullfaks | O15: The North Sea | P15: 36 | Q15: 88
N16: Aasta Hansteen | O16: The Norwegian Sea | P16: 41 | Q16: 76
B17: Exploration & Production International | N17: Visund | O17: The North Sea | P17: 34 | Q17: 68
B18: Revenue | C18: 3489 | D18: 5558 | E18: 7431 | N18: Asgard | O18: The Norwegian Sea | P18: 27 | Q18: 49
B19: Operating Income | C19: -3565 | D19: 326 | E19: 3806 | N19: Tyrihans | O19: The Norwegian Sea | P19: 29 | Q19: 39
B20: Assets involved | C20: 17835 | D20: 15358 | N20: Snorre | O20: The North Sea | P20: 40 | Q20: 34
N21: Kvutebjorn | O21: The North Sea | P21: 31 | Q21: 30
B22: Exploration & Production USA | N22: Grane | O22: The North Sea | P22: 30 | Q22: 23
B23: Revenue | C23: 2615 | D23: 4149 | E23: 5523 | N23: Martin Linge | O23: The North Sea | P23: 27 | Q23: 23
B24: Operating Income | C24: -3512 | D24: 1150 | E24: 4022 | N24: Statfjord Unit | O24: The North Sea | P24: 26 | Q24: 22
B25: Assets involved | C25: 12586 | D25: 11406 | N25: Troll Phase 2 | O25: The North Sea | P25: 30 | Q25: 22
N26: Sleipner West | O26: The North Sea | P26: 28 | Q26: 21
B27: Marketing, Midstream & Processing | H27: 60% increase | N27: Fram | O27: The North Sea | P27: 24 | Q27: 20
B28: Revenue | C28: 44945 | D28: 87368 | E28: 148105 | H28: FCF over 4 years | N28: Gina Krog | O28: The North Sea | P28: 32 | Q28: 18
B29: Operating Income | C29: 359 | D29: 1141 | E29: 3612 | H29: 25 Billion | N29: Gudrun | O29: The North Sea | P29: 32 | Q29: 16
B30: Assets involved | C30: 4368 | D30: 3019 | N30: Mikkel | O30: The Norwegian Sea | P30: 28 | Q30: 15
N31: Heidrun | O31: The Norwegian Sea | P31: 25 | Q31: 11
B32: Renewables | N32: Kristin | O32: The Norwegian Sea | P32: 33 | Q32: 10
B33: Revenue | C33: 181 | D33: 1411 | E33: 185 | N33: Vigdis area | O33: The North Sea | P33: 40 | Q33: 10
B34: Operating Income | C34: -35 | D34: 1245 | E34: -184 | N34: Trestakk | O34: The Norwegian Sea | P34: 29 | Q34: 10
B35: Assets involved | C35: 0 | D35: -45 | N35: Norne | O35: The Norwegian Sea | P35: 26 | Q35: 10
N36: Tordis area | O36: The North Sea | P36: 40 | Q36: 9
B37: Reserves | C37: 2021 | D37: =+C37+1 -> 2022 | N37: Valemon | O37: The North Sea | P37: 31 | Q37: 8
B38: Crude Oil | C38: 38307 | D38: 58524 | N38: Morvin | O38: The Norwegian Sea | P38: 27 | Q38: 6
B39: Natural Gas | C39: 28050 | D39: 65232 | N39: Roncador | O39: Brazil | P39: 52 | Q39: 37
B40: Refined | C40: 11473 | D40: 11093 | N40: Hebron | O40: Canada | P40: - | Q40: 12
B41: NGL | C41: 8490 | D41: 9240 | N41: Hibernia | O41: Canada | P41: - | Q41: 7
N42: Block 17 | O42: Angola | P42: 45 | Q42: 81
...

Sheet Model
C1: Q121 | D1: Q221 | E1: Q321 | F1: Q421 | G1: Q122 | H1: Q222 | I1: Q322 | J1: Q422 | M1: FY19 | N1: FY20 | O1: FY21 | P1: FY22 | Q1: FY23 | R1: FY24 | S1: FY25 | T1: FY26 | U1: FY27 | V1: FY28 | W1: FY29 | X1: FY30
B3: Production per Day | F3: 2158 | J3: 2046 | O3: 2079 | P3: =+P8+P9 -> 2039 | Q3: =+SUM(Q8:Q9) -> 2100.17
A4: REN | B4: Power Prod pa GWh | O4: 1562 | P4: 1649 | Q4: =+P4*1.01 -> 1665.49 | R4: =+Q4*1.01 -> 1682.1449 | S4: =+R4+Main!N81 -> 6982.1449 | T4: =+S4+Main!N82+Main!N83 -> 17582.145 | U4: =+T4+Main!N84 -> 26327.145 | V4: =+U4+5000 -> 31327.145 | W4: =+V4+5000 -> 36327.145 | X4: =+W4+5000 -> 41327.145
A5: Tot | B5: Power Prod pa GWh | O5: 1562 | P5: 2661
B6: Power Revenue | Q6: =+Q4*0.163 -> 271.47487 | R6: =+R4*0.163 -> 274.18962 | S6: =+S4*0.163 -> 1138.0896 | T6: =+T4*0.163 -> 2865.8896 | U6: =+U4*0.163 -> 4291.3246 | V6: =+V4*0.163 -> 5106.3246 | W6: =+W4*0.163 -> 5921.3246 | X6: =+X4*0.163 -> 6736.3246
B8: Oil Production pd | O8: 1076 | P8: 1013 | Q8: =+P8*1.03 -> 1043.39
B9: Gas Production pd | O9: 1003 | P9: 1026 | Q9: =+P9*1.03 -> 1056.78
B10: Crude Sold | O10: =+O15/O12 -> 547.24286 | P10: =+P15/P12 -> 622.59574 | Q10: 620 | R10: =+Q10*1.02 -> 632.4 | S10: =+R10*1.02 -> 645.048 | T10: =+S10*1.02 -> 657.94896 | U10: =+T10*1.02 -> 671.10794 | V10: =+U10*1.02 -> 684.5301 | W10: =+V10*1.02 -> 698.2207 | X10: =+W10*1.02 -> 712.18511
B11: Gas Sold | O11: =+O16/O13 -> 1921.2329 | P11: =+P16/P13 -> 2104.2581 | Q11: 2100 | R11: =+Q11*1.02 -> 2142 | S11: =+R11*1.02 -> 2184.84 | T11: =+S11*1.02 -> 2228.5368 | U11: =+T11*1.02 -> 2273.1075 | V11: =+U11*1.02 -> 2318.5697 | W11: =+V11*1.02 -> 2364.9411 | X11: =+W11*1.02 -> 2412.2399
B12: Crude Price | M12: 64 | N12: 39.7 | O12: 70 | P12: 94 | Q12: 85 | R12: =+Q12*0.97 -> 82.45 | S12: =+R12*0.97 -> 79.9765 | T12: =+S12*0.6 -> 47.9859 | U12: =+T12*1.02 -> 48.945618 | V12: =+U12*1.02 -> 49.92453 | W12: =+V12*1.02 -> 50.923021 | X12: =+W12*1.02 -> 51.941481
B13: Gas Price | M13: 5.8 | N13: 3.6 | O13: 14.6 | P13: 31 | Q13: 25 | R13: =+Q13*0.96 -> 24 | S13: =+R13*0.96 -> 23.04 | T13: =+S13*0.6 -> 13.824 | U13: =+T13*1.02 -> 14.10048 | V13: =+U13*1.02 -> 14.38249 | W13: =+V13*1.02 -> 14.670139 | X13: =+W13*1.02 -> 14.963542
B15: Crude Oil | O15: =+Main!C38 -> 38307 | P15: =+Main!D38 -> 58524 | Q15: =+Q10*Q12 -> 52700 | R15: =+R10*R12 -> 52141.38 | S15: =+S10*S12 -> 51588.681 | T15: =+T10*T12 -> 31572.273 | U15: =+U10*U12 -> 32847.793 | V15: =+V10*V12 -> 34174.844 | W15: =+W10*W12 -> 35555.507 | X15: =+X10*X12 -> 36991.95
B16: Natural Gas | O16: =+Main!C39 -> 28050 | P16: =+Main!D39 -> 65232 | Q16: =+Q11*Q13 -> 52500 | R16: =+R11*R13 -> 51408 | S16: =+S11*S13 -> 50338.714 | T16: =+T11*T13 -> 30807.293 | U16: =+U11*U13 -> 32051.907 | V16: =+V11*V13 -> 33346.804 | W16: =+W11*W13 -> 34694.015 | X16: =+X11*X13 -> 36095.654
B17: Refined | O17: =+Main!C40 -> 11473 | P17: =+Main!D40 -> 11093 | Q17: =+P17*0.98 -> 10871.14 | R17: =+Q17*0.98 -> 10653.717 | S17: =+R17*0.98 -> 10440.643 | T17: =+S17*0.98 -> 10231.83 | U17: =+T17*0.98 -> 10027.193 | V17: =+U17*0.98 -> 9826.6495 | W17: =+V17*0.98 -> 9630.1165 | X17: =+W17*0.98 -> 9437.5142
B18: NGL | O18: =+Main!C41 -> 8490 | P18: =+Main!D41 -> 9240 | Q18: =+P18*1.05 -> 9702 | R18: =+Q18*1.03 -> 9993.06 | S18: =+R18*1.02 -> 10192.921 | T18: =+S18*0.8 -> 8154.337 | U18: =+T18*0.8 -> 6523.4696 | V18: =+U18*0.8 -> 5218.7757 | W18: =+V18*0.8 -> 4175.0205 | X18: =+W18*0.8 -> 3340.0164
B19: Other | O19: =+O20-O18-O17-O16-O15 -> 4604 | P19: =+P20-P18-P17-P16-P15 -> 6717 | Q19: =+Q6 -> 271.47487 | R19: =+R6 -> 274.18962 | S19: =+S6 -> 1138.0896 | T19: =+T6 -> 2865.8896 | U19: =+U6 -> 4291.3246 | V19: =+V6 -> 5106.3246 | W19: =+W6 -> 5921.3246 | X19: =+X6 -> 6736.3246
B20: Revenue | C20: 17549 | D20: 17462 | E20: 23264 | F20: 32608 | G20: 36393 | H20: 36459 | I20: 43633 | J20: 34321 | M20: 64357 | N20: 45818 | O20: 90924 | P20: 150806 | Q20: =+SUM(Q15:Q19) -> 126044.61 | R20: =+SUM(R15:R19) -> 124470.35 | S20: =+SUM(S15:S19) -> 123699.05 | T20: =+SUM(T15:T19) -> 83631.622 | U20: =+SUM(U15:U19) -> 85741.688 | V20: =+SUM(V15:V19) -> 87673.398 | W20: =+SUM(W15:W19) -> 89975.984 | X20: =+SUM(X15:X19) -> 92601.459
B21: COGS | C21: 7166 | D21: 7399 | E21: 9052 | F21: 11543 | G21: 13510 | H21: 13851 | I21: 13592 | J21: 12853 | M21: 29532 | N21: 20986 | O21: 35160 | P21: 53806 | Q21: =+Q20*0.38 -> 47896.954 | R21: =+R20*0.38 -> 47298.732 | S21: =+S20*0.38 -> 47005.638 | T21: =+T20*0.38 -> 31780.016 | U21: =+U20*0.38 -> 32581.841 | V21: =+V20*0.38 -> 33315.891 | W21: =+W20*0.38 -> 34190.874 | X21: =+X20*0.38 -> 35188.554
B22: Gross Profit | C22: =+C20-C21 -> 10383 | D22: =+D20-D21 -> 10063 | E22: =+E20-E21 -> 14212 | F22: =+F20-F21 -> 21065 | G22: =+G20-G21 -> 22883 | H22: =+H20-H21 -> 22608 | I22: =+I20-I21 -> 30041 | J22: =+J20-J21 -> 21468 | M22: =+M20-M21 -> 34825 | N22: =+N20-N21 -> 24832 | O22: =+O20-O21 -> 55764 | P22: =+P20-P21 -> 97000 | Q22: =+Q20-Q21 -> 78147.661 | R22: =+R20-R21 -> 77171.615 | S22: =+S20-S21 -> 76693.41 | T22: =+T20-T21 -> 51851.606 | ... X22: =+X20-X21 -> 57412.904
B23: Operating Expense | C23: 1901 | D23: 2134 | E23: 2241 | F23: 2281 | G23: 1989 | H23: 2200 | I23: 2393 | J23: 3026 | M23: 9660 | N23: 8831 | O23: 8598 | P23: 9608 | Q23: =+P23*1.03 -> 9896.24 | R23: =+Q23*0.98 -> 9698.3152 | S23: =+R23*0.98 -> 9504.3489 | T23: =+S23*0.98 -> 9314.2619 | U23: =+T23*0.98 -> 9127.9767 | V23: =+U23*0.98 -> 8945.4171 | W23: =+V23*0.98 -> 8766.5088 | X23: =+W23*0.98 -> 8591.1786
B24: SG&A | C24: 218 | D24: 195 | E24: 145 | F24: 222 | G24: 282 | H24: 205 | I24: 221 | J24: 278 | M24: 809 | N24: 706 | O24: 780 | P24: 986 | Q24: =+P24*1.02 -> 1005.72 | R24: =+Q24*1.02 -> 1025.8344 | S24: =+R24*1.02 -> 1046.3511 | T24: =+S24*1.02 -> 1067.2781 | U24: =+T24*1.02 -> 1088.6237 | V24: =+U24*1.02 -> 1110.3961 | W24: =+V24*1.02 -> 1132.6041 | X24: =+W24*1.02 -> 1155.2561
B25: D&A | C25: 2797 | D25: 2111 | E25: 2034 | F25: 4777 | G25: 2017 | H25: 2140 | I25: 1049 | J25: 1184 | M25: 13204 | N25: 15235 | O25: 11719 | P25: 6391 | Q25: =+P25*0.98 -> 6263.18 | R25: =+Q25*0.98 -> 6137.9164 | S25: =+R25*0.98 -> 6015.1581 | T25: =+S25*0.98 -> 5894.8549 | U25: =+T25*0.98 -> 5776.9578 | V25: =+U25*0.98 -> 5661.4187 | W25: =+V25*0.98 -> 5548.1903 | X25: =+W25*0.98 -> 5437.2265
B26: R&D | C26: 247 | D26: 326 | E26: 226 | F26: 206 | G26: 203 | H26: 331 | I26: 275 | J26: 396 | M26: 1854 | N26: 3483 | O26: 1004 | P26: 1205 | Q26: =+P26*1.05 -> 1265.25 | R26: =+Q26*1.05 -> 1328.5125 | S26: =+R26*1.03 -> 1368.3679 | T26: =+S26*1.03 -> 1409.4189 | U26: =+T26*1.02 -> 1437.6073 | V26: =+U26*1.02 -> 1466.3594 | W26: =+V26*1.02 -> 1495.6866 | X26: =+W26*1.02 -> 1525.6004
B27: Operating Income | C27: =+C22-C23-C24-C25-C26 -> 5220 | D27: =+D22-D23-D24-D25-D26 -> 5297 | E27: =+E22-E23-E24-E25-E26 -> 9566 | F27: =+F22-F23-F24-F25-F26 -> 13579 | G27: =+G22-G23-G24-G25-G26 -> 18392 | H27: =+H22-H23-H24-H25-H26 -> 17732 | I27: =+I22-I23-I24-I25-I26 -> 26103 | J27: =+J22-J23-J24-J25-J26 -> 16584 | M27: =+M22-M23-M24-M25-M26 -> 9298 | N27: =+N22-N23-N24-N25-N26 -> -3423 | O27: =+O22-O23-O24-O25-O26 -> 33663 | P27: =+P22-P23-P24-P25-P26 -> 78810 | Q27: =+Q22-Q23-Q24-Q25-Q26 -> 59717.271 | R27: =+R22-R23-R24-R25-R26 -> 58981.037 | S27: =+S22-S23-S24-S25-S26 -> 58759.184 | T27: =+T22-T23-T24-T25-T26 -> 34165.792 | ... X27: =+X22-X23-X24-X25-X26 -> 40703.643
B28: Interest | C28: 312 | D28: 304 | E28: 308 | F28: 299 | G28: 226 | H28: 327 | I28: 336 | J28: 450 | M28: 1450 | N28: 1392 | O28: 1223 | P28: 1379 | Q28: =+P28*0.98 -> 1351.42 | R28: =+Q28*0.98 -> 1324.3916 | S28: =+R28*0.98 -> 1297.9038 | T28: =+S28*0.98 -> 1271.9457 | U28: =+T28*0.98 -> 1246.5068 | V28: =+U28*0.98 -> 1221.5766 | W28: =+V28*0.98 -> 1197.1451 | X28: =+W28*0.98 -> 1173.2022
B29: Finance | C29: 396 | D29: -90 | E29: -228 | F29: -143 | G29: -903 | H29: 2351 | I29: 1389 | J29: -1664 | M29: 1443 | N29: 556 | O29: -857 | P29: 1172 | Q29: 500 | R29: 500 | S29: 500 | T29: 500 | U29: 500 | V29: 500 | W29: 500 | X29: 500
B30: Pretax Income | C30: =+C27-C28+C29 -> 5304 | D30: =+D27-D28+D29 -> 4903 | E30: =+E27-E28+E29 -> 9030 | F30: =+F27-F28+F29 -> 13137 | G30: =+G27-G28+G29 -> 17263 | H30: =+H27-H28+H29 -> 19756 | I30: =+I27-I28+I29 -> 27156 | J30: =+J27-J28+J29 -> 14470 | M30: =+M27-M28+M29 -> 9291 | N30: =+N27-N28+N29 -> -4259 | O30: =+O27-O28+O29 -> 31583 | P30: =+P27-P28+P29 -> 78603 | Q30: =+Q27-Q28+Q29 -> 58865.851 | R30: =+R27-R28+R29 -> 58156.645 | S30: =+S27-S28+S29 -> 57961.28 | T30: =+T27-T28+T29 -> 33393.846 | ... X30: =+X27-X28+X29 -> 40030.441
B31: Taxes | C31: 2659 | D31: 2962 | E31: 7622 | F31: 9765 | G31: 12509 | H31: 12995 | I31: 17785 | J31: 6572 | M31: 7441 | N31: 1237 | O31: 23007 | P31: 49861 | Q31: =+Q30*0.65 -> 38262.803 | R31: =+R30*0.65 -> 37801.819 | S31: =+S30*0.65 -> 37674.832 | T31: =+T30*0.65 -> 21706 | U31: =+U30*0.65 -> 22738.413 | V31: =+V30*0.65 -> 23694.02 | W31: =+W30*0.65 -> 24794.234 | X31: =+X30*0.65 -> 26019.786
B32: Net Income | C32: =+C30-C31 -> 2645 | D32: =+D30-D31 -> 1941 | E32: =+E30-E31 -> 1408 | F32: =+F30-F31 -> 3372 | G32: =+G30-G31 -> 4754 | H32: =+H30-H31 -> 6761 | I32: =+I30-I31 -> 9371 | J32: =+J30-J31 -> 7898 | M32: =+M30-M31 -> 1850 | N32: =+N30-N31 -> -5496 | O32: =+O30-O31 -> 8576 | P32: =+P30-P31 -> 28742 | Q32: =+Q30-Q31 -> 20603.048 | R32: =+R30-R31 -> 20354.826 | S32: =+S30-S31 -> 20286.448 | T32: =+T30-T31 -> 11687.846 | ... X32: =+X30-X31 -> 14010.654 | Y32: =+X32*(1+MV) -> 14150.761 | Z32: =+Y32*(1+MV) -> 14292.268 | AA32: =+Z32*(1+MV) -> 14435.191 | AB32: =+AA32*(1+MV) -> 14579.543 | AC32: =+AB32*(1+MV) -> 14725.338 | AD32: =+AC32*(1+MV) -> 14872.592 | AE32: =+AD32*(1+MV) -> 15021.318 | AF32: =+AE32*(1+MV) -> 15171.531 | ... CU32: =+CT32*(1+MV) -> 29550.27
B33: Shares | C33: 3256 | D33: 3257 | E33: 3255 | F33: 3249 | G33: 3237 | H33: 3197 | I33: 3157 | J33: 3141 | M33: 3334 | N33: 3277 | O33: 3254 | P33: 3182 | Q33: =+P33*0.93 -> 2959.26 | R33: =+Q33 -> 2959.26 | S33: =+R33 -> 2959.26 | T33: =+S33 -> 2959.26 | U33: =+T33 -> 2959.26 | V33: =+U33 -> 2959.26 | W33: =+V33 -> 2959.26 | X33: =+W33 -> 2959.26
B34: EPS | M34: =+M32/M33 -> 0.55488902 | N34: =+N32/N33 -> -1.6771437 | O34: =+O32/O33 -> 2.6355255 | P34: =+P32/P33 -> 9.0326838 | Q34: =+Q32/Q33 -> 6.9622297 | R34: =+R32/R33 -> 6.8783499 | S34: =+S32/S33 -> 6.8552436 | T34: =+T32/T33 -> 3.9495841 | ... X34: =+X32/X33 -> 4.7345127
B35: EV/E | O35: =36.7/O34 -> 13.925117 | P35: =36.7/P34 -> 4.0630228 | Q35: =36.7/Q34 -> 5.2712998 | R35: =36.7/R34 -> 5.335582 | S35: =36.7/S34 -> 5.3535661 | T35: =36.7/T34 -> 9.2921177 | U35: =36.7/U34 -> 8.8702191 | V35: =36.7/V34 -> 8.512473 | ... X35: =36.7/X34 -> 7.7515897
B37: Gross Margin | C37: =+C22/C20 -> 0.59165764 | D37: =+D22/D20 -> 0.57627992 | E37: =+E22/E20 -> 0.61090096 | F37: =+F22/F20 -> 0.64600711 | G37: =+G22/G20 -> 0.62877476 | H37: =+H22/H20 -> 0.6200938 | I37: =+I22/I20 -> 0.68849265 | J37: =+J22/J20 -> 0.62550625 | M37: =+M22/M20 -> 0.54112218 | N37: =+N22/N20 -> 0.5419704 | O37: =+O22/O20 -> 0.61330342 | P37: =+P22/P20 -> 0.64321048 | Q37: =+Q22/Q20 -> 0.62 | R37: =+R22/R20 -> 0.62 | S37: =+S22/S20 -> 0.62 | T37: =+T22/T20 -> 0.62 | ... X37: =+X22/X20 -> 0.62 | Z37: Discount | AA37: 0.1
B38: Net Margin | C38: =+C32/C20 -> 0.15072084 | D38: =+D32/D20 -> 0.11115565 | E38: =+E32/E20 -> 0.060522696 | F38: =+F32/F20 -> 0.10341021 | G38: =+G32/G20 -> 0.13062952 | H38: =+H32/H20 -> 0.18544118 | I38: =+I32/I20 -> 0.21476864 | J38: =+J32/J20 -> 0.2301215 | M38: =+M32/M20 -> 0.028745902 | N38: =+N32/N20 -> -0.11995286 | O38: =+O32/O20 -> 0.094320531 | P38: =+P32/P20 -> 0.19058923 | Q38: =+Q32/Q20 -> 0.16345838 | R38: =+R32/R20 -> 0.16353153 | S38: =+S32/S20 -> 0.16399842 | T38: =+T32/T20 -> 0.13975391 | ... X38: =+X32/X20 -> 0.15130058 | Z38: Maturity | AA38: 0.01
B39: Taxes | C39: =+C31/C30 -> 0.50131976 | D39: =+D31/D30 -> 0.60411993 | E39: =+E31/E30 -> 0.8440753 | F39: =+F31/F30 -> 0.74332039 | G39: =+G31/G30 -> 0.72461333 | H39: =+H31/H30 -> 0.65777485 | I39: =+I31/I30 -> 0.65491972 | J39: =+J31/J30 -> 0.45418106 | M39: =+M31/M30 -> 0.80088257 | N39: =+N31/N30 -> -0.29044377 | O39: =+O31/O30 -> 0.72846151 | P39: =+P31/P30 -> 0.63433966 | Q39: =+Q31/Q30 -> 0.65 | R39: =+R31/R30 -> 0.65 | S39: =+S31/S30 -> 0.65 | T39: =+T31/T30 -> 0.65 | ... X39: =+X31/X30 -> 0.65 | Z39: NPV | AA39: =NPV(AA37,Q32:CV32) -> 160195.58
B41: Revenue Y/Y | N41: =+N20/M20 -1 -> -0.28806501 | O41: =+O20/N20 -1 -> 0.98446026 | P41: =+P20/O20 -1 -> 0.65859399 | Q41: =+Q20/P20 -1 -> -0.16419363 | R41: =+R20/Q20 -1 -> -0.012489768 | S41: =+S20/R20 -1 -> -0.0061966419 | T41: =+T20/S20 -1 -> -0.32391055 | U41: =+U20/T20 -1 -> 0.025230474 | ... X41: =+X20/W20 -1 -> 0.029179723 | Z41: Value | AA41: =+AA39+AA40 -> 160195.58
B42: Income Y/Y | O42: =+(O32/N32-1)*(-1) -> 2.5604076 | P42: =+P32/O32 -1 -> 2.3514459 | Q42: =+Q32/P32 -1 -> -0.28317278 | R42: =+R32/Q32 -1 -> -0.012047839 | S42: =+S32/R32 -1 -> -0.0033592802 | T42: =+T32/S32 -1 -> -0.42385941 | U42: =+U32/T32 -1 -> 0.047563491 | V42: =+V32/U32 -1 -> 0.042026103 | W42: =+W32/V32 -1 -> 0.046434243 | X42: =+X32/W32 -1 -> 0.049428925 | Z42: Price | AA42: =+AA41/Main!M5 -> 49.230357
Z43: Upside | AA43: =+AA42/Main!M4 -1 -> 0.58807604
B44: PP&E | M44: 71751 | N44: 68508 | O44: 62075 | P44: 56498
B45: Inventory | M45: 3363 | N45: 3084 | O45: 3395 | P45: 5205
...
