Workbook
Name TR: Sheet1!$AF$46

Sheet Sheet1
P2: 2022 | Q2: =+P2+1 -> 2023 | R2: =+Q2+1 -> 2024 | S2: =+R2+1 -> 2025 | T2: =+S2+1 -> 2026 | U2: =+T2+1 -> 2027 | V2: =+U2+1 -> 2028 | W2: =+V2+1 -> 2029 | X2: =+W2+1 -> 2030 | ... AC2: =+AB2+1 -> 2035
B4: US | P4: =+SUM(P5:P7) -> 3103 | Q4: =+SUM(Q5:Q7) -> 4404 | R4: =+SUM(R5:R7) -> 5798 | S4: =+SUM(S5:S7) -> 6914 | T4: =+S4*1.15 -> 7951.1 | U4: =+T4*1.12 -> 8905.232 | V4: =+U4*1.1 -> 9795.7552 | W4: =+V4*1.08 -> 10579.416 | X4: =+W4*1.08 -> 11425.769 | Y4: =+X4*1.08 -> 12339.83 | Z4: =+Y4*1.08 -> 13327.017 | AA4: =+Z4*1.08 -> 14393.178 | AB4: =+AA4*1.08 -> 15544.632 | AC4: =+AB4*1.08 -> 16788.203
B5: Sportsbook | P5: 2100 | Q5: 3072 | R5: 4013 | S5: =2353*2 -> 4706
B6: IGaming | P6: 687 | Q6: 1045 | R6: 1524 | S6: =979*2 -> 1958
B7: Other | P7: 316 | Q7: 287 | R7: 261 | S7: =125*2 -> 250
B9: UK | P9: =+SUM(P10:P12) -> 2664 | Q9: =+SUM(Q10:Q12) -> 3047 | R9: =+SUM(R10:R12) -> 3598 | S9: =+R9*1.15 -> 4137.7 | T9: =+S9*1.12 -> 4634.224 | U9: =+T9*1.12 -> 5190.3309 | V9: =+U9*1.1 -> 5709.364 | W9: =+V9*1.08 -> 6166.1131 | X9: =+W9*1.08 -> 6659.4021 | Y9: =+X9*1.08 -> 7192.1543 | Z9: =+Y9*1.08 -> 7767.5266 | AA9: =+Z9*1.08 -> 8388.9288 | AB9: =+AA9*1.08 -> 9060.0431 | AC9: =+AB9*1.08 -> 9784.8465
B10: Sportsbook | P10: 1323 | Q10: 1463 | R10: 1691
B11: IGaming | P11: 1189 | Q11: 1404 | R11: 1741
B12: Other | P12: 152 | Q12: 180 | R12: 166
B14: International | P14: =+SUM(P15:P17) -> 2138 | Q14: =+SUM(Q15:Q17) -> 2892 | R14: =+SUM(R15:R17) -> 3257 | S14: 3829 | T14: =+S14*1.15 -> 4403.35 | U14: =+T14*1.12 -> 4931.752 | V14: =+U14*1.1 -> 5424.9272 | W14: =+V14*1.08 -> 5858.9214 | X14: =+W14*1.08 -> 6327.6351 | Y14: =+X14*1.06 -> 6707.2932 | Z14: =+Y14*1.06 -> 7109.7308 | AA14: =+Z14*1.06 -> 7536.3146 | AB14: =+AA14*1.06 -> 7988.4935 | AC14: =+AB14*1.06 -> 8467.8031
B15: Sportsbook | P15: 335 | Q15: 603 | R15: 730
B16: IGaming | P16: 1696 | Q16: 2172 | R16: 2389
B17: Other | P17: 107 | Q17: 117 | R17: 138
B19: Australia
B20: Sportsbook | P20: 1558 | Q20: 1447 | R20: 1395 | S20: =+R20*0.95 -> 1325.25 | T20: =+S20*0.98 -> 1298.745 | U20: =+T20*0.98 -> 1272.7701 | V20: =+U20*0.98 -> 1247.3147 | W20: =+V20*0.98 -> 1222.3684 | X20: =+W20*0.98 -> 1197.921 | Y20: =+X20*0.98 -> 1173.9626 | Z20: =+Y20*0.98 -> 1150.4834 | AA20: =+Z20*0.98 -> 1127.4737 | ... AC20: =+AB20*0.98 -> 1082.8257
B23: Sportsbook | P23: =+P20+P15+P10+P5 -> 5316 | Q23: =+Q20+Q15+Q10+Q5 -> 6585 | R23: =+R20+R15+R10+R5 -> 7829
B24: IGaming | P24: =+P16+P11+P6 -> 3572 | Q24: =+Q16+Q11+Q6 -> 4621 | R24: =+R16+R11+R6 -> 5654
B25: Other | P25: =+P17+P12+P7 -> 575 | Q25: =+Q17+Q12+Q7 -> 584 | R25: =+R17+R12+R7 -> 565
B26: Revenue | P26: 9463 | Q26: 11790 | R26: 14048 | S26: =+S20+S14+S9+S4 -> 16205.95 | T26: =+T20+T14+T9+T4 -> 18287.419 | U26: =+U20+U14+U9+U4 -> 20300.085 | V26: =+V20+V14+V9+V4 -> 22177.361 | W26: =+W20+W14+W9+W4 -> 23826.818 | X26: =+X20+X14+X9+X4 -> 25610.727 | Y26: =+Y20+Y14+Y9+Y4 -> 27413.24 | Z26: =+Z20+Z14+Z9+Z4 -> 29354.758 | ... AC26: =+AC20+AC14+AC9+AC4 -> 36123.678
B27: COGS | P27: 4813 | Q27: 6202 | R27: 7346 | S27: =+Sheet2!S25+Sheet2!S33+Sheet2!S41+Sheet2!S49 -> 8141.989 | T27: =+T26*0.5 -> 9143.7095 | U27: =+U26*0.5 -> 10150.042 | V27: =+V26*0.5 -> 11088.681 | W27: =+W26*0.5 -> 11913.409 | X27: =+X26*0.5 -> 12805.364 | Y27: =+Y26*0.5 -> 13706.62 | Z27: =+Z26*0.5 -> 14677.379 | AA27: =+AA26*0.5 -> 15722.948 | ... AC27: =+AC26*0.5 -> 18061.839
B28: Profit | P28: =+P26-P27 -> 4650 | Q28: =+Q26-Q27 -> 5588 | R28: =+R26-R27 -> 6702 | S28: =+S26-S27 -> 8063.961 | T28: =+T26-T27 -> 9143.7095 | U28: =+U26-U27 -> 10150.042 | V28: =+V26-V27 -> 11088.681 | W28: =+W26-W27 -> 11913.409 | ... AC28: =+AC26-AC27 -> 18061.839
B29: R&D | P29: 552 | Q29: 765 | R29: 820 | S29: =+S26*0.06 -> 972.357 | T29: =+T26*0.06 -> 1097.2451 | U29: =+U26*0.06 -> 1218.0051 | V29: =+V26*0.06 -> 1330.6417 | W29: =+W26*0.06 -> 1429.6091 | X29: =+X26*0.06 -> 1536.6436 | Y29: =+Y26*0.06 -> 1644.7944 | Z29: =+Z26*0.06 -> 1761.2855 | ... AC29: =+AC26*0.06 -> 2167.4207
B30: Sales | P30: 3014 | Q30: 3776 | R30: 3205 | S30: =+S26*0.2 -> 3241.19 | T30: =+T26*0.2 -> 3657.4838 | U30: =+U26*0.2 -> 4060.017 | V30: =+V26*0.2 -> 4435.4722 | W30: =+W26*0.2 -> 4765.3637 | X30: =+X26*0.2 -> 5122.1454 | Y30: =+Y26*0.2 -> 5482.6481 | Z30: =+Z26*0.2 -> 5870.9515 | ... AC30: =+AC26*0.2 -> 7224.7357
B31: G&A | P31: 1172 | Q31: 1596 | R31: 1808 | S31: =956*2 -> 1912 | T31: =+S31*1.04 -> 1988.48 | U31: =+T31*1.04 -> 2068.0192 | V31: =+U31*1.04 -> 2150.74 | W31: =+W26*0.1 -> 2382.6818 | X31: =+X26*0.1 -> 2561.0727 | Y31: =+Y26*0.1 -> 2741.324 | Z31: =+Z26*0.1 -> 2935.4758 | AA31: =+AA26*0.1 -> 3144.5895 | AB31: =+AB26*0.1 -> 3369.8093 | AC31: =+AC26*0.1 -> 3612.3678
B32: Operating Income | P32: =+P28-P30-P29-P31 -> -88 | Q32: =+Q28-Q30-Q29-Q31 -> -549 | R32: =+R28-R30-R29-R31 -> 869 | S32: =+S28-S30-S29-S31 -> 1938.414 | T32: =+T28-T30-T29-T31 -> 2400.5006 | U32: =+U28-U30-U29-U31 -> 2804.0012 | V32: =+V28-V30-V29-V31 -> 3171.8267 | W32: =+W28-W30-W29-W31 -> 3335.7546 | ... AC32: =+AC28-AC30-AC29-AC31 -> 5057.315
B33: Other Income | P33: 5 | Q33: -157 | R33: -434 | S33: 142 | T33: 100 | U33: 100 | V33: 100 | W33: 100 | X33: 100 | Y33: 100 | Z33: 100 | AA33: 100 | AB33: 100 | AC33: 100
B34: Interest, net | P34: -212 | Q34: -385 | R34: -419 | S34: -450 | T34: =-T56*T58 -> -391.30137 | U34: =-U56*U58 -> -320.1159 | V34: =-V56*V58 -> -232.90977 | W34: =-W56*W58 -> -130.34632 | X34: =-X56*X58 -> -18.788794 | Y34: =-Y56*Y58 -> 104.96277 | Z34: =-Z56*Z58 -> 241.40783 | AA34: =-AA56*AA58 -> 391.63157 | ... AC34: =-AC56*AC58 -> 738.19668
B35: Pretax | P35: =+P32+P33+P34 -> -295 | Q35: =+Q32+Q33+Q34 -> -1091 | R35: =+R32+R33+R34 -> 16 | S35: =+S32+S33+S34 -> 1630.414 | T35: =+T32+T33+T34 -> 2109.1992 | U35: =+U32+U33+U34 -> 2583.8853 | V35: =+V32+V33+V34 -> 3038.9169 | W35: =+W32+W33+W34 -> 3305.4083 | ... AC35: =+AC32+AC33+AC34 -> 5895.5117
B36: Taxes | P36: 75 | Q36: 120 | R36: -146 | S36: =187*2 -> 374 | T36: =+T35*0.25 -> 527.2998 | U36: =+U35*0.25 -> 645.97132 | V36: =+V35*0.25 -> 759.72923 | W36: =+W35*0.25 -> 826.35207 | X36: =+X35*0.25 -> 916.67825 | Y36: =+Y35*0.25 -> 1010.7041 | Z36: =+Z35*0.25 -> 1112.7685 | AA36: =+AA35*0.25 -> 1223.5142 | ... AC36: =+AC35*0.25 -> 1473.8779
B37: Net Income | P37: =+P35-P36 -> -370 | Q37: =+Q35-Q36 -> -1211 | R37: =+R35-R36 -> 162 | S37: =+S35-S36 -> 1256.414 | T37: =+T35-T36 -> 1581.8994 | U37: =+U35-U36 -> 1937.914 | V37: =+V35-V36 -> 2279.1877 | W37: =+W35-W36 -> 2479.0562 | ... AC37: =+AC35-AC36 -> 4421.6337 | AD37: =+AC37*(1+TR) -> 4510.0664 | AE37: =+AD37*(1+TR) -> 4600.2677 | AF37: =+AE37*(1+TR) -> 4692.2731 | AG37: =+AF37*(1+TR) -> 4786.1186 | AH37: =+AG37*(1+TR) -> 4881.8409 | AI37: =+AH37*(1+TR) -> 4979.4778 | AJ37: =+AI37*(1+TR) -> 5079.0673 | AK37: =+AJ37*(1+TR) -> 5180.6487 | ... DA37: =+CZ37*(1+TR) -> 19915.711
B38: EPS | R38: =+R37/R39 -> 0.92426336 | S38: =+S37/S39 -> 7.1682557 | T38: =+T37/T39 -> 9.0252571 | U38: =+U37/U39 -> 11.056438 | V38: =+V37/V39 -> 13.003517 | W38: =+W37/W39 -> 14.143832 | X38: =+X37/X39 -> 15.689854 | Y38: =+Y37/Y39 -> 17.2992 | ... AC38: =+AC37/AC39 -> 25.226877
B39: Shares | R39: 175.27472 | S39: 175.27472 | T39: 175.27472 | U39: 175.27472 | V39: 175.27472 | W39: 175.27472 | X39: 175.27472 | Y39: 175.27472 | Z39: 175.27472 | AA39: 175.27472 | AB39: 175.27472 | AC39: 175.27472
B41: Gross Margin | P41: =+P28/P26 -> 0.49138751 | Q41: =+Q28/Q26 -> 0.47396098 | R41: =+R28/R26 -> 0.47707859 | S41: =+S28/S26 -> 0.49759261 | T41: =+T28/T26 -> 0.5 | U41: =+U28/U26 -> 0.5 | V41: =+V28/V26 -> 0.5 | W41: =+W28/W26 -> 0.5 | ... AC41: =+AC28/AC26 -> 0.5
B42: R&D | P42: =+P29/P26 -> 0.058332453 | Q42: =+Q29/Q26 -> 0.064885496 | R42: =+R29/R26 -> 0.058371298 | S42: =+S29/S26 -> 0.06 | T42: =+T29/T26 -> 0.06 | U42: =+U29/U26 -> 0.06 | V42: =+V29/V26 -> 0.06 | W42: =+W29/W26 -> 0.06 | ... AC42: =+AC29/AC26 -> 0.06
B43: Sales | P43: =+P30/P26 -> 0.31850365 | Q43: =+Q30/Q26 -> 0.32027142 | R43: =+R30/R26 -> 0.22814636 | S43: =+S30/S26 -> 0.2 | T43: =+T30/T26 -> 0.2 | U43: =+U30/U26 -> 0.2 | V43: =+V30/V26 -> 0.2 | W43: =+W30/W26 -> 0.2 | ... AC43: =+AC30/AC26 -> 0.2
B44: G&A | P44: =+P31/P26 -> 0.12385079 | Q44: =+Q31/Q26 -> 0.13536896 | R44: =+R31/R26 -> 0.12870159 | S44: =+S31/S26 -> 0.11798136 | T44: =+T31/T26 -> 0.10873486 | U44: =+U31/U26 -> 0.10187244 | V44: =+V31/V26 -> 0.096979075 | W44: =+W31/W26 -> 0.1 | ... AC44: =+AC31/AC26 -> 0.1
B45: Net Margin | P45: =+P37/P26 -> -0.039099651 | Q45: =+Q37/Q26 -> -0.10271416 | R45: =+R37/R26 -> 0.011531891 | S45: =+S37/S26 -> 0.077527945 | T45: =+T37/T26 -> 0.086502059 | U45: =+U37/U26 -> 0.095463343 | V45: =+V37/V26 -> 0.10277092 | W45: =+W37/W26 -> 0.10404478 | ... AC45: =+AC37/AC26 -> 0.12240264
AE46: TR | AF46: 0.02
B47: Revenue Y/Y | Q47: =+Q26/P26 -1 -> 0.2459051 | R47: =+R26/Q26 -1 -> 0.19151824 | S47: =+S26/R26 -1 -> 0.15361261 | T47: =+T26/S26 -1 -> 0.12843857 | U47: =+U26/T26 -1 -> 0.11005741 | V47: =+V26/U26 -1 -> 0.092476267 | W47: =+W26/V26 -1 -> 0.07437573 | X47: =+X26/W26 -1 -> 0.074869779 | ... AC47: =+AC26/AB26 -1 -> 0.071979894 | AE47: DR | AF47: 0.08
AE48: NPV | AF48: =NPV(AF47,S37:DA37) -> 50145.43
...

Sheet Sheet2
P2: 2022 | Q2: =+P2+1 -> 2023 | R2: =+Q2+1 -> 2024 | S2: =+R2+1 -> 2025
B4: US | P4: =+SUM(P5:P7) -> 3103 | Q4: =+SUM(Q5:Q7) -> 4404 | R4: =+SUM(R5:R7) -> 5798
B5: Sportsbook | P5: 2100 | Q5: 3072 | R5: 4013 | S5: =3164*2 -> 6328
B6: IGaming | P6: 687 | Q6: 1045 | R6: 1524 | S6: =946*2 -> 1892
B7: Other | P7: 316 | Q7: 287 | R7: 261 | S7: =486*2 -> 972
B9: UK | P9: =+SUM(P10:P12) -> 2664 | Q9: =+SUM(Q10:Q12) -> 3047 | R9: =+SUM(R10:R12) -> 3598
B10: Sportsbook | P10: 1323 | Q10: 1463 | R10: 1691
B11: IGaming | P11: 1189 | Q11: 1404 | R11: 1741
B12: Other | P12: 152 | Q12: 180 | R12: 166
B14: International | P14: =+SUM(P15:P17) -> 2138 | Q14: =+SUM(Q15:Q17) -> 2892 | R14: =+SUM(R15:R17) -> 3257
B15: Sportsbook | P15: 335 | Q15: 603 | R15: 730
B16: IGaming | P16: 1696 | Q16: 2172 | R16: 2389
B17: Other | P17: 107 | Q17: 117 | R17: 138
B19: Australia
B20: Sportsbook | P20: 1558 | Q20: 1447 | R20: 1395
B23: US
B24: Revenue | P24: 3103 | Q24: 4404 | R24: 5798 | S24: =+Sheet1!S4 -> 6914 | U24: COGS
B25: COGS | P25: 1787 | Q25: 2534 | R25: 3353 | S25: =+S24*0.58 -> 4010.12 | U25: R&D
B26: R&D | P26: 108 | Q26: 196 | R26: 270 | S26: 350 | U26: Sales
B27: Sales | P27: 1142 | Q27: 1150 | R27: 1278 | S27: 1150 | U27: G&A
B28: G&A | P28: 241 | Q28: 292 | R28: 390 | S28: 400 | U28: EBITDA
B29: EBITDA | P29: =+P24-P25-P26-P27-P28 -> -175 | Q29: =+Q24-Q25-Q26-Q27-Q28 -> 232 | R29: =+R24-R25-R26-R27-R28 -> 507 | S29: =+S24-S25-S26-S27-S28 -> 1003.88
P30: =+P25/P24 -> 0.5758943 | Q30: =+Q25/Q24 -> 0.57538601 | R30: =+R25/R24 -> 0.57830286
B31: UKI
B32: Revenue | P32: 2664 | Q32: 3047 | R32: 3598 | S32: =+Sheet1!S9 -> 4137.7
B33: COGS | P33: 978 | Q33: 1113 | R33: 1287 | S33: =+S32*0.37 -> 1530.949
B34: R&D | P34: 135 | Q34: 155 | R34: 162 | S34: 200
B35: Sales | P35: 542 | Q35: 591 | R35: 700 | S35: 800
B36: G&A | P36: 233 | Q36: 277 | R36: 332 | S36: 350
B37: EBITDA | P37: =+P32-P33-P34-P35-P36 -> 776 | Q37: =+Q32-Q33-Q34-Q35-Q36 -> 911 | R37: =+R32-R33-R34-R35-R36 -> 1117 | S37: =+S32-S33-S34-S35-S36 -> 1256.751
P38: =+P33/P32 -> 0.36711712 | Q38: =+Q33/Q32 -> 0.36527732 | R38: =+R33/R32 -> 0.35769872
B39: Internation
B40: Revenue | P40: 2138 | Q40: 2892 | R40: 3257 | S40: =+Sheet1!S14 -> 3829
B41: COGS | P41: 951 | Q41: 1342 | R41: 1521 | S41: =+S40*0.48 -> 1837.92
B42: R&D | P42: 168 | Q42: 206 | R42: 207 | S42: 250
B43: Sales | P43: 484 | Q43: 456 | R43: 471 | S43: 480
B44: G&A | P44: 207 | Q44: 326 | R44: 405 | S44: 450
B45: EBITDA | P45: =+P40-P41-P42-P43-P44 -> 328 | Q45: =+Q40-Q41-Q42-Q43-Q44 -> 562 | R45: =+R40-R41-R42-R43-R44 -> 653 | S45: =+S40-S41-S42-S43-S44 -> 811.08
P46: =+P41/P40 -> 0.44480823 | Q46: =+Q41/Q40 -> 0.46403873 | R46: =+R41/R40 -> 0.46699417
B47: Australia
...
