Workbook

Sheet Sheet2
B3: Price | C3: 40.8
B4: Shares | C4: 455.5
B5: MC | C5: =+C3*C4 -> 18584.4
B6: Net Cash | C6: =5198+2263-6471-4956 -> -3966 | D6: Q3 25
B7: EV | C7: =+C5-C6 -> 22550.4
B9: EV/FCF | C9: =+C7/Sheet1!F46 -> 20.591152
B10: FCF Yield | C10: =1/C9 -> 0.048564549
B12: Div. Yield | C12: =+Sheet1!F51/Sheet2!C3 -> 0.020098039

Sheet Sheet1
D2: 2023 | E2: =+D2+1 -> 2024 | F2: =+E2+1 -> 2025 | G2: =+F2+1 -> 2026 | H2: =+G2+1 -> 2027 | I2: =+H2+1 -> 2028 | J2: =+I2+1 -> 2029 | K2: =+J2+1 -> 2030 | L2: =+K2+1 -> 2031 | ... P2: =+O2+1 -> 2035
B4: Porsche 911 | D4: 50146 | E4: 50941 | F4: 51583 | G4: =+F4*1.015 -> 52356.745 | H4: =+G4*1.015 -> 53142.096 | I4: =+H4*1.015 -> 53939.228 | J4: =+I4*1.015 -> 54748.316 | K4: =+J4*1.015 -> 55569.541 | L4: =+K4*1.015 -> 56403.084 | M4: =+L4*1.015 -> 57249.13 | N4: =+M4*1.015 -> 58107.867 | ... P4: =+O4*1.015 -> 59864.177
B5: Porsche 718 | D5: 20518 | E5: 23670 | F5: 18612 | G5: =+F5*1.02 -> 18984.24 | H5: =+G5*1.02 -> 19363.925 | I5: =+H5*1.02 -> 19751.203 | J5: =+I5*1.02 -> 20146.227 | K5: =+J5*1.02 -> 20549.152 | L5: =+K5*1.02 -> 20960.135 | M5: =+L5*1.02 -> 21379.338 | N5: =+M5*1.02 -> 21806.924 | ... P5: =+O5*1.02 -> 22687.924
B6: Cayenne | D6: 87553 | E6: 102889 | F6: 80886 | G6: =+F6*1.015 -> 82099.29 | H6: =+G6*1.015 -> 83330.779 | I6: =+H6*1.015 -> 84580.741 | J6: =+I6*1.015 -> 85849.452 | K6: =+J6*1.015 -> 87137.194 | L6: =+K6*1.015 -> 88444.252 | M6: =+L6*1.015 -> 89770.916 | N6: =+M6*1.015 -> 91117.479 | ... P6: =+O6*1.015 -> 93871.505
B7: Panamera | D7: 34020 | E7: 29587 | F7: 27701 | G7: =+F7*0.98 -> 27146.98 | H7: =+G7*0.98 -> 26604.04 | I7: =+H7*0.98 -> 26071.96 | J7: =+I7*0.98 -> 25550.52 | K7: =+J7*0.98 -> 25039.51 | L7: =+K7*0.98 -> 24538.72 | M7: =+L7*0.98 -> 24047.945 | N7: =+M7*0.98 -> 23566.986 | ... P7: =+O7*0.98 -> 22633.734
B8: Macan | D8: 87355 | E8: 82795 | F8: 84328 | G8: =+F8*1.025 -> 86436.2 | H8: =+G8*1.025 -> 88597.105 | I8: =+H8*1.025 -> 90812.033 | J8: =+I8*1.025 -> 93082.333 | K8: =+J8*1.025 -> 95409.392 | L8: =+K8*1.025 -> 97794.627 | M8: =+L8*1.025 -> 100239.49 | N8: =+M8*1.025 -> 102745.48 | ... P8: =+O8*1.025 -> 107946.97
B9: Macan EV | F9: 45367
B10: Taycan | D10: 40629 | E10: 20836 | F10: 16339 | G10: =+F10*0.95 -> 15522.05 | H10: =+G10*0.95 -> 14745.947 | I10: =+H10*0.95 -> 14008.65 | J10: =+I10*0.95 -> 13308.218 | K10: =+J10*0.95 -> 12642.807 | L10: =+K10*0.95 -> 12010.666 | M10: =+L10*0.95 -> 11410.133 | N10: =+M10*0.95 -> 10839.626 | ... P10: =+O10*0.95 -> 9782.7629
B11: Cars Sold | D11: =+SUM(D12:D16) -> 320221 | E11: =+SUM(E12:E16) -> 310718 | F11: 279449 | G11: =+SUM(G4:G10) -> 282545.51 | H11: =+SUM(H4:H10) -> 285783.89 | I11: =+SUM(I4:I10) -> 289163.81 | J11: =+SUM(J4:J10) -> 292685.07 | K11: =+SUM(K4:K10) -> 296347.6 | L11: =+SUM(L4:L10) -> 300151.48 | M11: =+SUM(M4:M10) -> 304096.95 | N11: =+SUM(N4:N10) -> 308184.36 | ... P11: =+SUM(P4:P10) -> 316787.07
B12: Germany | D12: 32430 | E12: 35858
B13: North America | D13: 86059 | E13: 86541
B14: China | D14: 79283 | E14: 56887
B15: Europe | D15: 70229 | E15: 75899
B16: EM | D16: 52220 | E16: 55533
B18: Umsatz/Auto | D18: =+D20/D11 *1000 -> 126.56884 | E18: =+E20/E11 *1000 -> 129.00122 | F18: =+F20/F11 *1000 -> 129.77824 | G18: =+F18*1.01 -> 131.07602 | H18: =+G18*1.01 -> 132.38678 | I18: =+H18*1.01 -> 133.71065 | J18: =+I18*1.01 -> 135.04776 | K18: =+J18*1.01 -> 136.39824 | L18: =+K18*1.01 -> 137.76222 | M18: =+L18*1.01 -> 139.13984 | N18: =+M18*1.01 -> 140.53124 | ... P18: =+O18*1.01 -> 143.35592
B20: Umsatz | D20: 40530 | E20: 40083 | F20: =26864*1.35 -> 36266.4 | G20: =+G18*G11/1000 -> 37034.942 | H20: =+H18*H11/1000 -> 37834.011 | I20: =+I18*I11/1000 -> 38664.282 | J20: =+J18*J11/1000 -> 39526.462 | K20: =+K18*K11/1000 -> 40421.289 | L20: =+L18*L11/1000 -> 41349.534 | M20: =+M18*M11/1000 -> 42312.002 | N20: =+N18*N11/1000 -> 43309.531 | ... P20: =+P18*P11/1000 -> 45413.302
B21: COGS | D21: 28924 | E21: 29756 | F21: =23590*1.35 -> 31846.5 | G21: =+G20*0.85 -> 31479.7 | H21: =+H20*0.82 -> 31023.889 | I21: =+I20*0.8 -> 30931.426 | J21: =+J20*0.78 -> 30830.641 | K21: =+K20*0.75 -> 30315.967 | L21: =+L20*0.75 -> 31012.151 | M21: =+M20*0.75 -> 31734.001 | N21: =+N20*0.75 -> 32482.148 | O21: =+O20*0.75 -> 33257.246 | P21: =+P20*0.75 -> 34059.976
B22: Profit | D22: =+D20-D21 -> 11606 | E22: =+E20-E21 -> 10327 | F22: =+F20-F21 -> 4419.9 | G22: =+G20-G21 -> 5555.2412 | H22: =+H20-H21 -> 6810.1219 | I22: =+I20-I21 -> 7732.8565 | J22: =+J20-J21 -> 8695.8217 | K22: =+K20-K21 -> 10105.322 | ... P22: =+P20-P21 -> 11353.325
B23: Vertriebskosten | D23: 2869 | E23: 3099 | F23: =2046*1.35 -> 2762.1 | G23: =+G20*0.075 -> 2777.6206 | H23: =+H20*0.075 -> 2837.5508 | I23: =+I20*0.075 -> 2899.8212 | J23: =+J20*0.075 -> 2964.4847 | K23: =+K20*0.075 -> 3031.5967 | L23: =+L20*0.075 -> 3101.2151 | M23: =+M20*0.075 -> 3173.4001 | N23: =+N20*0.075 -> 3248.2148 | ... P23: =+P20*0.075 -> 3405.9976
B24: Verwaltungskosten | D24: 1787 | E24: 1859 | F24: =1411*1.35 -> 1904.85 | G24: =+F24*1.04 -> 1981.044 | H24: =+G24*1.04 -> 2060.2858 | I24: =+H24*1.04 -> 2142.6972 | J24: =+I24*1.04 -> 2228.4051 | K24: =+J24*1.04 -> 2317.5413 | L24: =+K24*1.04 -> 2410.2429 | M24: =+L24*1.04 -> 2506.6526 | N24: =+M24*1.04 -> 2606.9188 | ... P24: =+O24*1.04 -> 2819.6433
B25: Sonstige Erträge | D25: 1496 | E25: 1375 | F25: =224*1.33 -> 297.92 | G25: =+F25*1.05 -> 312.816 | H25: =+G25*1.05 -> 328.4568 | I25: =+H25*1.05 -> 344.87964 | J25: =+I25*1.05 -> 362.12362 | K25: =+J25*1.05 -> 380.2298 | L25: =+K25*1.05 -> 399.24129 | M25: =+L25*1.05 -> 419.20336 | N25: =+M25*1.05 -> 440.16353 | ... P25: =+O25*1.05 -> 485.28029
B26: Sonstiger Aufwand | D26: 1162 | E26: 1107
B27: Operating Income | D27: =+D22-D23-D24+D25-D26 -> 7284 | E27: =+E22-E23-E24+E25-E26 -> 5637 | F27: =+F22-F23-F24+F25-F26 -> 50.87 | G27: =+G22-G23-G24+G25-G26 -> 1109.3926 | H27: =+H22-H23-H24+H25-H26 -> 2240.7422 | I27: =+I22-I23-I24+I25-I26 -> 3035.2177 | J27: =+J22-J23-J24+J25-J26 -> 3865.0556 | K27: =+K22-K23-K24+K25-K26 -> 5136.4142 | ... P27: =+P22-P23-P24+P25-P26 -> 5612.9647
B28: Equity, net | D28: -9 | E28: -155 | F28: =-36*2 -> -72 | G28: -50 | H28: -50 | I28: -50 | J28: -50 | K28: -50 | L28: -50 | M28: -50 | N28: -50 | O28: -50 | P28: -50
B29: Zinsertrag | D29: 264 | E29: 278
B30: Zinsaufwand | D30: 184 | E30: 223
B31: Andere Finanz, net | D31: 19 | E31: -309
B32: Pretax | D32: =+D27+D28+D29-D30+D31 -> 7374 | E32: =+E27+E28+E29-E30+E31 -> 5228 | F32: =+F27+F28+F29-F30+F31 -> -21.13 | G32: =+G27+G28+G29-G30+G31 -> 1059.3926 | H32: =+H27+H28+H29-H30+H31 -> 2190.7422 | I32: =+I27+I28+I29-I30+I31 -> 2985.2177 | J32: =+J27+J28+J29-J30+J31 -> 3815.0556 | K32: =+K27+K28+K29-K30+K31 -> 5086.4142 | ... P32: =+P27+P28+P29-P30+P31 -> 5562.9647
B33: Taxes | D33: 2218 | E33: 1632 | F33: -5 | G33: =+G32*0.3 -> 317.81779 | H33: =+H32*0.3 -> 657.22265 | I33: =+I32*0.3 -> 895.56532 | J33: =+J32*0.3 -> 1144.5167 | K33: =+K32*0.3 -> 1525.9243 | L33: =+L32*0.3 -> 1552.5501 | M33: =+M32*0.3 -> 1580.1453 | N33: =+N32*0.3 -> 1608.7238 | ... P33: =+P32*0.3 -> 1668.8894
B34: Net Income | D34: =+D32-D33 -> 5156 | E34: =+E32-E33 -> 3596 | F34: =+F32-F33 -> -16.13 | G34: =+G32-G33 -> 741.57483 | H34: =+H32-H33 -> 1533.5195 | I34: =+I32-I33 -> 2089.6524 | J34: =+J32-J33 -> 2670.5389 | K34: =+K32-K33 -> 3560.4899 | ... P34: =+P32-P33 -> 3894.0753 | Q34: =+P34*(1+$S37) -> 3933.0161 | R34: =+Q34*(1+$S37) -> 3972.3462 | S34: =+R34*(1+$S37) -> 4012.0697 | T34: =+S34*(1+$S37) -> 4052.1904 | U34: =+T34*(1+$S37) -> 4092.7123 | V34: =+U34*(1+$S37) -> 4133.6394 | W34: =+V34*(1+$S37) -> 4174.9758 | X34: =+W34*(1+$S37) -> 4216.7256 | ... FQ34: =+FP34*(1+$S37) -> 18572.058
B36: Gross Margin | D36: =+D22/D20 -> 0.28635579 | E36: =+E22/E20 -> 0.2576404 | F36: =+F22/F20 -> 0.12187314 | G36: =+G22/G20 -> 0.15 | H36: =+H22/H20 -> 0.18 | I36: =+I22/I20 -> 0.2 | J36: =+J22/J20 -> 0.22 | K36: =+K22/K20 -> 0.25 | ... P36: =+P22/P20 -> 0.25 | R36: Discount | S36: 0.1
B37: Operating Margin | D37: =+D27/D20 -> 0.17971873 | E37: =+E27/E20 -> 0.14063319 | F37: =+F27/F20 -> 0.0014026758 | R37: Terminal | S37: 0.01
B38: Net Margin | D38: =+D34/D22 -> 0.44425297 | E38: =+E34/E22 -> 0.34821342 | F38: =+F34/F22 -> -0.0036494038 | R38: NPV | S38: =NPV(S36,F34:FW34) -> 30171.833
B39: Vertriebskosten | D39: =+D23/D$20 -> 0.070787071 | E39: =+E23/E$20 -> 0.077314572 | F39: =+F23/F$20 -> 0.076161406 | R39: Net Cash | S39: =+Sheet2!C6 -> -3966
B40: Verwaltungskosten | D40: =+D24/D$20 -> 0.044090797 | E40: =+E24/E$20 -> 0.046378764 | F40: =+F24/F$20 -> 0.052523824 | R40: Value | S40: =+S38+S39 -> 26205.833
B41: Revenue Y/Y | E41: =+E20/D20 -1 -> -0.011028868 | F41: =+F20/E20 -1 -> -0.095217424 | R41: Price | S41: =+S40/Sheet2!C4 -> 57.532015
B42: Cars Sold Y/Y | E42: =+E11/D11 -1 -> -0.02967638 | F42: =+F11/E11 -1 -> -0.10063466 | R42: Current | S42: 40.9
S43: =+S41/S42 -1 -> 0.40665074
B44: CFFO | D44: 7023 | E44: 6353 | F44: =3455*1.33 -> 4595.15
B45: CapEx | D45: =2016+2081 -> 4097 | E45: =2174+1583 -> 3757 | F45: 3500
...
