Workbook

Sheet Main
C3: Price | D3: 27.79
C4: Share | D4: =+Bull!V25 -> 55878.589
C5: MC | D5: =+D3*D4 -> 1552866
C6: Net cash | D6: =+Bull!Y17 -> 242715
C7: EV | D7: =+D5-D6 -> 1310151
D10: Prob. | E10: Value
C11: Bearish | D11: =1-D12-D13 -> 0.4 | E11: =+D11*Bear!Y19 -> 4.6952502
C12: base | D12: 0.45 | E12: =+D12*Base!Y19 -> 21.44649
C13: Bullish | D13: 0.15 | E13: =+D13*Bull!Y19 -> 26.746765
C15: Exp. Value | D15: =+SUM(E11:E13) -> 52.888505
C16: Upside | D16: =+D15/D3 -1 -> 0.90314879

Sheet Bull
D2: 2022 | E2: =+D2+1 -> 2023 | F2: =+E2+1 -> 2024 | G2: =+F2+1 -> 2025 | H2: =+G2+1 -> 2026 | I2: =+H2+1 -> 2027 | J2: =+I2+1 -> 2028 | K2: =+J2+1 -> 2029 | L2: =+K2+1 -> 2030 | ... V2: =+U2+1 -> 2040
B4: BHP | D4: =+D13 -> 75014 | E4: =+E13 -> 136191 | F4: =+F13 -> 224498 | G4: =+G13 -> 308054 | H4: 400000 | I4: 500000 | J4: 600000 | K4: 750000 | L4: 900000 | M4: 1050000 | N4: 1250000 | O4: 1450000 | P4: 1650000 | Q4: 1850000 | R4: 2050000 | S4: 2250000 | T4: 2400000 | U4: 2550000 | V4: 2650000
B5: BHP Y/Y | E5: =+E4/D4 -1 -> 0.8155411 | F5: =+F4/E4 -1 -> 0.64840555 | G5: =+G4/F4 -1 -> 0.3721904 | H5: =+H4/G4 -1 -> 0.29847364 | I5: =+I4/H4 -1 -> 0.25 | J5: =+J4/I4 -1 -> 0.2 | K5: =+K4/J4 -1 -> 0.25 | L5: =+L4/K4 -1 -> 0.2 | ... V5: =+V4/U4 -1 -> 0.039215686
B6: Localized prostate cancer | J6: 20000 | K6: 80000 | L6: 180000 | M6: 350000 | N6: 650000 | O6: 1050000 | P6: 1450000 | Q6: 1800000 | R6: 2200000 | S6: 2550000 | T6: 2900000 | U6: 3150000 | V6: 3350000
B7: Y/Y | K7: =+K6/J6 -1 -> 3 | L7: =+L6/K6 -1 -> 1.25 | M7: =+M6/L6 -1 -> 0.94444444 | N7: =+N6/M6 -1 -> 0.85714286 | O7: =+O6/N6 -1 -> 0.61538462 | P7: =+P6/O6 -1 -> 0.38095238 | Q7: =+Q6/P6 -1 -> 0.24137931 | R7: =+R6/Q6 -1 -> 0.22222222 | ... V7: =+V6/U6 -1 -> 0.063492063
B8: Other | L8: 20000 | M8: 50000 | N8: 100000 | O8: 180000 | P8: 280000 | Q8: 400000 | R8: 600000 | S8: 850000 | T8: 1150000 | U8: 1450000 | V8: 1750000
B10: System sales & rentals | E10: 58920 | F10: 90299
B11: Consumables | E11: 69522 | F11: 121456
B12: Service | E12: 7749 | F12: 12743
B13: Revenue | D13: 75014 | E13: 136191 | F13: 224498 | G13: 308054 | H13: =+SUM(H4:H8) -> 400000.3 | I13: =+SUM(I4:I8) -> 500000.25 | J13: =+SUM(J4:J8) -> 620000.2 | K13: =+SUM(K4:K8) -> 830003.25 | L13: =+SUM(L4:L8) -> 1100001.4 | M13: =+SUM(M4:M8) -> 1450001.1 | N13: =+SUM(N4:N8) -> 2000001 | O13: =+SUM(O4:O8) -> 2680000.8 | ... V13: =+SUM(V4:V8) -> 7750000.1
B14: COGS | D14: 37929 | E14: 65142 | F14: 87399 | G14: 111828 | H14: =+H13*(1-H27) -> 132000.1 | I14: =+I13*(1-I27) -> 160000.08 | J14: =+J13*(1-J27) -> 192200.06 | K14: =+K13*(1-K27) -> 249000.98 | L14: =+L13*(1-L27) -> 330000.44 | M14: =+M13*(1-M27) -> 435000.33 | N14: =+N13*(1-N27) -> 600000.31 | O14: =+O13*(1-O27) -> 804000.23 | ... V14: =+V13*(1-V27) -> 2325000 | X14: Discount | Y14: 0.1
B15: Gross Profit | D15: =+D13-D14 -> 37085 | E15: =+E13-E14 -> 71049 | F15: =+F13-F14 -> 137099 | G15: =+G13-G14 -> 196226 | H15: =+H13-H14 -> 268000.2 | I15: =+I13-I14 -> 340000.17 | J15: =+J13-J14 -> 427800.14 | K15: =+K13-K14 -> 581002.27 | ... V15: =+V13-V14 -> 5425000.1 | X15: Terminal | Y15: 0.03
B16: R&D | D16: 28981 | E16: 48446 | F16: 62298 | G16: 71277 | H16: =+G16*(1+H29*0.8) -> 88296.5 | I16: =+H16*(1+I29*0.8) -> 105955.78 | J16: =+I16*(1+J29*0.8) -> 126299.27 | K16: =+J16*(1+K29*0.8) -> 160522.78 | L16: =+K16*(1+L29*0.8) -> 202296.94 | M16: =+L16*(1+M29*0.8) -> 253790.59 | N16: =+M16*(1+N29*0.8) -> 330802.84 | O16: =+N16*(1+O29*0.8) -> 420781.14 | ... V16: =+U16*(1+V29*0.8) -> 997515.8 | X16: NPV | Y16: =NPV(Y14,G23:FB23) -> 9721094.8
B17: SG&A | D17: 88828 | E17: 131773 | F17: 171415 | G17: 228808 | H17: =+G17*(1+H29*0.6) -> 269784.03 | I17: =+H17*(1+I29*0.6) -> 310251.58 | J17: =+I17*(1+J29*0.6) -> 354927.77 | K17: =+J17*(1+K29*0.6) -> 427059.28 | L17: =+K17*(1+L29*0.6) -> 510412.13 | M17: =+L17*(1+M29*0.6) -> 607854.22 | N17: =+M17*(1+N29*0.6) -> 746193.34 | O17: =+N17*(1+O29*0.6) -> 898416.64 | ... V17: =+U17*(1+V29*0.6) -> 1734926.3 | X17: Net Cash | Y17: =+G38-G40 -> 242715
B18: Operating Income | D18: =+D15-D16-D17 -> -80724 | E18: =+E15-E16-E17 -> -109170 | F18: =+F15-F16-F17 -> -96614 | G18: =+G15-G16-G17 -> -103859 | H18: =+H15-H16-H17 -> -90080.328 | I18: =+I15-I16-I17 -> -76207.19 | J18: =+J15-J16-J17 -> -53426.9 | K18: =+K15-K16-K17 -> -6579.7829 | ... V18: =+V15-V16-V17 -> 2692558 | X18: Value | Y18: =+Y16+Y17 -> 9963809.8
B19: Interest expenses | D19: 5183 | E19: 3995 | F19: 4184 | G19: 3586 | H19: 3500 | I19: 3500 | J19: 3500 | K19: 3500 | L19: 3500 | M19: 3500 | N19: 3500 | O19: 3500 | P19: 3500 | Q19: 3500 | R19: 3500 | S19: 3500 | T19: 3500 | U19: 3500 | V19: 3500 | X19: Price | Y19: =+Y18/Q25 -> 178.31176
B20: Interest income | D20: 2011 | E20: 7268 | F20: 9385 | G20: 12063 | H20: 10000 | I20: 10000 | J20: 10000 | K20: 10000 | L20: 10000 | M20: 10000 | N20: 10000 | O20: 10000 | P20: 10000 | Q20: 10000 | R20: 10000 | S20: 10000 | T20: 10000 | U20: 10000 | V20: 10000
B21: Pretax | D21: =+D18-D19+D20 -> -83896 | E21: =+E18-E19+E20 -> -105897 | F21: =+F18-F19+F20 -> -91413 | G21: =+G18-G19+G20 -> -95382 | H21: =+H18-H19+H20 -> -83580.328 | I21: =+I18-I19+I20 -> -69707.19 | J21: =+J18-J19+J20 -> -46926.9 | K21: =+K18-K19+K20 -> -79.782895 | ... V21: =+V18-V19+V20 -> 2699058
B22: Taxes | F22: 368 | G22: 190 | K22: =+K49 -> -3.3508816 | L22: =+L49 -> 2679.2615 | M22: =+M49 -> 6713.9503 | N22: =+N49 -> 13839.191 | O22: =+O49 -> 90081.281 | P22: =+P21*0.21 -> 173162.15 | Q22: =+Q21*0.21 -> 228755.62 | R22: =+R21*0.21 -> 297855.98 | S22: =+S21*0.21 -> 369511.07 | T22: =+T21*0.21 -> 443232.77 | U22: =+U21*0.21 -> 509245.14 | V22: =+V21*0.21 -> 566802.18
B23: Net income | D23: =+D21-D22 -> -83896 | E23: =+E21-E22 -> -105897 | F23: =+F21-F22 -> -91781 | G23: =+G21-G22 -> -95572 | H23: =+H21-H22 -> -83580.328 | I23: =+I21-I22 -> -69707.19 | J23: =+J21-J22 -> -46926.9 | K23: =+K21-K22 -> -76.432013 | ... V23: =+V21-V22 -> 2132255.8 | W23: =+V23*(1+$Y15) -> 2196223.5 | X23: =+W23*(1+$Y15) -> 2262110.2 | Y23: =+X23*(1+$Y15) -> 2329973.5 | Z23: =+Y23*(1+$Y15) -> 2399872.7 | AA23: =+Z23*(1+$Y15) -> 2471868.9 | AB23: =+AA23*(1+$Y15) -> 2546024.9 | AC23: =+AB23*(1+$Y15) -> 2622405.7 | AD23: =+AC23*(1+$Y15) -> 2701077.9 | ... ER23: =+EQ23*(1+$Y15) -> 88375039
B24: EPS | D24: =+D23/D25 -> -1.8895495 | E24: =+E23/E25 -> -2.2409692 | F24: =+F23/F25 -> -1.7607866 | G24: =+G23/G25 -> -1.710351 | H24: =+H23/H25 -> -1.4957487 | I24: =+I23/I25 -> -1.2474758 | J24: =+J23/J25 -> -0.83980109 | K24: =+K23/K25 -> -0.0013678229 | ... V24: =+V23/V25 -> 38.158727
B25: Shares | D25: 44400 | E25: 47255 | F25: 52125 | G25: 55878.589 | H25: =+G25 -> 55878.589 | I25: =+H25 -> 55878.589 | J25: =+I25 -> 55878.589 | K25: =+J25 -> 55878.589 | L25: =+K25 -> 55878.589 | M25: =+L25 -> 55878.589 | N25: =+M25 -> 55878.589 | O25: =+N25 -> 55878.589 | ... V25: =+U25 -> 55878.589
B27: Gross Margin | D27: =+D15/D13 -> 0.49437438 | E27: =+E15/E13 -> 0.52168646 | F27: =+F15/F13 -> 0.61069141 | G27: =+G15/G13 -> 0.63698572 | H27: 0.67 | I27: 0.68 | J27: 0.69 | K27: 0.7 | L27: 0.7 | M27: 0.7 | N27: 0.7 | O27: 0.7 | P27: 0.7 | Q27: 0.7 | R27: 0.7 | S27: 0.7 | T27: 0.7 | U27: 0.7 | V27: 0.7
B28: Operating Margin | D28: =+D18/D13 -> -1.0761191 | E28: =+E18/E13 -> -0.80159482 | F28: =+F18/F13 -> -0.43035573 | G28: =+G18/G13 -> -0.33714544 | H28: =+H18/H13 -> -0.22520065 | I28: =+I18/I13 -> -0.1524143 | J28: =+J18/J13 -> -0.086172391 | K28: =+K18/K13 -> -0.0079274182 | ... V28: =+V18/V13 -> 0.34742683
B29: Revenue Y/Y | E29: =+E13/D13 -1 -> 0.8155411 | F29: =+F13/E13 -1 -> 0.64840555 | G29: =+G13/F13 -1 -> 0.3721904 | H29: =+H13/G13 -1 -> 0.29847461 | I29: =+I13/H13 -1 -> 0.24999969 | J29: =+J13/I13 -1 -> 0.23999978 | K29: =+K13/J13 -1 -> 0.33871449 | L29: =+L13/K13 -1 -> 0.32529776 | ... V29: =+V13/U13 -1 -> 0.083916076
B31: CFFO | D31: -80382 | E31: -108003 | F31: -99213
B32: CapEx | D32: 2653 | E32: 25206 | F32: 4409
B33: FCF | D33: =+D31-D32 -> -83035 | E33: =+E31-E32 -> -133209 | F33: =+F31-F32 -> -103622
B35: Issue of Stocks | E35: 161705 | F35: 164523
B36: FFCF | E36: =+E33+E35 -> 28496 | F36: =+F33+F35 -> 60901
B38: Cash | E38: 257222 | F38: 333725 | G38: 294281
B39: PP&E | E39: 27748 | F39: 26709 | G39: 30022
B40: Debt | E40: 51339 | F40: 51472 | G40: 51566
B41: NAV | E41: =+E38+E39-E40 -> 233631 | F41: =+F38+F39-F40 -> 308962 | G41: =+G38+G39-G40 -> 272737
B43: R&D | D43: =+D16/D$13 -> 0.38634122 | E43: =+E16/E$13 -> 0.35572101 | F43: =+F16/F$13 -> 0.27749913 | G43: =+G16/G$13 -> 0.23137826 | H43: =+H16/H$13 -> 0.22074109 | I43: =+I16/I$13 -> 0.21191145 | J43: =+J16/J$13 -> 0.20370843 | K43: =+K16/K$13 -> 0.19340019 | ... V43: =+V16/V$13 -> 0.12871171
B44: SG&A | D44: =+D17/D$13 -> 1.1841523 | E44: =+E17/E$13 -> 0.96756026 | F44: =+F17/F$13 -> 0.763548 | G44: =+G17/G$13 -> 0.74275289 | H44: =+H17/H$13 -> 0.67445957 | I44: =+I17/I$13 -> 0.62050285 | J44: =+J17/J$13 -> 0.57246396 | K44: =+K17/K$13 -> 0.51452723 | ... V44: =+V17/V$13 -> 0.22386145
B46: NOL | D46: =-D21 -> 83896 | E46: =+D46-E21 -> 189793 | F46: =+E46-F21 -> 281206 | G46: =+F46-G21 -> 376588 | H46: =+G46-H21 -> 460168.33 | I46: =+H46-I21 -> 529875.52 | J46: =+I46-J21 -> 576802.42 | K46: =+J46-K47 -> 576866.24 | L46: =+K46-L47 -> 525832.69 | M46: =+L46-M47 -> 397947.92 | N46: =+M46-N47 -> 134344.29
B47: NOL used | K47: =+K21*0.8 -> -63.826316 | L47: =+L21*0.8 -> 51033.552 | M47: =+M21*0.8 -> 127884.77 | N47: =+N21*0.8 -> 263603.64 | O47: =+N46 -> 134344.29
B48: Taxable income | K48: =+K21-K47 -> -15.956579 | L48: =+L21-L47 -> 12758.388 | M48: =+M21-M47 -> 31971.192 | N48: =+N21-N47 -> 65900.91 | O48: =+O21-O47 -> 428958.48
B49: Tax | K49: =+K48*0.21 -> -3.3508816 | L49: =+L48*0.21 -> 2679.2615 | M49: =+M48*0.21 -> 6713.9503 | N49: =+N48*0.21 -> 13839.191 | O49: =+O48*0.21 -> 90081.281

Sheet Base
D2: 2022 | E2: =+D2+1 -> 2023 | F2: =+E2+1 -> 2024 | G2: =+F2+1 -> 2025 | H2: =+G2+1 -> 2026 | I2: =+H2+1 -> 2027 | J2: =+I2+1 -> 2028 | K2: =+J2+1 -> 2029 | L2: =+K2+1 -> 2030 | ... V2: =+U2+1 -> 2040
B4: BHP | D4: =+D13 -> 75014 | E4: =+E13 -> 136191 | F4: =+F13 -> 224498 | G4: =+G13 -> 308054 | H4: 400000 | I4: 500000 | J4: 580000 | K4: 720000 | L4: 880000 | M4: 1050000 | N4: 1220000 | O4: 1400000 | P4: 1550000 | Q4: 1700000 | R4: 1800000 | S4: =+R4+100000 -> 1900000 | T4: =+S4+100000 -> 2000000 | U4: =+T4+50000 -> 2050000 | V4: =+U4+50000 -> 2100000
B5: BHP Y/Y | E5: =+E4/D4 -1 -> 0.8155411 | F5: =+F4/E4 -1 -> 0.64840555 | G5: =+G4/F4 -1 -> 0.3721904 | H5: =+H4/G4 -1 -> 0.29847364 | I5: =+I4/H4 -1 -> 0.25 | J5: =+J4/I4 -1 -> 0.16 | K5: =+K4/J4 -1 -> 0.24137931 | L5: =+L4/K4 -1 -> 0.22222222 | ... V5: =+V4/U4 -1 -> 0.024390244
B6: Localized prostate cancer | J6: 20000 | K6: 60000 | L6: 100000 | M6: 130000 | N6: 200000 | O6: 270000 | P6: 350000 | Q6: 450000 | R6: =+Q6+50000 -> 500000 | S6: =+R6+50000 -> 550000 | T6: =+S6+50000 -> 600000 | U6: =+T6+50000 -> 650000 | V6: =+U6+50000 -> 700000
B7: Y/Y | K7: =+K6/J6 -1 -> 2 | L7: =+L6/K6 -1 -> 0.66666667 | M7: =+M6/L6 -1 -> 0.3 | N7: =+N6/M6 -1 -> 0.53846154 | O7: =+O6/N6 -1 -> 0.35 | P7: =+P6/O6 -1 -> 0.2962963 | Q7: =+Q6/P6 -1 -> 0.28571429 | R7: =+R6/Q6 -1 -> 0.11111111 | ... V7: =+V6/U6 -1 -> 0.076923077
B8: Other | L8: 20000 | M8: 20000 | N8: 30000 | O8: 30000 | P8: 50000 | Q8: 50000 | R8: 50000 | S8: 50000 | T8: 50000 | U8: 50000 | V8: 50000
B10: System sales & rentals | E10: 58920 | F10: 90299 | G10: =93000+13132 -> 106132
B11: Consumables | E11: 69522 | F11: 121456 | G11: =159669+21777 -> 181446
B12: Service | E12: 7749 | F12: 12743 | G12: =2767+17709 -> 20476
B13: Revenue | D13: 75014 | E13: 136191 | F13: 224498 | G13: 308054 | H13: =+SUM(H4:H8) -> 400000.3 | I13: =+SUM(I4:I8) -> 500000.25 | J13: =+SUM(J4:J8) -> 600000.16 | K13: =+SUM(K4:K8) -> 780002.24 | L13: =+SUM(L4:L8) -> 1000000.9 | M13: =+SUM(M4:M8) -> 1200000.5 | N13: =+SUM(N4:N8) -> 1450000.7 | O13: =+SUM(O4:O8) -> 1700000.5 | ... V13: =+SUM(V4:V8) -> 2850000.1
B14: COGS | D14: 37929 | E14: 65142 | F14: 87399 | G14: 111828 | H14: =+H13*(1-H28) -> 140000.1 | I14: =+I13*(1-I28) -> 165000.08 | J14: =+J13*(1-J28) -> 192000.05 | K14: =+K13*(1-K28) -> 241800.69 | L14: =+L13*(1-L28) -> 300000.27 | M14: =+M13*(1-M28) -> 360000.15 | N14: =+N13*(1-N28) -> 435000.21 | O14: =+O13*(1-O28) -> 510000.15 | ... V14: =+V13*(1-V28) -> 855000.03 | X14: Discount | Y14: 0.1
B15: Gross Profit | D15: =+D13-D14 -> 37085 | E15: =+E13-E14 -> 71049 | F15: =+F13-F14 -> 137099 | G15: =+G13-G14 -> 196226 | H15: =+H13-H14 -> 260000.19 | I15: =+I13-I14 -> 335000.17 | J15: =+J13-J14 -> 408000.11 | K15: =+K13-K14 -> 538201.55 | ... V15: =+V13-V14 -> 1995000.1 | X15: Terminal | Y15: 0.03
B16: R&D | D16: 28981 | E16: 48446 | F16: 62298 | G16: 71277 | H16: =+G16*(1+H30*0.8) -> 88296.5 | I16: =+H16*(1+I30*0.8) -> 105955.78 | J16: =+I16*(1+J30*0.8) -> 122908.68 | K16: =+J16*(1+K30*0.8) -> 152407.1 | L16: =+K16*(1+L30*0.8) -> 186796.08 | M16: =+L16*(1+M30*0.8) -> 216683.37 | N16: =+M16*(1+N30*0.8) -> 252797.27 | O16: =+N16*(1+O30*0.8) -> 287665.82 | ... V16: =+U16*(1+V30*0.8) -> 436538.84 | X16: NPV | Y16: =NPV(Y14,G24:FB24) -> 2428222.2
B17: SG&A | D17: 88828 | E17: 131773 | F17: 171415 | G17: 228808 | H17: =+G17*(1+H30*0.6) -> 269784.03 | I17: =+H17*(1+I30*0.6) -> 310251.58 | J17: =+I17*(1+J30*0.6) -> 347481.72 | K17: =+J17*(1+K30*0.6) -> 410029.14 | L17: =+K17*(1+L30*0.6) -> 479418.06 | M17: =+L17*(1+M30*0.6) -> 536948.06 | N17: =+M17*(1+N30*0.6) -> 604066.59 | O17: =+N17*(1+O30*0.6) -> 666556.16 | ... V17: =+U17*(1+V30*0.6) -> 913977.98 | X17: Net Cash | Y17: =+G39-G41 -> 234888
B18: Operating expenses | D18: =+SUM(D16:D17) -> 117809 | E18: =+SUM(E16:E17) -> 180219 | F18: =+SUM(F16:F17) -> 233713 | G18: =+SUM(G16:G17) -> 300085 | H18: =+SUM(H16:H17) -> 358080.53 | I18: =+SUM(I16:I17) -> 416207.36 | J18: =+SUM(J16:J17) -> 470390.4 | K18: =+SUM(K16:K17) -> 562436.23 | ... V18: =+SUM(V16:V17) -> 1350516.8 | X18: Value | Y18: =+Y16+Y17 -> 2663110.2
B19: Operating Income | D19: =+D15-D16-D17 -> -80724 | E19: =+E15-E16-E17 -> -109170 | F19: =+F15-F16-F17 -> -96614 | G19: =+G15-G16-G17 -> -103859 | H19: =+H15-H16-H17 -> -98080.334 | I19: =+I15-I16-I17 -> -81207.193 | J19: =+J15-J16-J17 -> -62390.29 | K19: =+K15-K16-K17 -> -24234.684 | ... V19: =+V15-V16-V17 -> 644483.25 | X19: Price | Y19: =+Y18/Q26 -> 47.658866
B20: Interest expenses | D20: 5183 | E20: 3995 | F20: 4184 | G20: 3586 | H20: 3500 | I20: 3500 | J20: 3500 | K20: 3500 | L20: 3500 | M20: 3500 | N20: 3500 | O20: 3500 | P20: 3500 | Q20: 3500 | R20: 3500 | S20: 3500 | T20: 3500 | U20: 3500 | V20: 3500
B21: Interest income | D21: 2011 | E21: 7268 | F21: 9385 | G21: 12063 | H21: 10000 | I21: 10000 | J21: 10000 | K21: 10000 | L21: 10000 | M21: 10000 | N21: 10000 | O21: 10000 | P21: 10000 | Q21: 10000 | R21: 10000 | S21: 10000 | T21: 10000 | U21: 10000 | V21: 10000
B22: Pretax | D22: =+D19-D20+D21 -> -83896 | E22: =+E19-E20+E21 -> -105897 | F22: =+F19-F20+F21 -> -91413 | G22: =+G19-G20+G21 -> -95382 | H22: =+H19-H20+H21 -> -91580.334 | I22: =+I19-I20+I21 -> -74707.193 | J22: =+J19-J20+J21 -> -55890.29 | K22: =+K19-K20+K21 -> -17734.684 | ... V22: =+V19-V20+V21 -> 650983.25
B23: Taxes | F23: 368 | G23: 190 | H23: 200 | I23: 200 | J23: 200 | K23: 200 | L23: =+L50 -> 1692.0325 | M23: =+M50 -> 3900.4948 | N23: =+N50 -> 6914.7382 | O23: =+O50 -> 10175.692 | P23: =+P50 -> 29437.248 | Q23: =+Q22*0.21 -> 86278.208 | R23: =+R22*0.21 -> 97556.801 | S23: =+S22*0.21 -> 109058.59 | T23: =+T22*0.21 -> 120765.43 | U23: =+U22*0.21 -> 128696.22 | V23: =+V22*0.21 -> 136706.48
B24: Net income | D24: =+D22-D23 -> -83896 | E24: =+E22-E23 -> -105897 | F24: =+F22-F23 -> -91781 | G24: =+G22-G23 -> -95572 | H24: =+H22-H23 -> -91780.334 | I24: =+I22-I23 -> -74907.193 | J24: =+J22-J23 -> -56090.29 | K24: =+K22-K23 -> -17934.684 | ... V24: =+V22-V23 -> 514276.77 | W24: =+V24*(1+$Y15) -> 529705.07 | X24: =+W24*(1+$Y15) -> 545596.23 | Y24: =+X24*(1+$Y15) -> 561964.11 | Z24: =+Y24*(1+$Y15) -> 578823.04 | AA24: =+Z24*(1+$Y15) -> 596187.73 | AB24: =+AA24*(1+$Y15) -> 614073.36 | AC24: =+AB24*(1+$Y15) -> 632495.56 | AD24: =+AC24*(1+$Y15) -> 651470.43 | ... ER24: =+EQ24*(1+$Y15) -> 21315092
B25: EPS | D25: =+D24/D26 -> -1.8895495 | E25: =+E24/E26 -> -2.2409692 | F25: =+F24/F26 -> -1.7607866 | G25: =+G24/G26 -> -1.710351 | H25: =+H24/H26 -> -1.6424955 | I25: =+I24/I26 -> -1.3405348 | J25: =+J24/J26 -> -1.0037886 | K25: =+K24/K26 -> -0.32095808 | ... V25: =+V24/V26 -> 9.2034674
B26: Shares | D26: 44400 | E26: 47255 | F26: 52125 | G26: 55878.589 | H26: =+G26 -> 55878.589 | I26: =+H26 -> 55878.589 | J26: =+I26 -> 55878.589 | K26: =+J26 -> 55878.589 | L26: =+K26 -> 55878.589 | M26: =+L26 -> 55878.589 | N26: =+M26 -> 55878.589 | O26: =+N26 -> 55878.589 | ... V26: =+U26 -> 55878.589
V27: =+V25*20 -> 184.06935
B28: Gross Margin | D28: =+D15/D13 -> 0.49437438 | E28: =+E15/E13 -> 0.52168646 | F28: =+F15/F13 -> 0.61069141 | G28: =+G15/G13 -> 0.63698572 | H28: 0.65 | I28: 0.67 | J28: 0.68 | K28: 0.69 | L28: 0.7 | M28: 0.7 | N28: 0.7 | O28: 0.7 | P28: 0.7 | Q28: 0.7 | R28: 0.7 | S28: 0.7 | T28: 0.7 | U28: 0.7 | V28: 0.7
B29: Operating Margin | D29: =+D19/D13 -> -1.0761191 | E29: =+E19/E13 -> -0.80159482 | F29: =+F19/F13 -> -0.43035573 | G29: =+G19/G13 -> -0.33714544 | H29: =+H19/H13 -> -0.24520065 | I29: =+I19/I13 -> -0.1624143 | J29: =+J19/J13 -> -0.10398379 | K29: =+K19/K13 -> -0.031070019 | ... V29: =+V19/V13 -> 0.22613447
B30: Revenue Y/Y | E30: =+E13/D13 -1 -> 0.8155411 | F30: =+F13/E13 -1 -> 0.64840555 | G30: =+G13/F13 -1 -> 0.3721904 | H30: =+H13/G13 -1 -> 0.29847461 | I30: =+I13/H13 -1 -> 0.24999969 | J30: =+J13/I13 -1 -> 0.19999972 | K30: =+K13/J13 -1 -> 0.30000339 | L30: =+L13/K13 -1 -> 0.28204874 | ... V30: =+V13/U13 -1 -> 0.036363632
B32: CFFO | D32: -80382 | E32: -108003 | F32: -99213
B33: CapEx | D33: 2653 | E33: 25206 | F33: 4409
B34: FCF | D34: =+D32-D33 -> -83035 | E34: =+E32-E33 -> -133209 | F34: =+F32-F33 -> -103622
B36: Issue of Stocks | E36: 161705 | F36: 164523
B37: FFCF | E37: =+E34+E36 -> 28496 | F37: =+F34+F36 -> 60901
B39: Cash | E39: 257222 | F39: 333725 | G39: 286503
B40: PP&E | E40: 27748 | F40: 26709 | G40: 30399
B41: Debt | E41: 51339 | F41: 51472 | G41: 51615
B42: NAV | E42: =+E39+E40-E41 -> 233631 | F42: =+F39+F40-F41 -> 308962 | G42: =+G39+G40-G41 -> 265287
B44: R&D | D44: =+D16/D$13 -> 0.38634122 | E44: =+E16/E$13 -> 0.35572101 | F44: =+F16/F$13 -> 0.27749913 | G44: =+G16/G$13 -> 0.23137826 | H44: =+H16/H$13 -> 0.22074109 | I44: =+I16/I$13 -> 0.21191145 | J44: =+J16/J$13 -> 0.20484774 | K44: =+K16/K$13 -> 0.19539315 | ... V44: =+V16/V$13 -> 0.15317152
B45: SG&A | D45: =+D17/D$13 -> 1.1841523 | E45: =+E17/E$13 -> 0.96756026 | F45: =+F17/F$13 -> 0.763548 | G45: =+G17/G$13 -> 0.74275289 | H45: =+H17/H$13 -> 0.67445957 | I45: =+I17/I$13 -> 0.62050285 | J45: =+J17/J$13 -> 0.57913604 | K45: =+K17/K$13 -> 0.52567687 | ... V45: =+V17/V$13 -> 0.32069402
B47: NOL | D47: =-D22 -> 83896 | E47: =+D47-E22 -> 189793 | F47: =+E47-F22 -> 281206 | G47: =+F47-G22 -> 376588 | H47: =+G47-H22 -> 468168.33 | I47: =+H47-I22 -> 542875.53 | J47: =+I47-J22 -> 598765.82 | K47: =+J47-K22 -> 616500.5 | L47: =+K47-L48 -> 584271.31 | M47: =+L47-M48 -> 509976.17 | N47: =+M47-N48 -> 378266.87 | O47: =+N47-O48 -> 184444.18
B48: NOL used | L48: =+L22*0.8 -> 32229.191 | M48: =+M22*0.8 -> 74295.138 | N48: =+N22*0.8 -> 131709.3 | O48: =+O22*0.8 -> 193822.7 | P48: =+O47 -> 184444.18
...

Sheet Bear
D2: 2022 | E2: =+D2+1 -> 2023 | F2: =+E2+1 -> 2024 | G2: =+F2+1 -> 2025 | H2: =+G2+1 -> 2026 | I2: =+H2+1 -> 2027 | J2: =+I2+1 -> 2028 | K2: =+J2+1 -> 2029 | L2: =+K2+1 -> 2030 | ... V2: =+U2+1 -> 2040
B4: BHP | D4: =+D13 -> 75014 | E4: =+E13 -> 136191 | F4: =+F13 -> 224498 | G4: =+G13 -> 308054 | H4: 400000 | I4: 480000 | J4: 550000 | K4: 620000 | L4: 700000 | M4: 780000 | N4: 850000 | O4: 920000 | P4: 980000 | Q4: 1030000 | R4: =+Q4*1.04 -> 1071200 | S4: =+R4*1.04 -> 1114048 | T4: =+S4*1.03 -> 1147469.4 | U4: =+T4*1.03 -> 1181893.5 | V4: =+U4*1.03 -> 1217350.3
B5: BHP Y/Y | E5: =+E4/D4 -1 -> 0.8155411 | F5: =+F4/E4 -1 -> 0.64840555 | G5: =+G4/F4 -1 -> 0.3721904 | H5: =+H4/G4 -1 -> 0.29847364 | I5: =+I4/H4 -1 -> 0.2 | J5: =+J4/I4 -1 -> 0.14583333 | K5: =+K4/J4 -1 -> 0.12727273 | L5: =+L4/K4 -1 -> 0.12903226 | ... V5: =+V4/U4 -1 -> 0.03
B6: Localized prostate cancer | J6: 10000 | K6: 20000 | L6: 30000 | M6: =+L6+10000 -> 40000 | N6: =+M6+10000 -> 50000 | O6: =+N6+10000 -> 60000 | P6: =+O6+10000 -> 70000 | Q6: =+P6+10000 -> 80000 | R6: =+Q6+10000 -> 90000 | S6: =+R6+10000 -> 100000 | T6: =+S6+10000 -> 110000 | ... V6: =+U6+10000 -> 130000
B7: Y/Y | K7: =+K6/J6 -1 -> 1 | L7: =+L6/K6 -1 -> 0.5 | M7: =+M6/L6 -1 -> 0.33333333 | N7: =+N6/M6 -1 -> 0.25 | O7: =+O6/N6 -1 -> 0.2 | P7: =+P6/O6 -1 -> 0.16666667 | Q7: =+Q6/P6 -1 -> 0.14285714 | R7: =+R6/Q6 -1 -> 0.125 | ... V7: =+V6/U6 -1 -> 0.083333333
B8: Other | L8: 10000 | M8: 10000 | N8: 20000 | O8: 20000 | P8: 30000 | Q8: 40000 | R8: 50000 | S8: =+R8+10000 -> 60000 | T8: =+S8+10000 -> 70000 | U8: =+T8+10000 -> 80000 | V8: =+U8+10000 -> 90000
B10: System sales & rentals | E10: 58920 | F10: 90299
B11: Consumables | E11: 69522 | F11: 121456
B12: Service | E12: 7749 | F12: 12743
B13: Revenue | D13: 75014 | E13: 136191 | F13: 224498 | G13: 308054 | H13: =+SUM(H4:H8) -> 400000.3 | I13: =+SUM(I4:I8) -> 480000.2 | J13: =+SUM(J4:J8) -> 560000.15 | K13: =+SUM(K4:K8) -> 640001.13 | L13: =+SUM(L4:L8) -> 740000.63 | M13: =+SUM(M4:M8) -> 830000.45 | N13: =+SUM(N4:N8) -> 920000.34 | O13: =+SUM(O4:O8) -> 1000000.3 | ... V13: =+SUM(V4:V8) -> 1437350.4
B14: COGS | D14: 37929 | E14: 65142 | F14: 87399 | G14: 111828 | H14: =+H13*(1-H27) -> 132000.1 | I14: =+I13*(1-I27) -> 153600.06 | J14: =+J13*(1-J27) -> 173600.05 | K14: =+K13*(1-K27) -> 192000.34 | L14: =+L13*(1-L27) -> 222000.19 | M14: =+M13*(1-M27) -> 249000.13 | N14: =+N13*(1-N27) -> 276000.1 | O14: =+O13*(1-O27) -> 300000.08 | ... V14: =+V13*(1-V27) -> 431205.13 | X14: Discount | Y14: 0.1
B15: Gross Profit | D15: =+D13-D14 -> 37085 | E15: =+E13-E14 -> 71049 | F15: =+F13-F14 -> 137099 | G15: =+G13-G14 -> 196226 | H15: =+H13-H14 -> 268000.2 | I15: =+I13-I14 -> 326400.14 | J15: =+J13-J14 -> 386400.1 | K15: =+K13-K14 -> 448000.79 | ... V15: =+V13-V14 -> 1006145.3 | X15: Terminal | Y15: 0.03
B16: R&D | D16: 28981 | E16: 48446 | F16: 62298 | G16: 71277 | H16: =+G16*(1+H29*0.8) -> 88296.5 | I16: =+H16*(1+I29*0.8) -> 102423.91 | J16: =+I16*(1+J29*0.8) -> 116080.42 | K16: =+J16*(1+K29*0.8) -> 129346.91 | L16: =+K16*(1+L29*0.8) -> 145515.17 | M16: =+L16*(1+M29*0.8) -> 159673.36 | N16: =+M16*(1+N29*0.8) -> 173524.52 | O16: =+N16*(1+O29*0.8) -> 185595.77 | ... V16: =+U16*(1+V29*0.8) -> 248486.98 | X16: NPV | Y16: =NPV(Y14,G23:FB23) -> 413194.89
B17: SG&A | D17: 88828 | E17: 131773 | F17: 171415 | G17: 228808 | H17: =+G17*(1+H29*0.6) -> 269784.03 | I17: =+H17*(1+I29*0.6) -> 302158.05 | J17: =+I17*(1+J29*0.6) -> 332373.82 | K17: =+J17*(1+K29*0.6) -> 360863.35 | L17: =+K17*(1+L29*0.6) -> 394694.06 | M17: =+L17*(1+M29*0.6) -> 423495.97 | N17: =+M17*(1+N29*0.6) -> 451048.67 | O17: =+N17*(1+O29*0.6) -> 474581.62 | ... V17: =+U17*(1+V29*0.6) -> 591404.59 | X17: Net Cash | Y17: =+G38-G40 -> 242715
B18: Operating Income | D18: =+D15-D16-D17 -> -80724 | E18: =+E15-E16-E17 -> -109170 | F18: =+F15-F16-F17 -> -96614 | G18: =+G15-G16-G17 -> -103859 | H18: =+H15-H16-H17 -> -90080.328 | I18: =+I15-I16-I17 -> -78181.823 | J18: =+J15-J16-J17 -> -62054.137 | K18: =+K15-K16-K17 -> -42209.468 | ... V18: =+V15-V16-V17 -> 166253.73 | X18: Value | Y18: =+Y16+Y17 -> 655909.89
B19: Interest expenses | D19: 5183 | E19: 3995 | F19: 4184 | G19: 3586 | H19: 3500 | I19: 3500 | J19: 3500 | K19: 3500 | L19: 3500 | M19: 3500 | N19: 3500 | O19: 3500 | P19: 3500 | Q19: 3500 | R19: 3500 | S19: 3500 | T19: 3500 | U19: 3500 | V19: 3500 | X19: Price | Y19: =+Y18/Q25 -> 11.738125
B20: Interest income | D20: 2011 | E20: 7268 | F20: 9385 | G20: 12063 | H20: 10000 | I20: 10000 | J20: 10000 | K20: 10000 | L20: 10000 | M20: 10000 | N20: 10000 | O20: 10000 | P20: 10000 | Q20: 10000 | R20: 10000 | S20: 10000 | T20: 10000 | U20: 10000 | V20: 10000
B21: Pretax | D21: =+D18-D19+D20 -> -83896 | E21: =+E18-E19+E20 -> -105897 | F21: =+F18-F19+F20 -> -91413 | G21: =+G18-G19+G20 -> -95382 | H21: =+H18-H19+H20 -> -83580.328 | I21: =+I18-I19+I20 -> -71681.823 | J21: =+J18-J19+J20 -> -55554.137 | K21: =+K18-K19+K20 -> -35709.468 | ... V21: =+V18-V19+V20 -> 172753.73
B22: Taxes | F22: 368 | G22: 190 | M22: =+M49 -> 181.9013 | N22: =+N49 -> 1088.936 | O22: =+O49 -> 1945.5576 | P22: =+P49 -> 2841.9195 | Q22: =+Q49 -> 3657.5079 | R22: =+R49 -> 4392.4351 | S22: =+S49 -> 5165.3895 | T22: =+T49 -> 5837.2686 | U22: =+U49 -> -1039.6168 | V22: =+V21*0.21 -> 36278.284
B23: Net income | D23: =+D21-D22 -> -83896 | E23: =+E21-E22 -> -105897 | F23: =+F21-F22 -> -91781 | G23: =+G21-G22 -> -95572 | H23: =+H21-H22 -> -83580.328 | I23: =+I21-I22 -> -71681.823 | J23: =+J21-J22 -> -55554.137 | K23: =+K21-K22 -> -35709.468 | ... V23: =+V21-V22 -> 136475.45 | W23: =+V23*(1+$Y15) -> 140569.71 | X23: =+W23*(1+$Y15) -> 144786.8 | Y23: =+X23*(1+$Y15) -> 149130.41 | Z23: =+Y23*(1+$Y15) -> 153604.32 | AA23: =+Z23*(1+$Y15) -> 158212.45 | AB23: =+AA23*(1+$Y15) -> 162958.82 | AC23: =+AB23*(1+$Y15) -> 167847.59 | AD23: =+AC23*(1+$Y15) -> 172883.02 | ... ER23: =+EQ23*(1+$Y15) -> 5656461.6
B24: EPS | D24: =+D23/D25 -> -1.8895495 | E24: =+E23/E25 -> -2.2409692 | F24: =+F23/F25 -> -1.7607866 | G24: =+G23/G25 -> -1.710351 | H24: =+H23/H25 -> -1.4957487 | I24: =+I23/I25 -> -1.2828138 | J24: =+J23/J25 -> -0.99419362 | K24: =+K23/K25 -> -0.63905457 | ... V24: =+V23/V25 -> 2.4423568
B25: Shares | D25: 44400 | E25: 47255 | F25: 52125 | G25: 55878.589 | H25: =+G25 -> 55878.589 | I25: =+H25 -> 55878.589 | J25: =+I25 -> 55878.589 | K25: =+J25 -> 55878.589 | L25: =+K25 -> 55878.589 | M25: =+L25 -> 55878.589 | N25: =+M25 -> 55878.589 | O25: =+N25 -> 55878.589 | ... V25: =+U25 -> 55878.589
B27: Gross Margin | D27: =+D15/D13 -> 0.49437438 | E27: =+E15/E13 -> 0.52168646 | F27: =+F15/F13 -> 0.61069141 | G27: =+G15/G13 -> 0.63698572 | H27: 0.67 | I27: 0.68 | J27: 0.69 | K27: 0.7 | L27: 0.7 | M27: 0.7 | N27: 0.7 | O27: 0.7 | P27: 0.7 | Q27: 0.7 | R27: 0.7 | S27: 0.7 | T27: 0.7 | U27: 0.7 | V27: 0.7
B28: Operating Margin | D28: =+D18/D13 -> -1.0761191 | E28: =+E18/E13 -> -0.80159482 | F28: =+F18/F13 -> -0.43035573 | G28: =+G18/G13 -> -0.33714544 | H28: =+H18/H13 -> -0.22520065 | I28: =+I18/I13 -> -0.16287873 | J28: =+J18/J13 -> -0.11081093 | K28: =+K18/K13 -> -0.065952177 | ... V28: =+V18/V13 -> 0.1156668
B29: Revenue Y/Y | E29: =+E13/D13 -1 -> 0.8155411 | F29: =+F13/E13 -1 -> 0.64840555 | G29: =+G13/F13 -1 -> 0.3721904 | H29: =+H13/G13 -1 -> 0.29847461 | I29: =+I13/H13 -1 -> 0.1999996 | J29: =+J13/I13 -1 -> 0.16666648 | K29: =+K13/J13 -1 -> 0.14285886 | L29: =+L13/K13 -1 -> 0.15624895 | ... V29: =+V13/U13 -1 -> 0.040131018
B31: CFFO | D31: -80382 | E31: -108003 | F31: -99213
B32: CapEx | D32: 2653 | E32: 25206 | F32: 4409
B33: FCF | D33: =+D31-D32 -> -83035 | E33: =+E31-E32 -> -133209 | F33: =+F31-F32 -> -103622
B35: Issue of Stocks | E35: 161705 | F35: 164523
B36: FFCF | E36: =+E33+E35 -> 28496 | F36: =+F33+F35 -> 60901
B38: Cash | E38: 257222 | F38: 333725 | G38: 294281
B39: PP&E | E39: 27748 | F39: 26709 | G39: 30022
B40: Debt | E40: 51339 | F40: 51472 | G40: 51566
B41: NAV | E41: =+E38+E39-E40 -> 233631 | F41: =+F38+F39-F40 -> 308962 | G41: =+G38+G39-G40 -> 272737
B43: R&D | D43: =+D16/D$13 -> 0.38634122 | E43: =+E16/E$13 -> 0.35572101 | F43: =+F16/F$13 -> 0.27749913 | G43: =+G16/G$13 -> 0.23137826 | H43: =+H16/H$13 -> 0.22074109 | I43: =+I16/I$13 -> 0.21338306 | J43: =+J16/J$13 -> 0.20728641 | K43: =+K16/K$13 -> 0.20210419 | ... V43: =+V16/V$13 -> 0.1728785
B44: SG&A | D44: =+D17/D$13 -> 1.1841523 | E44: =+E17/E$13 -> 0.96756026 | F44: =+F17/F$13 -> 0.763548 | G44: =+G17/G$13 -> 0.74275289 | H44: =+H17/H$13 -> 0.67445957 | I44: =+I17/I$13 -> 0.62949567 | J44: =+J17/J$13 -> 0.59352452 | K44: =+K17/K$13 -> 0.56384798 | ... V44: =+V17/V$13 -> 0.4114547
B46: NOL | D46: =-D21 -> 83896 | E46: =+D46-E21 -> 189793 | F46: =+E46-F21 -> 281206 | G46: =+F46-G21 -> 376588 | H46: =+G46-H21 -> 460168.33 | I46: =+H46-I21 -> 531850.15 | J46: =+I46-J21 -> 587404.29 | K46: =+J46-K21 -> 623113.75 | L46: =+K46-L21 -> 638822.54 | M46: =+L46-M47 -> 635357.75 | N46: =+M46-N47 -> 614616.11 | O46: =+N46-O47 -> 577557.87 | P46: =+O46-P47 -> 523426.07 | Q46: =+P46-Q47 -> 453759.26 | R46: =+Q46-R47 -> 370093.83 | S46: =+R46-S47 -> 271705.45 | T46: =+S46-T47 -> 160519.38
B47: NOL used | M47: =+M21*0.8 -> 3464.7867 | N47: =+N21*0.8 -> 20741.638 | O47: =+O21*0.8 -> 37058.24 | P47: =+P21*0.8 -> 54131.799 | Q47: =+Q21*0.8 -> 69666.817 | R47: =+R21*0.8 -> 83665.43 | S47: =+S21*0.8 -> 98388.372 | T47: =+T21*0.8 -> 111186.07 | U47: =+T46 -> 160519.38
B48: Taxable income | M48: =+M21-M47 -> 866.19667 | N48: =+N21-N47 -> 5185.4094 | O48: =+O21-O47 -> 9264.5601 | P48: =+P21-P47 -> 13532.95 | Q48: =+Q21-Q47 -> 17416.704 | R48: =+R21-R47 -> 20916.358 | S48: =+S21-S47 -> 24597.093 | T48: =+T21-T47 -> 27796.517 | U48: =+U21-U47 -> -4950.5563
B49: Tax | M49: =+M48*0.21 -> 181.9013 | N49: =+N48*0.21 -> 1088.936 | O49: =+O48*0.21 -> 1945.5576 | P49: =+P48*0.21 -> 2841.9195 | Q49: =+Q48*0.21 -> 3657.5079 | R49: =+R48*0.21 -> 4392.4351 | S49: =+S48*0.21 -> 5165.3895 | T49: =+T48*0.21 -> 5837.2686 | U49: =+U48*0.21 -> -1039.6168
