Workbook
Name MV: Sheet2!$AE$32

Sheet Sheet1
C3: Price | D3: 40.27
C4: Shares | D4: 977
C5: Cap | D5: =+D3*D4 -> 39343.79
C6: Net Cash | D6: =+Sheet2!AE34 -> 3080
C7: EV | D7: =+D5-D6 -> 36263.79
D9: =+Sheet2!AE36/Sheet1!D3 -1 -> 0.43177651
C12: EV/FCF | D12: =+D7/Sheet2!T42 -> 11.412849
C13: FCF Yield | D13: =1/D12 -> 0.087620544

Sheet Sheet2
B1: Q121 | C1: Q221 | D1: Q321 | E1: Q421 | F1: Q122 | G1: Q222 | H1: Q322 | I1: Q422 | M1: FY19 | N1: FY20 | O1: FY21 | P1: FY22 | Q1: FY23 | R1: FY24 | S1: FY25 | T1: FY26 | U1: FY27 | V1: FY28 | W1: FY29 | X1: FY30 | Y1: FY31 | Z1: FY32 | AA1: FY33 | AB1: FY34
A3: US People | M3: 238.3 | N3: 329.5 | O3: 332.9 | P3: =+O3*1.01 -> 336.229 | Q3: =+P3*1.01 -> 339.59129 | R3: =+Q3*1.01 -> 342.9872 | S3: =+R3*1.01 -> 346.41707 | T3: =+S3*1.01 -> 349.88125 | U3: =+T3*1.01 -> 353.38006 | V3: =+U3*1.01 -> 356.91386 | W3: =+V3*1.01 -> 360.483 | X3: =+W3*1.01 -> 364.08783
A4: US Penetration
A6: Active Accounts | M6: 305 | O6: 426 | P6: 435 | Q6: 426 | R6: 434 | S6: 439 | T6: =+S6*1.005 -> 441.195 | U6: =+T6*1.005 -> 443.40097 | V6: =+U6*1.005 -> 445.61798 | W6: =+V6*1.005 -> 447.84607 | X6: =+W6*1.005 -> 450.0853 | Y6: =+X6*1.005 -> 452.33573 | Z6: =+Y6*1.005 -> 454.59741 | AA6: =+Z6*1.005 -> 456.87039 | AB6: =+AA6*1.005 -> 459.15474
A7: Transaction | M7: 12400 | O7: 19300 | P7: 22349 | Q7: 24981 | R7: 26334 | S7: =6045+6226+6331+6754 -> 25356 | T7: =+T6*T8 -> 25589.31 | U7: =+U6*U8 -> 25717.257 | V7: =+V6*V8 -> 25845.843 | W7: =+W6*W8 -> 25975.072 | X7: =+X6*X8 -> 26104.947 | Y7: =+Y6*Y8 -> 26235.472 | Z7: =+Z6*Z8 -> 26366.65 | AA7: =+AA6*AA8 -> 26498.483 | AB7: =+AB6*AB8 -> 26630.975
A8: TPA | M8: =+M7/M6 -> 40.655738 | O8: =+O7/O6 -> 45.305164 | P8: =+P7/P6 -> 51.377011 | Q8: =+Q7/Q6 -> 58.640845 | R8: =+R7/R6 -> 60.677419 | S8: =+S7/S6 -> 57.758542 | T8: 58 | U8: 58 | V8: 58 | W8: 58 | X8: 58 | Y8: 58 | Z8: 58 | AA8: 58 | AB8: 58
A9: TPV | S9: =475.135+458.088+443.547+417.208 -> 1793.978 | T9: =+T7*T10/1000 -> 1846.6948 | U9: =+U7*U10/1000 -> 1893.0468 | V9: =+V7*V10/1000 -> 1940.5623 | W9: =+W7*W10/1000 -> 1989.2704 | X9: =+X7*X10/1000 -> 2039.2011 | Y9: =+Y7*Y10/1000 -> 2090.385 | Z9: =+Z7*Z10/1000 -> 2142.8537 | AA9: =+AA7*AA10/1000 -> 2196.6393 | AB9: =+AB7*AB10/1000 -> 2251.775
A10: VPT | S10: =+S9*1000/S7 -> 70.751617 | T10: =+S10*1.02 -> 72.166649 | U10: =+T10*1.02 -> 73.609982 | V10: =+U10*1.02 -> 75.082182 | W10: =+V10*1.02 -> 76.583826 | X10: =+W10*1.02 -> 78.115502 | Y10: =+X10*1.02 -> 79.677812 | Z10: =+Y10*1.02 -> 81.271368 | AA10: =+Z10*1.02 -> 82.896796 | AB10: =+AA10*1.02 -> 84.554732
A12: Revenue/Transaction | M12: =+M14/M7 -> 1.4332258 | O12: =+O14/O7 -> 1.3145596 | P12: =+P14/P7 -> 1.2312855 | Q12: =+Q14/Q7 -> 1.1917457 | R12: =+R14/R7 -> 1.2074504 | S12: =+S14/S7 -> 1.3082505 | T12: =+S12*1.02 -> 1.3344155 | U12: =+T12*1.02 -> 1.3611038 | V12: =+U12*1.02 -> 1.3883259 | W12: =+V12*1.02 -> 1.4160924 | X12: =+W12*1.02 -> 1.4444143 | Y12: =+X12*1.02 -> 1.4733026 | Z12: =+Y12*1.02 -> 1.5027686 | AA12: =+Z12*1.02 -> 1.532824 | AB12: =+AA12*1.02 -> 1.5634805
A14: Revenue | B14: 6033 | F14: 6483 | M14: 17772 | N14: 21454 | O14: 25371 | P14: 27518 | Q14: 29771 | R14: 31797 | S14: 33172 | T14: =+T7*T12 -> 34146.772 | U14: =+U7*U12 -> 35003.856 | V14: =+V7*V12 -> 35882.453 | W14: =+W7*W12 -> 36783.103 | X14: =+X7*X12 -> 37706.359 | Y14: =+Y7*Y12 -> 38652.788 | Z14: =+Z7*Z12 -> 39622.973 | AA14: =+AA7*AA12 -> 40617.51 | AB14: =+AB7*AB12 -> 41637.009
A15: Transaction expense | B15: 2275 | F15: 2817 | M15: 6790 | N15: 7934 | O15: 10315 | P15: 12173 | Q15: 14385 | R15: 15697 | S15: 15987 | T15: =+T14*0.48 -> 16390.451 | U15: =+U14*0.48 -> 16801.851 | V15: =+V14*0.48 -> 17223.578 | W15: =+W14*0.48 -> 17655.889 | X15: =+X14*0.48 -> 18099.052 | Y15: =+Y14*0.48 -> 18553.338 | Z15: =+Z14*0.48 -> 19019.027 | AA15: =+AA14*0.48 -> 19496.405 | AB15: =+AB14*0.48 -> 19985.765
A16: Gross Profit | B16: =+B14-B15 -> 3758 | C16: =+C14-C15 -> 0 | D16: =+D14-D15 -> 0 | E16: =+E14-E15 -> 0 | F16: =+F14-F15 -> 3666 | G16: =+G14-G15 -> 0 | H16: =+H14-H15 -> 0 | I16: =+I14-I15 -> 0 | M16: =+M14-M15 -> 10982 | N16: =+N14-N15 -> 13520 | O16: =+O14-O15 -> 15056 | P16: =+P14-P15 -> 15345 | Q16: =+Q14-Q15 -> 15386 | R16: =+R14-R15 -> 16100 | S16: =+S14-S15 -> 17185 | T16: =+T14-T15 -> 17756.322 | ... AB16: =+AB14-AB15 -> 21651.245
A17: Credit losses | B17: 273 | F17: 369 | M17: 1380 | N17: 1741 | O17: 1060 | P17: 1572 | Q17: 1682 | R17: 1442 | S17: 1720 | T17: =+T9*0.001*1000 -> 1846.6948 | U17: =+U9*0.001*1000 -> 1893.0468 | V17: =+V9*0.001*1000 -> 1940.5623 | W17: =+W9*0.001*1000 -> 1989.2704 | X17: =+X9*0.001*1000 -> 2039.2011 | Y17: =+Y9*0.001*1000 -> 2090.385 | Z17: =+Z9*0.001*1000 -> 2142.8537 | AA17: =+AA9*0.001*1000 -> 2196.6393 | AB17: =+AB9*0.001*1000 -> 2251.775
A18: Customer Support | B18: 518 | F18: 534 | M18: 1615 | N18: 1778 | O18: 2075 | P18: 2120 | Q18: 1919 | R18: 1768 | S18: 1704 | T18: =+T6*4 -> 1764.78 | U18: =+U6*4 -> 1773.6039 | V18: =+V6*4 -> 1782.4719 | W18: =+W6*4 -> 1791.3843 | X18: =+X6*4 -> 1800.3412 | Y18: =+Y6*4 -> 1809.3429 | Z18: =+Z6*4 -> 1818.3896 | AA18: =+AA6*4 -> 1827.4816 | AB18: =+AB6*4 -> 1836.619
A19: Sales | B19: 602 | F19: 594 | M19: 1401 | N19: 1861 | O19: 2445 | P19: 2257 | Q19: 1809 | R19: 2001 | S19: 2283 | T19: =+T14*0.07 -> 2390.2741 | U19: =+U14*0.07 -> 2450.27 | V19: =+V14*0.07 -> 2511.7717 | W19: =+W14*0.07 -> 2574.8172 | X19: =+X14*0.07 -> 2639.4451 | Y19: =+Y14*0.07 -> 2705.6952 | Z19: =+Z14*0.07 -> 2773.6081 | AA19: =+AA14*0.07 -> 2843.2257 | AB19: =+AB14*0.07 -> 2914.5907
A20: R&D | B20: 741 | F20: 815 | M20: 2085 | N20: 2642 | O20: 3038 | P20: 3253 | Q20: 2973 | R20: 2979 | S20: 3103 | T20: =+T14*0.094 -> 3209.7966 | U20: =+U14*0.094 -> 3290.3625 | V20: =+V14*0.094 -> 3372.9506 | W20: =+W14*0.094 -> 3457.6117 | X20: =+X14*0.094 -> 3544.3977 | Y20: =+Y14*0.094 -> 3633.3621 | Z20: =+Z14*0.094 -> 3724.5595 | AA20: =+AA14*0.094 -> 3818.0459 | AB20: =+AB14*0.094 -> 3913.8789
A21: G&A | B21: 524 | F21: 607 | M21: 1711 | N21: 2070 | O21: 2114 | P21: 2099 | Q21: 2059 | R21: 2147 | S21: 1979 | T21: =+S21*1.04 -> 2058.16 | U21: =+T21*1.04 -> 2140.4864 | V21: =+U21*1.04 -> 2226.1059 | W21: =+V21*1.04 -> 2315.1501 | X21: =+W21*1.04 -> 2407.7561 | Y21: =+X21*1.04 -> 2504.0663 | Z21: =+Y21*1.04 -> 2604.229 | AA21: =+Z21*1.04 -> 2708.3982 | AB21: =+AA21*1.04 -> 2816.7341
A22: Restructuring | B22: 58 | F22: 36 | M22: 71 | N22: 139 | O22: 62 | P22: 207 | Q22: -84 | R22: 438 | S22: 331 | T22: =+S22*0.8 -> 264.8 | U22: =+T22*0.8 -> 211.84 | V22: =+U22*0.8 -> 169.472 | W22: =+V22*0.8 -> 135.5776 | X22: =+W22*0.8 -> 108.46208 | Y22: =+X22*0.8 -> 86.769664 | Z22: =+Y22*0.8 -> 69.415731 | AA22: =+Z22*0.8 -> 55.532585 | AB22: =+AA22*0.8 -> 44.426068
A23: Operating Expenses | B23: =+SUM(B17:B22) -> 2716 | C23: =+SUM(C17:C22) -> 0 | D23: =+SUM(D17:D22) -> 0 | E23: =+SUM(E17:E22) -> 0 | F23: =+SUM(F17:F22) -> 2955 | G23: =+SUM(G17:G22) -> 0 | H23: =+SUM(H17:H22) -> 0 | I23: =+SUM(I17:I22) -> 0 | M23: =+SUM(M17:M22) -> 8263 | N23: =+SUM(N17:N22) -> 10231 | O23: =+SUM(O17:O22) -> 10794 | P23: =+SUM(P17:P22) -> 11508 | Q23: =+SUM(Q17:Q22) -> 10358 | R23: =+SUM(R17:R22) -> 10775 | S23: =+SUM(S17:S22) -> 11120 | T23: =+SUM(T17:T22) -> 11534.505 | ... AB23: =+SUM(AB17:AB22) -> 13778.024
A24: Operating Income | B24: =+B16-B23 -> 1042 | C24: =+C16-C23 -> 0 | D24: =+D16-D23 -> 0 | E24: =+E16-E23 -> 0 | F24: =+F16-F23 -> 711 | G24: =+G16-G23 -> 0 | H24: =+H16-H23 -> 0 | I24: =+I16-I23 -> 0 | M24: =+M16-M23 -> 2719 | N24: =+N16-N23 -> 3289 | O24: =+O16-O23 -> 4262 | P24: =+P16-P23 -> 3837 | Q24: =+Q16-Q23 -> 5028 | R24: =+R16-R23 -> 5325 | S24: =+S16-S23 -> 6065 | T24: =+T16-T23 -> 6221.8162 | ... AB24: =+AB16-AB23 -> 7873.2213
A25: Other Income | B25: -170 | F25: 82 | M25: 279 | N25: 1776 | O25: -163 | P25: -471 | Q25: 383 | R25: 4 | S25: 227
A26: Pretax Income | B26: =+B24+B25 -> 872 | C26: =+C24+C25 -> 0 | D26: =+D24+D25 -> 0 | E26: =+E24+E25 -> 0 | F26: =+F24+F25 -> 793 | G26: =+G24+G25 -> 0 | H26: =+H24+H25 -> 0 | I26: =+I24+I25 -> 0 | M26: =+M24+M25 -> 2998 | N26: =+N24+N25 -> 5065 | O26: =+O24+O25 -> 4099 | P26: =+P24+P25 -> 3366 | Q26: =+Q24+Q25 -> 5411 | R26: =+R24+R25 -> 5329 | S26: =+S24+S25 -> 6292 | T26: =+T24+T25 -> 6221.8162 | ... AB26: =+AB24+AB25 -> 7873.2213
A27: Taxes | B27: -225 | F27: 120 | M27: 539 | N27: 863 | O27: -70 | P27: 947 | Q27: 1165 | R27: 1182 | S27: 1059 | T27: =+T26*0.2 -> 1244.3632 | U27: =+U26*0.2 -> 1288.4792 | V27: =+V26*0.2 -> 1331.1083 | W27: =+W26*0.2 -> 1372.6805 | X27: =+X26*0.2 -> 1413.5407 | Y27: =+Y26*0.2 -> 1453.9657 | Z27: =+Z26*0.2 -> 1494.1781 | AA27: =+AA26*0.2 -> 1534.3564 | AB27: =+AB26*0.2 -> 1574.6443
A28: Net Income | B28: =+B26-B27 -> 1097 | C28: =+C26-C27 -> 0 | D28: =+D26-D27 -> 0 | E28: =+E26-E27 -> 0 | F28: =+F26-F27 -> 673 | G28: =+G26-G27 -> 0 | H28: =+H26-H27 -> 0 | I28: =+I26-I27 -> 0 | M28: =+M26-M27 -> 2459 | N28: =+N26-N27 -> 4202 | O28: =+O26-O27 -> 4169 | P28: =+P26-P27 -> 2419 | Q28: =+Q26-Q27 -> 4246 | R28: =+R26-R27 -> 4147 | S28: =+S26-S27 -> 5233 | T28: =+T26-T27 -> 4977.453 | ... AB28: =+AB26-AB27 -> 6298.577 | AC28: =+AB28*(1+MV) -> 6235.5913 | AD28: =+AC28*(1+MV) -> 6173.2353 | AE28: =+AD28*(1+MV) -> 6111.503 | AF28: =+AE28*(1+MV) -> 6050.388 | AG28: =+AF28*(1+MV) -> 5989.8841 | AH28: =+AG28*(1+MV) -> 5929.9852 | AI28: =+AH28*(1+MV) -> 5870.6854 | AJ28: =+AI28*(1+MV) -> 5811.9785 | ... CO28: =+CN28*(1+MV) -> 3277.4049
AB29: =+AB28/Sheet1!D4 -> 6.4468547
A30: Gross Margin | B30: =+B16/B14 -> 0.62290734 | C30: =+C16/C14 -> #DIV/0! | D30: =+D16/D14 -> #DIV/0! | E30: =+E16/E14 -> #DIV/0! | F30: =+F16/F14 -> 0.56547894 | G30: =+G16/G14 -> #DIV/0! | H30: =+H16/H14 -> #DIV/0! | I30: =+I16/I14 -> #DIV/0! | M30: =+M16/M14 -> 0.61793833 | N30: =+N16/N14 -> 0.63018551 | O30: =+O16/O14 -> 0.59343345 | P30: =+P16/P14 -> 0.557635 | Q30: =+Q16/Q14 -> 0.51681166 | R30: =+R16/R14 -> 0.50633708 | S30: =+S16/S14 -> 0.5180574 | T30: =+T16/T14 -> 0.52 | ... AB30: =+AB16/AB14 -> 0.52
A31: Operating Margin | B31: =+B24/B14 -> 0.17271672 | C31: =+C24/C14 -> #DIV/0! | D31: =+D24/D14 -> #DIV/0! | E31: =+E24/E14 -> #DIV/0! | F31: =+F24/F14 -> 0.10967145 | G31: =+G24/G14 -> #DIV/0! | H31: =+H24/H14 -> #DIV/0! | I31: =+I24/I14 -> #DIV/0! | M31: =+M24/M14 -> 0.15299347 | N31: =+N24/N14 -> 0.15330475 | O31: =+O24/O14 -> 0.16798707 | P31: =+P24/P14 -> 0.13943601 | Q31: =+Q24/Q14 -> 0.16888919 | R31: =+R24/R14 -> 0.16746863 | S31: =+S24/S14 -> 0.18283492 | T31: =+T24/T14 -> 0.18220803 | ... AB31: =+AB24/AB14 -> 0.1890919 | AD31: Discount | AE31: 0.1
A32: Net Margin | B32: =+B28/B14 -> 0.18183325 | C32: =+C28/C14 -> #DIV/0! | D32: =+D28/D14 -> #DIV/0! | E32: =+E28/E14 -> #DIV/0! | F32: =+F28/F14 -> 0.10380996 | G32: =+G28/G14 -> #DIV/0! | H32: =+H28/H14 -> #DIV/0! | I32: =+I28/I14 -> #DIV/0! | M32: =+M28/M14 -> 0.13836372 | N32: =+N28/N14 -> 0.19586091 | O32: =+O28/O14 -> 0.16432147 | P32: =+P28/P14 -> 0.087906098 | Q32: =+Q28/Q14 -> 0.14262201 | R32: =+R28/R14 -> 0.13042111 | S32: =+S28/S14 -> 0.15775353 | T32: =+T28/T14 -> 0.14576643 | ... AB32: =+AB28/AB14 -> 0.15127352 | AD32: Maturity | AE32: -0.01
AD33: NPV | AE33: =NPV(AE31,Q28:CP28) -> 53251.514
A34: Revenue Y/Y | F34: =+F14/B14 -1 -> 0.074589756 | N34: =+N14/M14 -1 -> 0.20717983 | O34: =+O14/N14 -1 -> 0.18257668 | P34: =+P14/O14 -1 -> 0.084624177 | Q34: =+Q14/P14 -1 -> 0.081873683 | R34: =+R14/Q14 -1 -> 0.068052803 | S34: =+S14/R14 -1 -> 0.043243073 | T34: =+T14/S14 -1 -> 0.0293854 | U34: =+U14/T14 -1 -> 0.0251 | ... AB34: =+AB14/AA14 -1 -> 0.0251 | AD34: Net Cash | AE34: =8995+1760+3601-11276 -> 3080
A35: Net Income Y/Y | N35: =+N28/M28 -1 -> 0.70882473 | O35: =+O28/N28 -1 -> -0.0078534031 | P35: =+P28/O28 -1 -> -0.41976493 | Q35: =+Q28/P28 -1 -> 0.75527077 | R35: =+R28/Q28 -1 -> -0.023316062 | S35: =+S28/R28 -1 -> 0.26187605 | T35: =+T28/S28 -1 -> -0.048833748 | U35: =+U28/T28 -1 -> 0.0354526 | ... AB35: =+AB28/AA28 -1 -> 0.02625718 | AD35: Value | AE35: =+AE33+AE34 -> 56331.514
A36: Acounts Y/Y | P36: =+P6/O6 -1 -> 0.021126761 | Q36: =+Q6/P6 -1 -> -0.020689655 | R36: =+R6/Q6 -1 -> 0.018779343 | S36: =+S6/R6 -1 -> 0.011520737 | T36: =+T6/S6 -1 -> 0.005 | U36: =+U6/T6 -1 -> 0.005 | V36: =+V6/U6 -1 -> 0.005 | W36: =+W6/V6 -1 -> 0.005 | ... AB36: =+AB6/AA6 -1 -> 0.005 | AD36: Price | AE36: =+AE35/Sheet1!D4 -> 57.65764
AD37: Diff | AE37: =+AE36/Sheet1!D3 -1 -> 0.43177651
A38: CFFO | P38: 5813 | Q38: 4843 | R38: 7450 | S38: 6416 | T38: =+T28 -> 4977.453
A39: CapEx | P39: 706 | Q39: 623 | R39: 683 | S39: 852 | T39: 800
A40: FCF | P40: =+P38-P39 -> 5107 | Q40: =+Q38-Q39 -> 4220 | R40: =+R38-R39 -> 6767 | S40: =+S38-S39 -> 5564 | T40: =+T38-T39 -> 4177.453
A41: SBC | Q41: 1475 | R41: 1230 | S41: 1002 | T41: 1000
A42: Adj. FCF | Q42: =+Q40-Q41 -> 2745 | R42: =+R40-R41 -> 5537 | S42: =+S40-S41 -> 4562 | T42: =+T40-T41 -> 3177.453
A44: Stock buybacks | S44: 5700 | T44: 6000
A45: Stocks bought | S45: 78
...
