Workbook
Name Neutron: Main!$M$14
Name shares: Main!$E$6
Name TCF: Model!#REF!
Name TR: Model!$AJ$56

Sheet Main
H4: Launch Pad: | O4: Spce Hardware: | T4: Hypersonic: | U4: Payload | V4: Altitude
D5: Price | E5: 4.3 | O5: Star Tracker: | P5: Price tsd | Q5: Specifications | R5: In Orbit | T5: Haste | U5: 700 | V5: 80km
D6: Shares | E6: 475.36 | H6: Location | I6: Name | J6: Launches | O6: ST-16RT2 | P6: 120-140 | R6: =30+13+10 -> 53
D7: Market Cap | E7: =+E5*E6 -> 2044.048 | H7: New Zealand | I7: LC-1 | J7: 120 | O7: ST-16HV
D8: Net Cash | E8: =242.515+229.276+36.5-100.043-2.906 -> 405.342 | H8: Virginia | I8: LC-2 | J8: 12 | O8: Radios:
D9: EV | E9: =+E7-E8 -> 1638.706 | O9: Frontier-S
O10: Frontier-S-LEO-ST | P10: 115 | Q10: Standard | R10: LEO
O11: Frontier-S-LEO-HR | P11: 200 | Q11: High Reliability | R11: LEO
H12: Rockets: | O12: Frontier-S-DSN-ST | P12: 165 | Q12: Standard | R12: Deep Space
I13: LEO | J13: Height | K13: Radius | L13: Propellant | M13: Rev/Launch | O13: Frontier-S-DSN-HR | P13: 250 | Q13: High Reliability | R13: Deep Space
D14: Q123 | E14: Q223 | H14: Neutron: | I14: 13000 | J14: 40 | K14: 7 | L14: Methane | M14: 50000 | O14: Frontier-X
C15: Revenue | D15: 54.9 | E15: 62 | H15: Electron | I15: 300 | J15: 18 | K15: 1.2 | L15: Kerosene | M15: 6750 | O15: Frontier-X-LEO-ST | P15: 175 | Q15: Standard | R15: LEO
C16: Launch | D16: 19.6 | E16: 39 | O16: Frontier-X-LEO-HR | P16: 250 | Q16: High Reliability | R16: LEO
C17: Systems | D17: 35.3 | E17: 23 | O17: Frontier-X-DSN-ST | P17: 225 | Q17: Standard | R17: Deep Space
O18: Frontier-X-DSN-HR | P18: 300 | Q18: High Reliability | R18: Deep Space
C19: Margin | D19: 0.173 | E19: 0.22 | H19: 25 Spacecrasfts in Manufacturing
O20: Space Software | P20: Cumulative years in Space
C21: Expense | E21: 42 | O21: MAX Flight Control | P21: 188 Years 99 Days
O22: Solis simulation environment
O23: MAX Ground Data System
O25: Separations Systems: | P25: Reliability | Q25: Type Symbol | S25: Flight Heritage 2023: | Y25: Flight Heritage 2022:
O26: Advanced Lightband | P26: 1 | Q26: ALB | S26: Launch Vehicle | T26: Date | U26: System Size | V26: System Type | W26: Client | Y26: Launch Vehicle | Z26: Date | AA26: System Size | AB26: System Type | AC26: Client
O27: Motorized Lightband | P27: 1 | Q27: MLB | S27: Falcon 9 | T27: 45031 | U27: 8 | V27: MLB Mk 2 | W27: UTIAS | Y27: Falcon 9 | Z27: 44906 | AA27: 6U | AB27: CSD | AC27: NASA
O28: Satellite Dispensers | Q28: CSD | S28: Falcon 9 | T28: 45031 | U28: 15 | V28: MLB Mk 2 | W28: Orbital Sidekick | Y28: Antares | Z28: 44872 | AA28: 11 | AB28: MLB Mk 2 | AC28: NASA
S29: Falcon 9 | T29: 45031 | U29: 15 | V29: MLB Mk 2 | W29: Orbital Sidekick | Y29: Falcon Heavy | Z29: 44866 | AA29: 8 | AB29: MLB Mk 2 | AC29: US Space Force
O30: Photon: | S30: Falcon 9 | T30: 45031 | U30: 15 | V30: MLB Mk 2 | W30: Umbra Space | Y30: Falcon 9 | Z30: 44809 | AA30: 24 | AB30: MLB Mk 2 | AC30: Spaceflight Inc.
O31: Kick Stages Deployed | P31: 22 | Q31: Q123 | S31: Falcon 9 | T31: 45031 | U31: 8 | V31: MLB Mk 2 | W31: HawkEye 360 | Y31: Electron | Z31: 44755 | AA31: 11 | AB31: MLB Mk 2 | AC31: NRO
O32: Spacecraft on Orbit | P32: 3 | Q32: Q123 | S32: Falcon 9 | T32: 45031 | U32: 8 | V32: MLB Mk 2 | W32: HawkEye 360 | Y32: Altas V | Z32: 44743 | AA32: 12U | AB32: CSD | AC32: Space Test Program
S33: Falcon 9 | T33: 45031 | U33: 8 | V33: MLB Mk 2 | W33: HawkEye 360 | Y33: Astra Rocket | Z33: 44724 | AA33: 3U | AB33: 2x CSD | AC33: NASA
O34: Solar Solutions: | S34: Falcon 9 | T34: 45031 | U34: 15 | V34: ALB | W34: Tomorrow.io | Y34: Falcon 9 | Z34: 44706 | AA34: 15 | AB34: MLB Mk 2 | AC34: Umbra Space
O35: Setellites in Orbit | P35: 1000+ | S35: Falcon 9 | T35: 45031 | U35: 24 | V35: MLB Mk 2 | W35: D-Orbit | Y35: Falcon 9 | Z35: 44706 | AA35: 24 | AB35: ALB | AC35: Spaceflight Inc.
O36: Setellites Scheduled | P36: 415 | S36: Electron | T36: 45009 | U36: 11 | V36: MLB Mk 2 | W36: BlackSky Global | Y36: Falcon 9 | Z36: 44706 | AA36: 24 | AB36: MLB Mk 2 | AC36: Momentus Space
S37: Electron | T37: 45009 | U37: 11 | V37: MLB Mk 2 | W37: BlackSky Global | Y37: Falcon 9 | Z37: 44706 | AA37: 24 | AB37: MLB Mk 2 | AC37: HawkEye 360
S38: Electron | T38: 45001 | U38: 11 | V38: MLB Mk 2 | W38: Capella Space | Y38: Falcon 9 | Z38: 44706 | AA38: 24 | AB38: MLB Mk 2 | AC38: D-Orbit
S39: Electron | T39: 45001 | U39: 11 | V39: MLB Mk 2 | W39: Capella Space | Y39: Electron | Z39: 44906 | AA39: 11.732 | AB39: MLB Mk 2 | AC39: BlackSky Global
S40: Falcon 9 | T40: 44957 | U40: 24 | V40: MLB Mk 2 | W40: D-Orbit | Y40: Falcon 9 | Z40: 44906 | AA40: 8 | AB40: MLB Mk 2 | AC40: UTIAS-Hawkeye
S41: Electron | T41: 44950 | U41: 8 | V41: MLB Mk 2 | W41: HawkEye 360 | Y41: Falcon 9 | Z41: 44906 | AA41: 24 | AB41: MLB Mk 2 | AC41: D-Orbit
S42: Electron | T42: 44950 | U42: 8 | V42: MLB Mk 2 | W42: HawkEye 360 | Y42: Falcon 9 | Z42: 44907 | AA42: 8 | AB42: ALB | AC42: PlanetIQ
S43: Electron | T43: 44950 | U43: 8 | V43: MLB Mk 2 | W43: HawkEye 360 | Y43: Falcon 9 | Z43: 44908 | AA43: 15 | AB43: MLB Mk 2 | AC43: Lynk Tower 01
S44: Falcon 9 | T44: 44929 | U44: 15 | V44: MLB Mk 2 | W44: Umbra Lab | Y44: Antares | Z44: 44909 | AA44: 11.732 | AB44: MLB Mk 2 | AC44: NGC, NASA
...

Sheet Model
C1: Q122 | D1: Q222 | E1: Q322 | F1: Q422 | G1: Q123 | H1: Q223 | I1: Q323 | J1: Q423 | K1: Q124 | L1: Q224 | M1: Q324 | N1: Q424 | Q1: =+R1-1 -> 2018 | R1: 2019 | S1: =+R1+1 -> 2020 | T1: =+S1+1 -> 2021 | U1: =+T1+1 -> 2022 | V1: =+U1+1 -> 2023 | W1: 2024 | X1: =+W1+1 -> 2025 | Y1: =+X1+1 -> 2026 | Z1: =+Y1+1 -> 2027 | AA1: =+Z1+1 -> 2028 | AB1: =+AA1+1 -> 2029 | AC1: =+AB1+1 -> 2030 | AD1: =+AC1+1 -> 2031 | AE1: =+AD1+1 -> 2032 | ... AG1: =+AF1+1 -> 2034
V2: =+V3/U3 -1 -> 0.058047345 | W2: =+W3/V3 -1 -> 0.058414214 | X2: =+X3/W3 -1 -> 0.058799322 | Y2: =+Y3/X3 -1 -> 0.059203333 | Z2: =+Z3/Y3 -1 -> 0.059626904 | AA2: =+AA3/Z3 -1 -> 0.033865072 | AB2: =+AB3/AA3 -1 -> 0.025631897 | AC2: =+AC3/AB3 -1 -> 0.023860404 | ... AG2: =+AG3/AF3 -1 -> 0.024267491
A3: Million | B3: Satellite Market: | U3: =+SUM(U4:U7) -> 8153 | V3: =+SUM(V4:V7) -> 8626.26 | W3: =+SUM(W4:W7) -> 9130.1562 | X3: =+SUM(X4:X7) -> 9667.0032 | Y3: =+SUM(Y4:Y7) -> 10239.322 | Z3: =+SUM(Z4:Z7) -> 10849.861 | AA3: =+SUM(AA4:AA7) -> 11217.292 | AB3: =+SUM(AB4:AB7) -> 11504.813 | ... AG3: =+SUM(AG4:AG7) -> 12957.176
A4: >7k | B4: Super Heavy Sat. | U4: 480 | V4: =+U4*1.12 -> 537.6 | W4: =+V4*1.12 -> 602.112 | X4: =+W4*1.12 -> 674.36544 | Y4: =+X4*1.12 -> 755.28929 | Z4: =+Y4*1.12 -> 845.92401 | AA4: =+Z4*1.12 -> 947.43489 | AB4: =+AA4*1.05 -> 994.80663 | AC4: =+AB4*1.05 -> 1044.547 | AD4: =+AC4*1.05 -> 1096.7743 | AE4: =+AD4*1.05 -> 1151.613 | AF4: =+AE4*1.05 -> 1209.1937 | AG4: =+AF4*1.05 -> 1269.6534
A5: 5-7k | B5: Heavy Sat. | U5: 5930 | V5: =+U5*1.05 -> 6226.5 | W5: =+V5*1.05 -> 6537.825 | X5: =+W5*1.05 -> 6864.7163 | Y5: =+X5*1.05 -> 7207.9521 | Z5: =+Y5*1.05 -> 7568.3497 | AA5: =+Z5*1.02 -> 7719.7167 | AB5: =+AA5*1.02 -> 7874.111 | AC5: =+AB5*1.02 -> 8031.5932 | AD5: =+AC5*1.02 -> 8192.2251 | AE5: =+AD5*1.02 -> 8356.0696 | AF5: =+AE5*1.02 -> 8523.191 | AG5: =+AF5*1.02 -> 8693.6548
A6: 1,2-5k | B6: Medium Sat. | U6: 1500 | V6: =+U6*1.06 -> 1590 | W6: =+V6*1.06 -> 1685.4 | X6: =+W6*1.06 -> 1786.524 | Y6: =+X6*1.06 -> 1893.7154 | Z6: =+Y6*1.06 -> 2007.3384 | AA6: =+Z6*1.04 -> 2087.6319 | AB6: =+AA6*1.03 -> 2150.2609 | AC6: =+AB6*1.02 -> 2193.2661 | AD6: =+AC6*1.02 -> 2237.1314 | AE6: =+AD6*1.02 -> 2281.874 | AF6: =+AE6*1.02 -> 2327.5115 | AG6: =+AF6*1.02 -> 2374.0617
A7: ,6-1,2k | B7: Small Sat. | U7: 243 | V7: =+U7*1.12 -> 272.16 | W7: =+V7*1.12 -> 304.8192 | X7: =+W7*1.12 -> 341.3975 | Y7: =+X7*1.12 -> 382.3652 | Z7: =+Y7*1.12 -> 428.24903 | AA7: =+Z7*1.08 -> 462.50895 | AB7: =+AA7*1.05 -> 485.6344 | AC7: =+AB7*1.05 -> 509.91612 | AD7: =+AC7*1.05 -> 535.41192 | AE7: =+AD7*1.05 -> 562.18252 | AF7: =+AE7*1.05 -> 590.29165 | AG7: =+AF7*1.05 -> 619.80623
A8: Rocket | B8: Lab addresses | U8: =+U7/U3 -> 0.02980498 | V8: =+V7/V3 -> 0.031550174 | W8: =+W7/W3 -> 0.033385979 | X8: =+(X7+X6+Model!X5)/Model!X3 -> 0.93024049 | Y8: =+(Y7+Y6+Model!Y5)/Model!Y3 -> 0.9262364 | Z8: =+(Z7+Z6+Model!Z5)/Model!Z3 -> 0.92203366 | AA8: =+(AA7+AA6+Model!AA5)/Model!AA3 -> 0.91553801 | AB8: =+(AB7+AB6+Model!AB5)/Model!AB3 -> 0.91353126 | AC8: =+(AC7+AC6+Model!AC5)/Model!AC3 -> 0.91132368 | AD8: =+(AD7+AD6+Model!AD5)/Model!AD3 -> 0.90906849 | AE8: =+(AE7+AE6+Model!AE5)/Model!AE3 -> 0.90676511 | ... AG8: =+(AG7+AG6+Model!AG5)/Model!AG3 -> 0.90201157
A9: S | B9: Electron Market Share | U9: =+U21/U7 -> 0.25 | V9: =+V21/V7 -> 0.26415344 | W9: =+W21/W7 -> 0.54130448 | X9: =+X21/X7 -> 0.56239427 | Y9: =+Y21/Y7 -> 0.65905579 | Z9: =+Z21/Z7 -> 0.63047428 | AA9: =+AA21/AA7 -> 0.65728458 | AB9: =+AB21/AB7 -> 0.72070677 | ... AG9: =+AG21/AG7 -> 0.56469261
A10: M-H | B10: Neutron Market Share | U10: =+U28/SUM(U5:U6) -> 0 | V10: =+V28/SUM(V5:V6) -> 0 | W10: =+W28/SUM(W5:W6) -> 0 | X10: =+X28/SUM(X5:X6) -> 0.0057795181 | Y10: =+Y28/SUM(Y5:Y6) -> 0.017469326 | Z10: =+Z28/SUM(Z5:Z6) -> 0.034462276 | AA10: =+AA28/SUM(AA5:AA6) -> 0.061688437 | AB10: =+AB28/SUM(AB5:AB6) -> 0.087786049 | ... AG10: =+AG28/SUM(AG5:AG6) -> 0.15902106
B11: Total Market Share | U11: =+U36/(U3*1000) -> 0.0074512449 | V11: =+V36/(V3*1000) -> 0.0083340868 | W11: =+W36/(W3*1000) -> 0.01807198 | X11: =+X36/(X3*1000) -> 0.025033611 | Y11: =+Y36/(Y3*1000) -> 0.040139376 | Z11: =+Z36/(Z3*1000) -> 0.055300247 | AA11: =+AA36/(AA3*1000) -> 0.081035598 | AB11: =+AB36/(AB3*1000) -> 0.10691178 | ... AG11: =+AG36/(AG3*1000) -> 0.16284412
B12: SpaceX Market Share | U12: =3250/U3 -> 0.39862627
B14: Backlog | T14: 241 | U14: 503.6
A15: E | B15: Orbit Missions | Q15: 3 | R15: 6 | S15: 6 | T15: 5 | U15: 9
B16: Spacecraft Deployed | U16: 152
B18: Electron:
B19: Launches | C19: 1 | D19: 2 | E19: 3 | F19: 2 | G19: 3 | H19: 5 | I19: 3 | J19: 8 | Q19: 3 | R19: 6 | S19: 6 | T19: 6 | U19: 9 | V19: 10 | W19: 22 | X19: 24 | Y19: 28 | Z19: 30 | AA19: 32 | AB19: 35 | AC19: 35 | AD19: 35 | AE19: 35 | AF19: 35 | AG19: 35
B20: Revenue per Launch | C20: 6.5 | D20: 6.5 | E20: 6.5 | F20: 6.5 | G20: 6.535 | H20: 7.5 | I20: 7.5 | J20: 7.5 | T20: 6.5 | U20: 6.75 | V20: =+V21/V19 -> 7.1892 | W20: 7.5 | X20: 8 | Y20: 9 | Z20: 9 | AA20: 9.5 | AB20: 10 | AC20: 10 | AD20: 10 | AE20: 10 | AF20: 10 | AG20: 10
B21: Total Revenue | C21: =+C19*C20 -> 6.5 | D21: =+D19*D20 -> 13 | E21: =+E19*E20 -> 19.5 | F21: =+F19*F20 -> 13 | G21: =+G19*G20 -> 19.605 | H21: =+H19*H20 -> 37.5 | I21: =+I19*I20 -> 22.5 | J21: =+J19*J20 -> 60 | T21: =+T19*T20 -> 39 | U21: =+U19*U20 -> 60.75 | V21: =+V36/1000 -> 71.892 | W21: =+W19*W20 -> 165 | X21: =+X19*X20 -> 192 | Y21: =+Y19*Y20 -> 252 | Z21: =+Z19*Z20 -> 270 | AA21: =+AA19*AA20 -> 304 | AB21: =+AB19*AB20 -> 350 | AC21: =+AC19*AC20 -> 350 | AD21: =+AD19*AD20 -> 350 | ... AG21: =+AG19*AG20 -> 350
B22: Gross Margin | V22: 0 | W22: 0.3 | X22: 0.4 | Y22: 0.5 | Z22: 0.52 | AA22: 0.54 | AB22: 0.55 | AC22: 0.55 | AD22: 0.55 | AE22: 0.55 | AF22: 0.55 | AG22: 0.55
B23: Gross Profit | V23: =+V21*V22 -> 0 | W23: =+W21*W22 -> 49.5 | X23: =+X21*X22 -> 76.8 | Y23: =+Y21*Y22 -> 126 | Z23: =+Z21*Z22 -> 140.4 | AA23: =+AA21*AA22 -> 164.16 | AB23: =+AB21*AB22 -> 192.5 | AC23: =+AC21*AC22 -> 192.5 | ... AG23: =+AG21*AG22 -> 192.5
B25: Neutron:
B26: Launches | W26: 0 | X26: 1 | Y26: 3 | Z26: 6 | AA26: 11 | AB26: 16 | AC26: 22 | AD26: 25 | AE26: 27 | AF26: 30 | AG26: 32
B27: Revenue per Launch | W27: 50 | X27: 50 | Y27: 53 | Z27: 55 | AA27: 55 | AB27: 55 | AC27: 55 | AD27: 55 | AE27: 55 | AF27: 55 | AG27: 55
B28: Total Revenue | W28: =+W26*W27 -> 0 | X28: =+X26*X27 -> 50 | Y28: =+Y26*Y27 -> 159 | Z28: =+Z26*Z27 -> 330 | AA28: =+AA26*AA27 -> 605 | AB28: =+AB26*AB27 -> 880 | AC28: =+AC26*AC27 -> 1210 | AD28: =+AD26*AD27 -> 1375 | ... AG28: =+AG26*AG27 -> 1760
B29: Gross Margin | W29: -0.5 | X29: -0.25 | Y29: 0.1 | Z29: 0.175 | AA29: 0.25 | AB29: 0.3 | AC29: 0.35 | AD29: 0.4 | AE29: 0.4 | AF29: 0.4 | AG29: 0.4
B30: Gross Profit | W30: =+W28*W29 -> 0 | X30: =+X28*X29 -> -12.5 | Y30: =+Y28*Y29 -> 15.9 | Z30: =+Z28*Z29 -> 57.75 | AA30: =+AA28*AA29 -> 151.25 | AB30: =+AB28*AB29 -> 264 | AC30: =+AC28*AC29 -> 423.5 | AD30: =+AD28*AD29 -> 550 | ... AG30: =+AG28*AG29 -> 704
B32: Space System Rev. | T32: 23.3 | U32: 150.3 | V32: 174.6 | W32: 218 | X32: 350 | Y32: 501 | Z32: 656 | AA32: =+Z32*1.2 -> 787.2 | AB32: =+AA32*1.2 -> 944.64 | AC32: =+AB32*1.2 -> 1133.568 | AD32: =+AC32*1.15 -> 1303.6032 | AE32: =+AD32*1.15 -> 1499.1437 | AF32: =+AE32*1.15 -> 1724.0152 | AG32: =+AF32*1.15 -> 1982.6175
B33: Gross Marign | U33: 0.2 | V33: =+V34/V32 -> 0.29443872 | W33: 0.35 | X33: 0.4 | Y33: 0.43 | Z33: 0.45 | AA33: 0.45 | AB33: 0.5 | AC33: 0.5 | AD33: 0.5 | AE33: 0.5 | AF33: 0.5 | AG33: 0.5
B34: Gross Profit | U34: =+U32*U33 -> 30.06 | V34: =+V40/1000 -> 51.409 | W34: =+W32*W33 -> 76.3 | X34: =+X32*X33 -> 140 | Y34: =+Y32*Y33 -> 215.43 | Z34: =+Z32*Z33 -> 295.2 | AA34: =+AA32*AA33 -> 354.24 | AB34: =+AB32*AB33 -> 472.32 | AC34: =+AC32*AC33 -> 566.784 | AD34: =+AD32*AD33 -> 651.8016 | ... AG34: =+AG32*AG33 -> 991.30876
B36: Launch Revenue | C36: =+C21*1000 -> 6500 | D36: =+D21*1000 -> 13000 | E36: =+E21*1000 -> 19500 | F36: =+F21*1000 -> 13000 | G36: =+G21*1000 -> 19605 | H36: =+H21*1000 -> 37500 | I36: =+I21*1000 -> 22500 | T36: =+T21*1000 -> 39000 | U36: =+U21*1000 -> 60750 | V36: =+V38-V37 -> 71892 | W36: =+(W21+W28)*1000 -> 165000 | X36: =+(X21+X28)*1000 -> 242000 | Y36: =+(Y21+Y28)*1000 -> 411000 | Z36: =+(Z21+Z28)*1000 -> 600000 | AA36: =+(AA21+AA28)*1000 -> 909000 | AB36: =+(AB21+AB28)*1000 -> 1230000 | AC36: =+(AC21+AC28)*1000 -> 1560000 | AD36: =+(AD21+AD28)*1000 -> 1725000 | ... AG36: =+(AG21+AG28)*1000 -> 2110000
B37: Space System Rev. | C37: =+C38-C36 -> 34203 | D37: =+D38-D36 -> 42474 | E37: =+E38-E36 -> 43557 | F37: =+F38-F36 -> 38762 | G37: =+G38-G36 -> 35290 | H37: 23000 | I37: =+I38-I36 -> 45161 | T37: =+T32*1000 -> 23300 | U37: =+U32*1000 -> 150300 | V37: 172700 | W37: =+W32*1000 -> 218000 | X37: =+X32*1000 -> 350000 | Y37: =+Y32*1000 -> 501000 | Z37: =+Z32*1000 -> 656000 | AA37: =+AA32*1000 -> 787200 | AB37: =+AB32*1000 -> 944640 | AC37: =+AC32*1000 -> 1133568 | AD37: =+AD32*1000 -> 1303603.2 | ... AG37: =+AG32*1000 -> 1982617.5
B38: Revenue | C38: 40703 | D38: 55474 | E38: 63057 | F38: =+U38-E38-D38-C38 -> 51762 | G38: 54895 | H38: 62045 | I38: 67661 | J38: 59991 | K38: 92767 | L38: 106251 | M38: =+L38+10000 -> 116251 | N38: =+M38+10000 -> 126251 | S38: 35160 | T38: 62237 | U38: 210996 | V38: =+SUM(G38:J38) -> 244592 | W38: =+SUM(K38:N38) -> 441520 | X38: =+(X36+X37) -> 592000 | Y38: =+(Y36+Y37) -> 912000 | Z38: =+(Z36+Z37) -> 1256000 | AA38: =+(AA36+AA37) -> 1696200 | AB38: =+(AB36+AB37) -> 2174640 | AC38: =+(AC36+AC37) -> 2693568 | AD38: =+(AD36+AD37) -> 3028603.2 | AE38: =+(AE36+AE37) -> 3334143.7 | ... AG38: =+(AG36+AG37) -> 4092617.5
B39: COGS | C39: 36968 | D39: 50516 | E39: 54590 | F39: =+U39-E39-D39-C39 -> 49932 | G39: 48538 | H39: 47452 | I39: 52694 | J39: 44499 | K39: 68593 | L39: 79089 | M39: =+M38*0.74 -> 86025.74 | N39: =+N38*0.74 -> 93425.74 | S39: 46977 | T39: 64130 | U39: 192006 | V39: =+SUM(G39:J39) -> 193183 | W39: =+SUM(K39:N39) -> 327133.48 | X39: =+X38-X40 -> 387700 | Y39: =+Y38-Y40 -> 554670 | Z39: =+Z38-Z40 -> 762650 | AA39: =+AA38-AA40 -> 1026550 | AB39: =+AB38-AB40 -> 1245820 | AC39: =+AC38-AC40 -> 1510784 | AD39: =+AD38-AD40 -> 1634301.6 | AE39: =+AE38-AE40 -> 1798071.8 | ... AG39: =+AG38-AG40 -> 2204808.8
B40: Gross Profit | C40: =+C38-C39 -> 3735 | D40: =+D38-D39 -> 4958 | E40: =+E38-E39 -> 8467 | F40: =+U40-E40-D40-C40 -> 1830 | G40: =+G38-G39 -> 6357 | H40: =+H38-H39 -> 14593 | I40: =+I38-I39 -> 14967 | J40: =+J38-J39 -> 15492 | K40: =+K38-K39 -> 24174 | L40: =+L38-L39 -> 27162 | M40: =+M38-M39 -> 30225.26 | N40: =+N38-N39 -> 32825.26 | S40: =+S38-S39 -> -11817 | T40: =+T38-T39 -> -1893 | U40: =+U38-U39 -> 18990 | V40: =+V38-V39 -> 51409 | W40: =+W38-W39 -> 114386.52 | X40: =+(X34+X30+X23)*1000 -> 204300 | Y40: =+(Y34+Y30+Y23)*1000 -> 357330 | Z40: =+(Z34+Z30+Z23)*1000 -> 493350 | AA40: =+(AA34+AA30+AA23)*1000 -> 669650 | AB40: =+(AB34+AB30+AB23)*1000 -> 928820 | AC40: =+(AC34+AC30+AC23)*1000 -> 1182784 | AD40: =+(AD34+AD30+AD23)*1000 -> 1394301.6 | AE40: =+(AE34+AE30+AE23)*1000 -> 1536071.8 | ... AG40: =+(AG34+AG30+AG23)*1000 -> 1887808.8
B41: R&D | C41: 13477 | D41: 19165 | E41: 17508 | F41: =+U41-E41-D41-C41 -> 15018 | G41: 23905 | H41: 31035 | I41: 26626 | J41: 37488 | K41: 38504 | L41: 39912 | M41: =+L41+1000 -> 40912 | N41: =+M41+1000 -> 41912 | S41: 19142 | T41: 41765 | U41: 65168 | V41: =+SUM(G41:J41) -> 119054 | W41: =+SUM(K41:N41) -> 161240 | X41: =+W41*1.08 -> 174139.2 | Y41: =+X41*1.08 -> 188070.34 | Z41: =+Y41*1.1 -> 206877.37 | AA41: =+Z41*1.12 -> 231702.65 | AB41: =+AA41*1.12 -> 259506.97 | AC41: =+AB41*1.12 -> 290647.81 | AD41: =+AC41*1.12 -> 325525.55 | AE41: =+AD41*1.12 -> 364588.61 | AF41: =+AE41*1.12 -> 408339.25 | AG41: =+AF41*1.12 -> 457339.95
B42: SG&A | C42: 23078 | D42: 18952 | E42: 22961 | F42: =+U42-E42-D42-C42 -> 24035 | G42: 28469 | H42: 28717 | I42: 27200 | J42: 25887 | K42: 28749 | L42: 30524 | M42: =+L42+1500 -> 32024 | N42: =+M42+1500 -> 33524 | S42: 23993 | T42: 58395 | U42: 89026 | V42: =+SUM(G42:J42) -> 110273 | W42: =+SUM(K42:N42) -> 124821 | X42: =+W42*1.04 -> 129813.84 | Y42: =+X42*1.06 -> 137602.67 | Z42: =+Y42*1.06 -> 145858.83 | AA42: =+Z42*1.06 -> 154610.36 | AB42: =+AA42*1.06 -> 163886.98 | AC42: =+AB42*1.06 -> 173720.2 | AD42: =+AC42*1.06 -> 184143.41 | AE42: =+AD42*1.06 -> 195192.02 | AF42: =+AE42*1.06 -> 206903.54 | AG42: =+AF42*1.06 -> 219317.75
B43: Operating Expenses | C43: =+C41+C42 -> 36555 | D43: =+D41+D42 -> 38117 | E43: =+E41+E42 -> 40469 | F43: =+U43-E43-D43-C43 -> 39053 | G43: =+G41+G42 -> 52374 | H43: =+H41+H42 -> 59752 | I43: =+I41+I42 -> 53826 | J43: =+J41+J42 -> 63375 | K43: =+K41+K42 -> 67253 | L43: =+L41+L42 -> 70436 | M43: =+M41+M42 -> 72936 | N43: =+N41+N42 -> 75436 | S43: =+S41+S42 -> 43135 | T43: =+T41+T42 -> 100160 | U43: =+U41+U42 -> 154194 | V43: =+V41+V42 -> 229327 | W43: =+W41+W42 -> 286061 | X43: =+X41+X42 -> 303953.04 | Y43: =+Y41+Y42 -> 325673.01 | Z43: =+Z41+Z42 -> 352736.2 | ... AG43: =+AG41+AG42 -> 676657.71
B44: Operating Income | C44: =+C40-C43 -> -32820 | D44: =+D40-D43 -> -33159 | E44: =+E40-E43 -> -32002 | F44: =+U44-E44-D44-C44 -> -37223 | G44: =+G40-G43 -> -46017 | H44: =+H40-H43 -> -45159 | I44: =+I40-I43 -> -38859 | J44: =+J40-J43 -> -47883 | K44: =+K40-K43 -> -43079 | L44: =+L40-L43 -> -43274 | M44: =+M40-M43 -> -42710.74 | N44: =+N40-N43 -> -42610.74 | S44: =+S40-S43 -> -54952 | T44: =+T40-T43 -> -102053 | U44: =+U40-U43 -> -135204 | V44: =+V40-V43 -> -177918 | W44: =+W40-W43 -> -171674.48 | X44: =+X40-X43 -> -99653.04 | Y44: =+Y40-Y43 -> 31656.994 | Z44: =+Z40-Z43 -> 140613.8 | ... AG44: =+AG40-AG43 -> 1211151.1
B45: Interest | C45: 2989 | D45: 2432 | E45: 1486 | F45: =+U45-E45-D45-C45 -> 892 | G45: 685 | H45: 745 | I45: 1413 | J45: 1405 | K45: 898 | L45: 824 | M45: 900 | N45: 900 | S45: -224 | T45: 6128 | U45: 7799 | V45: =+SUM(G45:J45) -> 4248 | W45: =+SUM(K45:N45) -> 3522 | X45: =+X69*0.08 -> 10000 | Y45: =+Y69*0.08 -> 14400 | Z45: =+Y45*0.95 -> 13680 | AA45: =+Z45*0.95 -> 12996 | AB45: =+AA45*0.95 -> 12346.2 | AC45: =+AB45*0.95 -> 11728.89 | AD45: =+AC45*0.95 -> 11142.445 | AE45: =+AD45*0.95 -> 10585.323 | AF45: =+AE45*0.95 -> 10056.057 | AG45: =+AF45*0.95 -> 9553.2542
...
