Workbook
Name TR: Model!$W$43

Sheet Main
B3: AMS Company Portfolio: | E3: Oilfield Equipment Company Portfolio:
B5: NON-MAGNETIC STEELS | C5: Manufacture of high-alloy, non-magnetic steels offering high material | E5: HIGH-PERFORMANCE DRILLING MOTORS | F5: Cutting-edge drilling motors with high torques for directional and horizontal
C6: strength and corrosion resistance | F6: drilling
B8: HIGH-PRECISION COMPONENTS | C8: High-precision manufacture of customized components from | E8: CIRCULATION TOOLS | F8: Circulation tools for sealing liquid-permeable zones and hole cleaning
C9: non-magnetic, corrosion resistant steels and other high-performing | F9: during the drilling process
C10: alloy steels
E11: ROTARY STEERABLE TOOLS | F11: Tools for intelligent drillstring steering in directional drilling with real-time
B12: ADVANCED ADDITIVE MANUFACTURING | C12: Manufacture of complex metal parts using Direct Metal Laser Sintering | F12: integration capabilities
C13: (DMLS)
E14: WELL COMPLETION SOLUTIONS | F14: High-efficiency products and applications like: core completion equipment,
B15: HIGH-TECH SERVICE AND REPAIR | C15: Repair and mechanical processing of existing components using | F15: frac plugs & systems, toe initiation tools, packer products, artificial lift
C16: state-of-the-art methods to extend product life and contribute to | F16: equipment
C17: circular economy
B20: Driver: | C20: installed base utilization | E20: Driver: | F20: new wells drilled
B21: Translation: | C21: production activity & wear-and-tear | E21: Translation: | F21: oilfield service capex cycle
B22: Basic: | C22: maintenance of rigs | E22: Basic: | F22: construction of rigs

Sheet Model
C2: 2018 | D2: =+C2+1 -> 2019 | E2: =+D2+1 -> 2020 | F2: =+E2+1 -> 2021 | G2: =+F2+1 -> 2022 | H2: =+G2+1 -> 2023 | I2: =+H2+1 -> 2024 | J2: =+I2+1 -> 2025 | K2: =+J2+1 -> 2026 | ... T2: =+S2+1 -> 2035
B4: WTI Crude | I4: 75 | J4: 70 | K4: =+J4*1.03 -> 72.1 | L4: =+K4*1.03 -> 74.263 | M4: =+L4*1.03 -> 76.49089 | N4: =+M4*1.03 -> 78.785617 | O4: 80 | P4: 80 | Q4: 80 | R4: 80 | S4: 80 | T4: 80
B5: Brent Crude | J5: 67.75
B7: Rig Count | C7: 1020 | D7: 1002 | E7: 773 | F7: 825 | G7: 768 | H7: 828 | I7: 811 | J7: =+I7+Factors!$C$4*(Factors!$C$3-Model!I7)+Factors!$C$5*((Model!J4/Model!I4) -1)*Model!I7 -> 763.89667 | K7: =+J7+Factors!$C$4*(Factors!$C$3-Model!J7)+Factors!$C$5*((Model!K4/Model!J4) -1)*Model!J7 -> 794.86635 | L7: =+K7+Factors!$C$4*(Factors!$C$3-Model!K7)+Factors!$C$5*((Model!L4/Model!K4) -1)*Model!K7 -> 815.73992 | M7: =+L7+Factors!$C$4*(Factors!$C$3-Model!L7)+Factors!$C$5*((Model!M4/Model!L4) -1)*Model!L7 -> 829.80871 | N7: =+M7+Factors!$C$4*(Factors!$C$3-Model!M7)+Factors!$C$5*((Model!N4/Model!M4) -1)*Model!M7 -> 839.29107 | O7: =+N7+Factors!$C$4*(Factors!$C$3-Model!N7)+Factors!$C$5*((Model!O4/Model!N4) -1)*Model!N7 -> 835.88851 | P7: =+O7+Factors!$C$4*(Factors!$C$3-Model!O7)+Factors!$C$5*((Model!P4/Model!O4) -1)*Model!O7 -> 823.32753 | Q7: =+P7+Factors!$C$4*(Factors!$C$3-Model!P7)+Factors!$C$5*((Model!Q4/Model!P4) -1)*Model!P7 -> 815.16289 | ... T7: =+S7+Factors!$C$4*(Factors!$C$3-Model!S7)+Factors!$C$5*((Model!T4/Model!S4) -1)*Model!S7 -> 804.16411
B8: Rev/Rig | C8: =+C16/C7 -> 243.82353 | D8: =+D16/D7 -> 221.05788 | E8: =+E16/E7 -> 170.11643 | F8: =+F16/F7 -> 183.51515 | G8: =+G16/G7 -> 328.90625 | H8: =+H16/H7 -> 310.62802 | I8: =+I16/I7 -> 339.28113 | J8: =+I8*(1+Factors!$C$7)*(1+Factors!$C$8*((Model!J4/Factors!$C$6)-1)) -> 320.11175 | K8: =+J8*(1+Factors!$C$7)*(1+Factors!$C$8*((Model!K4/Factors!$C$6)-1)) -> 307.16803 | L8: =+K8*(1+Factors!$C$7)*(1+Factors!$C$8*((Model!L4/Factors!$C$6)-1)) -> 299.83039 | M8: =+L8*(1+Factors!$C$7)*(1+Factors!$C$8*((Model!M4/Factors!$C$6)-1)) -> 297.77814 | N8: =+M8*(1+Factors!$C$7)*(1+Factors!$C$8*((Model!N4/Factors!$C$6)-1)) -> 300.96733 | O8: =+N8*(1+Factors!$C$7)*(1+Factors!$C$8*((Model!O4/Factors!$C$6)-1)) -> 306.98668 | P8: =+O8*(1+Factors!$C$7)*(1+Factors!$C$8*((Model!P4/Factors!$C$6)-1)) -> 313.12641 | Q8: =+P8*(1+Factors!$C$7)*(1+Factors!$C$8*((Model!Q4/Factors!$C$6)-1)) -> 319.38894 | ... T8: =+S8*(1+Factors!$C$7)*(1+Factors!$C$8*((Model!T4/Factors!$C$6)-1)) -> 338.9381
B11: AMS | C11: 171500 | D11: 223800 | E11: 159700 | F11: 141400 | G11: 248700 | H11: 328700 | I11: 285289 | J11: =+I11*1.05 -> 299553.45 | K11: =+J11*1.05 -> 314531.12 | L11: =+K11*1.05 -> 330257.68 | M11: =+L11*1.05 -> 346770.56 | N11: =+M11*1.05 -> 364109.09 | O11: =+N11*1.05 -> 382314.55 | P11: =+O11*1.05 -> 401430.27 | Q11: =+P11*1.05 -> 421501.79 | ... T11: =+S11*1.05 -> 487941.01
B12: Product Sales | G12: 225932 | H12: 305072 | I12: 264812
B13: Service & Repair | G13: 16362 | H13: 18432 | I13: 15874
B14: Rental Revenue | G14: 6378 | H14: 5183 | I14: 4063
B16: Oilfield Equipment | C16: 248700 | D16: 221500 | E16: 131500 | F16: 151400 | G16: 252600 | H16: 257200 | I16: 275157 | J16: =+J8*J7 -> 244532.3 | K16: =+K8*K7 -> 244157.53 | L16: =+L8*L7 -> 244583.62 | M16: =+M8*M7 -> 247098.89 | N16: =+N8*N7 -> 252599.2 | O16: =+O8*O7 -> 256606.64 | P16: =+P8*P7 -> 257805.6 | Q16: =+Q8*Q7 -> 260354.01 | ... T16: =+T8*T7 -> 272561.86
B17: Product Sales | G17: 114839 | H17: 123391 | I17: 154698
B18: Service & Repair | G18: 7190 | H18: 5409 | I18: 7946
B19: Rental Revenue | G19: 130538 | H19: 128384 | I19: 112513
B21: Product Sales | G21: =+G17+G12 -> 340771 | H21: =+H17+H12 -> 428463 | I21: 419510
B22: Service & Repair | G22: =+G18+G13 -> 23552 | H22: =+H18+H13 -> 23841 | I22: 23820
B23: Rental Revenue | G23: =+G19+G14 -> 136916 | H23: =+H19+H14 -> 133567 | I23: 117116
B24: Revenue | C24: 420210 | D24: 445256 | E24: 291159 | F24: 292811 | G24: 501239 | H24: 585871 | I24: 560446 | J24: =+J11+J16 -> 544085.75 | K24: =+K11+K16 -> 558688.66 | L24: =+L11+L16 -> 574841.29 | M24: =+M11+M16 -> 593869.46 | N24: =+N11+N16 -> 616708.29 | O24: =+O11+O16 -> 638921.18 | P24: =+P11+P16 -> 659235.87 | Q24: =+Q11+Q16 -> 681855.8 | ... T24: =+T11+T16 -> 760502.86
B25: COGS | C25: 274608 | D25: 312690 | E25: 225086 | F25: 216847 | G25: 332384 | H25: 383272 | I25: 390145 | J25: =+J24*(1-J40) -> 380860.02 | K25: =+K24*(1-K40) -> 391082.06 | L25: =+L24*(1-L40) -> 402388.91 | M25: =+M24*(1-M40) -> 415708.62 | N25: =+N24*(1-N40) -> 431695.8 | O25: =+O24*(1-O40) -> 447244.83 | P25: =+P24*(1-P40) -> 461465.11 | Q25: =+Q24*(1-Q40) -> 477299.06 | ... T25: =+T24*(1-T40) -> 532352
B26: Gross Profit | C26: =+C24-C25 -> 145602 | D26: =+D24-D25 -> 132566 | E26: =+E24-E25 -> 66073 | F26: =+F24-F25 -> 75964 | G26: =+G24-G25 -> 168855 | H26: =+H24-H25 -> 202599 | I26: =+I24-I25 -> 170301 | J26: =+J24-J25 -> 163225.72 | ... T26: =+T24-T25 -> 228150.86
B27: Selling | C27: 23864 | D27: 27493 | E27: 21112 | F27: 21368 | G27: 31339 | H27: 36357 | I27: 39226 | J27: =28578*1.33 -> 38008.74 | K27: =+K24*0.072 -> 40225.583 | L27: =+L24*0.072 -> 41388.573 | M27: =+M24*0.072 -> 42758.601 | N27: =+N24*0.072 -> 44402.997 | O27: =+O24*0.072 -> 46002.325 | P27: =+P24*0.072 -> 47464.983 | Q27: =+Q24*0.072 -> 49093.618 | R27: =+R24*0.072 -> 50861.453 | ... T27: =+T24*0.072 -> 54756.206
B28: G&A | C28: 46123 | D28: 39821 | E28: 38817 | F28: 31306 | G28: 42544 | H28: 49646 | I28: 49059 | J28: =35000*1.33 -> 46550 | K28: =+K24*0.088 -> 49164.602 | L28: =+L24*0.088 -> 50586.034 | M28: =+M24*0.088 -> 52260.512 | N28: =+N24*0.088 -> 54270.329 | O28: =+O24*0.088 -> 56225.064 | P28: =+P24*0.088 -> 58012.757 | Q28: =+Q24*0.088 -> 60003.31 | R28: =+R24*0.088 -> 62163.998 | ... T28: =+T24*0.088 -> 66924.252
B29: R&D | H29: 8243 | I29: 10481 | J29: =+J24*0.02 -> 10881.715 | K29: =+K24*0.02 -> 11173.773 | L29: =+L24*0.02 -> 11496.826 | M29: =+M24*0.02 -> 11877.389 | N29: =+N24*0.02 -> 12334.166 | O29: =+O24*0.02 -> 12778.424 | P29: =+P24*0.02 -> 13184.717 | Q29: =+Q24*0.02 -> 13637.116 | ... T29: =+T24*0.02 -> 15210.057
B30: Othern, net | C30: =-16818+15760 -> -1058 | D30: =-12915+8507 -> -4408 | E30: =-18226+6454 -> -11772 | F30: =-10284+15204 -> 4920 | G30: =-15357+16565 -> 1208 | H30: =-22395+8077+H29 -> -6075 | I30: =-25470+13540+I29 -> -1449 | J30: =-21122*1.33+14079*1.33+J29 -> 1514.525 | K30: =-10000+K29 -> 1173.7731 | L30: =-10000+L29 -> 1496.8259 | M30: =-10000+M29 -> 1877.3891 | N30: =-10000+N29 -> 2334.1657 | O30: =-10000+O29 -> 2778.4237 | P30: =-10000+P29 -> 3184.7174 | Q30: =-10000+Q29 -> 3637.116 | R30: =-10000+R29 -> 4128.1814 | ... T30: =-10000+T29 -> 5210.0572
B31: Operating Income | C31: =+C26-C27-C28+C30 -> 74557 | D31: =+D26-D27-D28+D30 -> 60844 | E31: =+E26-E27-E28+E30 -> -5628 | F31: =+F26-F27-F28+F30 -> 28210 | G31: =+G26-G27-G28+G30 -> 96180 | H31: =+H26-H27-H28+H30-H29 -> 102278 | I31: =+I26-I27-I28+I30-I29 -> 70086 | J31: =+J26-J27-J28+J30 -> 80181.51 | K31: =+K26-K27-K28+K30 -> 79390.185 | L31: =+L26-L27-L28+L30 -> 81974.607 | M31: =+M26-M27-M28+M30 -> 85019.113 | N31: =+N26-N27-N28+N30 -> 88673.326 | O31: =+O26-O27-O28+O30 -> 92227.389 | P31: =+P26-P27-P28+P30 -> 95477.739 | Q31: =+Q26-Q27-Q28+Q30 -> 99096.928 | ... T31: =+T26-T27-T28+T30 -> 111680.46
B32: Interest Income | C32: 2900 | D32: 3598 | E32: 1574 | F32: 441 | G32: 2854 | H32: 9038 | I32: 5705 | J32: =6515*1.33 -> 8664.95 | K32: =+J32*0.85 -> 7365.2075 | L32: =+K32*0.85 -> 6260.4264 | M32: =+L32*0.85 -> 5321.3624 | N32: =+M32*0.85 -> 4523.1581 | O32: =+N32*0.85 -> 3844.6843 | P32: =+O32*0.85 -> 3267.9817 | Q32: =+P32*0.85 -> 2777.7844 | R32: =+Q32*0.85 -> 2361.1168 | ... T32: =+S32*0.85 -> 1705.9069
B33: Interest Expenses | C33: 11401 | D33: 8699 | E33: 4823 | F33: 5374 | G33: 5692 | H33: 8544 | I33: 12204 | J33: =10907*1.33 -> 14506.31 | K33: =+J33*0.98 -> 14216.184 | L33: =+K33*0.98 -> 13931.86 | M33: =+L33*0.98 -> 13653.223 | N33: =+M33*0.98 -> 13380.158 | O33: =+N33*0.98 -> 13112.555 | P33: =+O33*0.98 -> 12850.304 | Q33: =+P33*0.98 -> 12593.298 | R33: =+Q33*0.98 -> 12341.432 | ... T33: =+S33*0.98 -> 11852.711
B34: Pretax | C34: =+C31+C32-C33 -> 66056 | D34: =+D31+D32-D33 -> 55743 | E34: =+E31+E32-E33 -> -8877 | F34: =+F31+F32-F33 -> 23277 | G34: =+G31+G32-G33 -> 93342 | H34: =+H31+H32-H33 -> 102772 | I34: =+I31+I32-I33 -> 63587 | J34: =+J31+J32-J33 -> 74340.15 | ... T34: =+T31+T32-T33 -> 101533.65
B35: Taxes | C35: 14500 | D35: 15560 | E35: -9496 | F35: 2412 | G35: 18144 | H35: 22635 | I35: 18292 | J35: =+J34*0.23 -> 17098.234 | K35: =+K34*0.23 -> 16684.018 | L35: =+L34*0.23 -> 17089.73 | M35: =+M34*0.23 -> 17638.068 | N35: =+N34*0.23 -> 18357.755 | O35: =+O34*0.23 -> 19080.689 | P35: =+P34*0.23 -> 19755.946 | Q35: =+Q34*0.23 -> 20534.725 | ... T35: =+T34*0.23 -> 23352.74
B36: Net Income | C36: =+C34-C35 -> 51556 | D36: =+D34-D35 -> 40183 | E36: =+E34-E35 -> 619 | F36: =+F34-F35 -> 20865 | G36: =+G34-G35 -> 75198 | H36: =+H34-H35 -> 80137 | I36: =+I34-I35 -> 45295 | J36: =+J34-J35 -> 57241.915 | ... T36: =+T34-T35 -> 78180.913
B37: EPS | H37: =+H36/H38 -> 5.0938809 | I37: =+I36/I38 -> 2.8741458 | J37: =+J36/J38 -> 3.6322245 | K37: =+K36/K38 -> 3.5442314 | L37: =+L36/L38 -> 3.6304179 | M37: =+M36/M38 -> 3.7469029 | N37: =+N36/N38 -> 3.8997879 | O37: =+O36/O38 -> 4.0533628 | ... T37: =+T36/T38 -> 4.9608862
B38: Shares | H38: 15732.013 | I38: 15759.465 | J38: =+I38+0 -> 15759.465 | K38: =+J38+0 -> 15759.465 | L38: =+K38+0 -> 15759.465 | M38: =+L38+0 -> 15759.465 | N38: =+M38+0 -> 15759.465 | O38: =+N38+0 -> 15759.465 | P38: =+O38+0 -> 15759.465 | Q38: =+P38+0 -> 15759.465 | ... T38: =+S38+0 -> 15759.465
B40: Gross Margin | C40: =+C26/C24 -> 0.34649818 | D40: =+D26/D24 -> 0.29772985 | E40: =+E26/E24 -> 0.22693099 | F40: =+F26/F24 -> 0.25943014 | G40: =+G26/G24 -> 0.33687522 | H40: =+H26/H24 -> 0.34580821 | I40: =+I26/I24 -> 0.30386692 | J40: 0.3 | K40: 0.3 | L40: 0.3 | M40: 0.3 | N40: 0.3 | O40: 0.3 | P40: 0.3 | Q40: 0.3 | R40: 0.3 | S40: 0.3 | T40: 0.3
B41: Net Margin | C41: =+C36/C24 -> 0.12269104 | D41: =+D36/D24 -> 0.090246959 | E41: =+E36/E24 -> 0.0021259861 | F41: =+F36/F24 -> 0.071257569 | G41: =+G36/G24 -> 0.15002424 | H41: =+H36/H24 -> 0.13678267 | I41: =+I36/I24 -> 0.080819562 | J41: =+J36/J24 -> 0.10520753 | ... T41: =+T36/T24 -> 0.1028016
B42: Revenue Y/Y | D42: =+D24/C24 -1 -> 0.059603532 | E42: =+E24/D24 -1 -> -0.3460863 | F42: =+F24/E24 -1 -> 0.0056738758 | G42: =+G24/F24 -1 -> 0.71181752 | H42: =+H24/G24 -1 -> 0.1688456 | I42: =+I24/H24 -1 -> -0.043396925 | J42: =+J24/I24 -1 -> -0.029191485 | K42: =+K24/J24 -1 -> 0.026839348 | ... T42: =+T24/S24 -1 -> 0.037990679 | V42: Discount | W42: 0.1
B43: AMS Sales Y/Y | D43: =+D11/C11 -1 -> 0.30495627 | E43: =+E11/D11 -1 -> -0.28641644 | F43: =+F11/E11 -1 -> -0.11458986 | G43: =+G11/F11 -1 -> 0.75884017 | H43: =+H11/G11 -1 -> 0.3216727 | I43: =+I11/H11 -1 -> -0.13206876 | V43: Terminal | W43: 0.01
B44: OE Sales Y/Y | D44: =+D16/C16 -1 -> -0.10936872 | E44: =+E16/D16 -1 -> -0.40632054 | F44: =+F16/E16 -1 -> 0.1513308 | G44: =+G16/F16 -1 -> 0.66842801 | H44: =+H16/G16 -1 -> 0.01821061 | I44: =+I16/H16 -1 -> 0.069817263 | V44: NPV | W44: =NPV(W42,J52:CD52) -> 766616.79
B45: AMS Share | C45: =+C11/C24 -> 0.40812927 | D45: =+D11/D24 -> 0.50263219 | E45: =+E11/E24 -> 0.54849756 | F45: =+F11/F24 -> 0.48290536 | G45: =+G11/G24 -> 0.49617049 | H45: =+H11/H24 -> 0.56104501 | I45: =+I11/I24 -> 0.50903923 | J45: =+J11/J24 -> 0.55056294 | ... T45: =+T11/T24 -> 0.64160312 | V45: Net Cash | W45: =281900-45786-272911 -> -36797
B46: OE Share | C46: =+C16/C24 -> 0.59184693 | D46: =+D16/D24 -> 0.49746663 | E46: =+E16/E24 -> 0.45164326 | F46: =+F16/F24 -> 0.51705708 | G46: =+G16/G24 -> 0.50395121 | H46: =+H16/H24 -> 0.43900449 | I46: =+I16/I24 -> 0.49096077 | J46: =+J16/J24 -> 0.44943706 | ... T46: =+T16/T24 -> 0.35839688 | V46: Value | W46: =+W44+W45 -> 729819.79
V47: Price | W47: =+W46/T38 -> 46.309934
B48: D&A | H48: 94209 | I48: 63608 | J48: =+SUM(C51:I51)/7 -> 28710.429 | K48: =+SUM(D51:J51)/7 -> 28577.34 | L48: =+SUM(E51:K51)/7 -> 29145.675 | M48: =+SUM(F51:L51)/7 -> 31990.986 | N48: =+SUM(G51:M51)/7 -> 34493.006 | O48: =+SUM(H51:N51)/7 -> 35680.937 | P48: =+SUM(I51:O51)/7 -> 36076.453 | Q48: =+SUM(J51:P51)/7 -> 36797.982 | ... T48: =+SUM(M51:S51)/7 -> 39050.313
...

Sheet Factors
B3: Rig Norm | C3: 800
B4: Mean Reversion | C4: 0.35
B5: Oil Sens. | C5: 0.8
B6: WTI norm | C6: 80
B7: Inflation | C7: 0.02
B8: Beta | C8: 0.6
