Workbook

Sheet main
C4: Price | D4: 34.3
C5: Price USD | D5: =+(D4/[1]!EURNOK)*[1]!EURUSD -> 3.5875913
C6: Shares | D6: 2496.4062
C7: MC | D7: =+D5*D6 -> 8956.0853
C8: Net Cash | D8: =+Model!R48 -> -5242 | E8: FY25
C9: EV | D9: =+D7-D8 -> 14198.085
C11: EV/FCF | D11: =+D9/Model!E54 -> 7.9434291
C12: FCF Yield | D12: =1/D11 -> 0.12589021
C14: Fwd DpS | D14: =1.21*4 -> 4.84
C15: Div Yield | D15: =+D14/D4 -> 0.14110787

Sheet Model
A1: USD
D2: 2024 | E2: =+D2+1 -> 2025 | F2: 2026 | G2: =+F2+1 -> 2027 | H2: =+G2+1 -> 2028 | I2: =+H2+1 -> 2029 | J2: =+I2+1 -> 2030 | K2: =+J2+1 -> 2031 | L2: =+K2+1 -> 2032 | M2: =+L2+1 -> 2033 | N2: =+M2+1 -> 2034 | O2: =+N2+1 -> 2035
B4: Production | D4: =+SUM(D5:D7) -> 280 | E4: =+SUM(E5:E7) -> 333 | F4: =+F5+F6+F7 -> 437.5 | G4: =+G5+G6+G7 -> 436.5 | H4: =+H5+H6+H7 -> 422 | I4: =+I5+I6+I7 -> 416.5 | J4: =+J5+J6+J7 -> 400.3 | K4: =+K5+K6+K7 -> 373.9 | L4: =+L5+L6+L7 -> 359 | M4: =+M5+M6+M7 -> 323.1 | ... O4: =+O5+O6+O7 -> 271.8
B5: Oil | D5: 161 | E5: 214 | F5: =+'Detailed Production'!H5 -> 282.5 | G5: =+'Detailed Production'!I5 -> 283 | H5: =+'Detailed Production'!J5 -> 274.75 | I5: =+'Detailed Production'!K5 -> 275.5 | J5: =+'Detailed Production'!L5 -> 267.15 | K5: =+'Detailed Production'!M5 -> 250.8 | L5: =+'Detailed Production'!N5 -> 245.45 | M5: =+'Detailed Production'!O5 -> 219.1 | ... O5: =+'Detailed Production'!Q5 -> 186.65
B6: Gas | D6: 100 | E6: 101 | F6: =+'Detailed Production'!H6 -> 137.5 | G6: =+'Detailed Production'!I6 -> 136.5 | H6: =+'Detailed Production'!J6 -> 130.75 | I6: =+'Detailed Production'!K6 -> 125 | J6: =+'Detailed Production'!L6 -> 117.65 | K6: =+'Detailed Production'!M6 -> 108.1 | L6: =+'Detailed Production'!N6 -> 99.05 | M6: =+'Detailed Production'!O6 -> 90 | ... O6: =+'Detailed Production'!Q6 -> 72.15
B7: NGL | D7: 19 | E7: 18 | F7: =+E7-0.5 -> 17.5 | G7: =+F7-0.5 -> 17 | H7: =+G7-0.5 -> 16.5 | I7: =+H7-0.5 -> 16 | J7: =+I7-0.5 -> 15.5 | K7: =+J7-0.5 -> 15 | L7: =+K7-0.5 -> 14.5 | M7: =+L7-0.5 -> 14 | ... O7: =+N7-0.5 -> 13
B9: Sales | D9: =+SUM(D10:D12) -> 97.7 | E9: =+SUM(E10:E12) -> 116.1 | F9: =+SUM(F10:F12) -> 149.9125 | G9: =+SUM(G10:G12) -> 149.6045 | H9: =+SUM(H10:H12) -> 144.65225 | I9: =+SUM(I10:I12) -> 142.85 | J9: =+SUM(J10:J12) -> 137.32995 | K9: =+SUM(K10:K12) -> 128.2773 | ... O9: =+SUM(O10:O12) -> 93.25345
B10: Oil | D10: 56.3 | E10: 77.3 | F10: =+F5*0.35 -> 98.875 | G10: =+G5*0.35 -> 99.05 | H10: =+H5*0.35 -> 96.1625 | I10: =+I5*0.35 -> 96.425 | J10: =+J5*0.35 -> 93.5025 | K10: =+K5*0.35 -> 87.78 | L10: =+L5*0.35 -> 85.9075 | M10: =+M5*0.35 -> 76.685 | ... O10: =+O5*0.35 -> 65.3275
B11: Gas | D11: 33.4 | E11: 33.4 | F11: =+F6*0.333 -> 45.7875 | G11: =+G6*0.333 -> 45.4545 | H11: =+H6*0.333 -> 43.53975 | I11: =+I6*0.333 -> 41.625 | J11: =+J6*0.333 -> 39.17745 | K11: =+K6*0.333 -> 35.9973 | L11: =+L6*0.333 -> 32.98365 | M11: =+M6*0.333 -> 29.97 | ... O11: =+O6*0.333 -> 24.02595
B12: NGL | D12: 8 | E12: 5.4 | F12: =+F7*0.3 -> 5.25 | G12: =+G7*0.3 -> 5.1 | H12: =+H7*0.3 -> 4.95 | I12: =+I7*0.3 -> 4.8 | J12: =+J7*0.3 -> 4.65 | K12: =+K7*0.3 -> 4.5 | L12: =+L7*0.3 -> 4.35 | M12: =+M7*0.3 -> 4.2 | ... O12: =+O7*0.3 -> 3.9
B14: Realized Price
B15: Oil | D15: 81 | E15: 68.3 | F15: 70 | G15: 72 | H15: 75 | I15: 78 | J15: 80 | K15: =+J15*1.02 -> 81.6 | L15: =+K15*1.02 -> 83.232 | M15: =+L15*1.02 -> 84.89664 | N15: =+M15*1.02 -> 86.594573 | O15: =+N15*1.02 -> 88.326464
B16: Gas | D16: 72.6 | E16: 74.7 | F16: =+E16*1.02 -> 76.194 | G16: =+F16*1.02 -> 77.71788 | H16: =+G16*1.02 -> 79.272238 | I16: =+H16*1.02 -> 80.857682 | J16: =+I16*1.02 -> 82.474836 | K16: =+J16*1.02 -> 84.124333 | L16: =+K16*1.02 -> 85.806819 | M16: =+L16*1.02 -> 87.522956 | ... O16: =+N16*1.02 -> 91.058883
B17: NGL | D17: 47.3 | E17: 43.3 | F17: 40 | G17: 40 | H17: 40 | I17: 40 | J17: 40 | K17: 40 | L17: 40 | M17: 40 | N17: 40 | O17: 40
B19: Production Cost | D19: 12.8 | E19: 11.1 | F19: 10 | G19: =+F19*1.05 -> 10.5 | H19: =+G19*1.05 -> 11.025 | I19: =+H19*1.05 -> 11.57625 | J19: =+I19*1.05 -> 12.155063 | K19: =+J19*1.05 -> 12.762816 | L19: =+K19*1.05 -> 13.400956 | M19: =+L19*1.05 -> 14.071004 | N19: =+M19*1.05 -> 14.774554 | O19: =+N19*1.05 -> 15.513282
B20: Dividend pS | D20: 0.43 | E20: 0.47
B21: Dividend | D21: =+D20*main!$D$6 -> 1073.4547 | E21: =+E20*main!$D$6 -> 1173.3109 | F21: =300*4 -> 1200
B23: Dev. CapEx | F23: 2600
B24: Exp. CapEx | F24: 275
B27: Oil | D27: 4558 | E27: 5274 | F27: =+F15*F10 -> 6921.25 | G27: =+G15*G10 -> 7131.6 | H27: =+H15*H10 -> 7212.1875 | I27: =+I15*I10 -> 7521.15 | J27: =+J15*J10 -> 7480.2 | K27: =+K15*K10 -> 7162.848 | L27: =+L15*L10 -> 7150.253 | M27: =+M15*M10 -> 6510.2988 | ... O27: =+O15*O10 -> 5770.1471
B28: Gas | D28: 2428 | E28: 2457 | F28: =+F16*F11 -> 3488.7328 | G28: =+G16*G11 -> 3532.6274 | H28: =+H16*H11 -> 3451.4934 | I28: =+I16*I11 -> 3365.701 | J28: =+J16*J11 -> 3231.1538 | K28: =+K16*K11 -> 3028.2488 | L28: =+L16*L11 -> 2830.2221 | M28: =+M16*M11 -> 2623.063 | ... O28: =+O16*O11 -> 2187.7762
B29: NGL | D29: 379 | E29: 235 | F29: =+F17*F12 -> 210 | G29: =+G17*G12 -> 204 | H29: =+H17*H12 -> 198 | I29: =+I17*I12 -> 192 | J29: =+J17*J12 -> 186 | K29: =+K17*K12 -> 180 | L29: =+L17*L12 -> 174 | M29: =+M17*M12 -> 168 | ... O29: =+O17*O12 -> 156
B30: Petro Revenue | D30: =+SUM(D27:D29) -> 7365 | E30: =+SUM(E27:E29) -> 7966 | F30: =+SUM(F27:F29) -> 10619.983 | G30: =+SUM(G27:G29) -> 10868.227 | H30: =+SUM(H27:H29) -> 10861.681 | I30: =+SUM(I27:I29) -> 11078.851 | J30: =+SUM(J27:J29) -> 10897.354 | K30: =+SUM(K27:K29) -> 10371.097 | ... O30: =+SUM(O27:O29) -> 8113.9233
B31: Other Income | D31: 77.7 | E31: 130 | F31: 100 | G31: 100 | H31: 100 | I31: 100 | J31: 100 | K31: 100 | L31: 100 | M31: 100 | N31: 100 | O31: 100
B32: Total Revenue | D32: =+D30+D31 -> 7442.7 | E32: =+E30+E31 -> 8096 | F32: =+F30+F31 -> 10719.983 | G32: =+G30+G31 -> 10968.227 | H32: =+H30+H31 -> 10961.681 | I32: =+I30+I31 -> 11178.851 | J32: =+J30+J31 -> 10997.354 | K32: =+K30+K31 -> 10471.097 | ... O32: =+O30+O31 -> 8213.9233
B33: Production Cost | D33: 1402.9 | E33: 1295 | F33: =+F19*F9 -> 1499.125 | G33: =+G19*G9 -> 1570.8473 | H33: =+H19*H9 -> 1594.7911 | I33: =+I19*I9 -> 1653.6673 | J33: =+J19*J9 -> 1669.2541 | K33: =+K19*K9 -> 1637.1795 | L33: =+L19*L9 -> 1651.5493 | M33: =+M19*M9 -> 1559.8412 | ... O33: =+O19*O9 -> 1446.6671
B34: Exploration Cost | D34: 192.4 | E34: 245.4 | F34: =+E34*1.03 -> 252.762 | G34: =+F34*1.03 -> 260.34486 | H34: =+G34*1.03 -> 268.15521 | I34: =+H34*1.03 -> 276.19986 | J34: =+I34*1.03 -> 284.48586 | K34: =+J34*1.03 -> 293.02043 | L34: =+K34*1.03 -> 301.81105 | M34: =+L34*1.03 -> 310.86538 | ... O34: =+N34*1.03 -> 329.79708
B35: D&A | D35: 1915.9 | E35: 2710.1 | F35: 3000 | G35: 3000 | H35: 3000 | I35: 3000 | J35: 3000 | K35: 3000 | L35: 3000 | M35: 3000 | N35: 3000 | O35: 3000
B36: Impairment, net | D36: -3.8 | E36: 550.6
B37: Other expenses | D37: 144.6 | E37: 211 | F37: 200 | G37: =+F37*1.02 -> 204 | H37: =+G37*1.02 -> 208.08 | I37: =+H37*1.02 -> 212.2416 | J37: =+I37*1.02 -> 216.48643 | K37: =+J37*1.02 -> 220.81616 | L37: =+K37*1.02 -> 225.23248 | M37: =+L37*1.02 -> 229.73713 | N37: =+M37*1.02 -> 234.33188 | O37: =+N37*1.02 -> 239.01851
B38: Operating Income | D38: =+D32-D33-D34-D35+D36-D37 -> 3783.1 | E38: =+E32-E33-E34-E35+E36-E37 -> 4185.1 | F38: =+F32-F33-F34-F35+F36-F37 -> 5768.0958 | G38: =+G32-G33-G34-G35+G36-G37 -> 5933.0353 | H38: =+H32-H33-H34-H35+H36-H37 -> 5890.6546 | I38: =+I32-I33-I34-I35+I36-I37 -> 6036.7423 | J38: =+J32-J33-J34-J35+J36-J37 -> 5827.1273 | K38: =+K32-K33-K34-K35+K36-K37 -> 5320.0807 | ... O38: =+O32-O33-O34-O35+O36-O37 -> 3198.4406
B39: Net Finance | D39: -106.9 | E39: -310 | F39: =-F65*F68 -> -311.94975 | G39: =-G65*G68 -> -294.79251 | H39: =-H65*H68 -> -288.89666 | I39: =-I65*I68 -> -288.89666 | J39: =-J65*J68 -> -265.42381 | K39: =-K65*K68 -> -238.88143 | L39: =-L65*L68 -> -250.8255 | M39: =-M65*M68 -> -263.36678 | ... O39: =-O65*O68 -> -290.36187
B40: Net exchange | D40: -370.4 | E40: 431.8
B41: Pretax | D41: =+D38+D39+D40 -> 3305.8 | E41: =+E38+E39+E40 -> 4306.9 | F41: =+F38+F39+F40 -> 5456.146 | G41: =+G38+G39+G40 -> 5638.2428 | H41: =+H38+H39+H40 -> 5601.758 | I41: =+I38+I39+I40 -> 5747.8456 | J41: =+J38+J39+J40 -> 5561.7035 | K41: =+K38+K39+K40 -> 5081.1993 | ... O41: =+O38+O39+O40 -> 2908.0787
B42: Taxes | D42: 2986 | E42: 3460.1 | F42: =+F41*0.78 -> 4255.7939 | G42: =+G41*0.78 -> 4397.8293 | H42: =+H41*0.78 -> 4369.3712 | I42: =+I41*0.78 -> 4483.3196 | J42: =+J41*0.78 -> 4338.1288 | K42: =+K41*0.78 -> 3963.3354 | L42: =+L41*0.78 -> 3763.5443 | M42: =+M41*0.78 -> 3149.2901 | ... O42: =+O41*0.78 -> 2268.3014
B43: Net Income | D43: =+D41-D42 -> 319.8 | E43: =+E41-E42 -> 846.8 | F43: =+F41-F42 -> 1200.3521 | G43: =+G41-G42 -> 1240.4134 | H43: =+H41-H42 -> 1232.3868 | I43: =+I41-I42 -> 1264.526 | J43: =+J41-J42 -> 1223.5748 | K43: =+K41-K42 -> 1117.8638 | ... O43: =+O41-O42 -> 639.77732 | FL43: =+FK43*(1+$R46) -> 0
B44: Hybrid Capital Div. | D44: 15.6 | E44: 61.3 | F44: =+F43*0.06 -> 72.021128 | G44: =+G43*0.06 -> 74.424804 | H44: =+H43*0.06 -> 73.943205 | I44: =+I43*0.06 -> 75.871562 | J44: =+J43*0.06 -> 73.414487 | K44: =+K43*0.06 -> 67.071831 | L44: =+L43*0.06 -> 63.69075 | M44: =+M43*0.06 -> 53.295678 | ... O44: =+O43*0.06 -> 38.386639
B45: Shareholder | D45: =+D43-D44 -> 304.2 | E45: =+E43-E44 -> 785.5 | F45: =+F43-F44 -> 1128.331 | G45: =+G43-G44 -> 1165.9886 | H45: =+H43-H44 -> 1158.4436 | I45: =+I43-I44 -> 1188.6545 | J45: =+J43-J44 -> 1150.1603 | K45: =+K43-K44 -> 1050.792 | ... O45: =+O43-O44 -> 601.39068 | Q45: Discount | R45: 0.1
Q46: Terminal | R46: 0.01
B47: Operating Margin | D47: =+D38/D32 -> 0.50829672 | E47: =+E38/E32 -> 0.51693429 | F47: =+F38/F32 -> 0.5380695 | G47: =+G38/G32 -> 0.54092927 | H47: =+H38/H32 -> 0.53738607 | I47: =+I38/I32 -> 0.54001455 | J47: =+J38/J32 -> 0.52986632 | K47: =+K38/K32 -> 0.50807292 | ... O47: =+O38/O32 -> 0.38939256 | Q47: NPV | R47: =NPV(R45,F55:FX55) -> 17223.7
...

Sheet Detailed Production
A1: kboepd
D2: Q125 | E2: Q225 | F2: Q325 | G2: Q425 | H2: 2026 | I2: =+H2+1 -> 2027 | J2: =+I2+1 -> 2028 | K2: =+J2+1 -> 2029 | L2: =+K2+1 -> 2030 | M2: =+L2+1 -> 2031 | N2: =+M2+1 -> 2032 | O2: =+N2+1 -> 2033 | P2: =+O2+1 -> 2034 | Q2: =+P2+1 -> 2035
B4: Total | D4: =+D5+D6 -> 272 | E4: =+E5+E6 -> 289 | F4: =+F5+F6 -> 368 | G4: =+G5+G6 -> 401 | H4: =+H5+H6 -> 420 | I4: =+I5+I6 -> 419.5 | J4: =+J5+J6 -> 405.5 | K4: =+K5+K6 -> 400.5 | ... Q4: =+Q5+Q6 -> 258.8
B5: Total Oil | D5: =+SUM(D12:D15)+D17+D18+D22+D23+D27+D26/2+D29/2+D37+D38/2+D39/2 -> 155.5 | E5: =+SUM(E12:E15)+E17+E18+E22+E23+E27+E26/2+E29/2+E37+E38/2+E39/2 -> 167.5 | F5: =+SUM(F12:F15)+F17+F18+F22+F23+F27+F26/2+F29/2+F37+F38/2+F39/2 -> 248.5 | G5: =+SUM(G12:G15)+G17+G18+G22+G23+G27+G26/2+G29/2+G37+G38/2+G39/2 -> 252 | H5: =+SUM(H12:H15)+H17+H18+H22+H23+H27+H26/2+H29/2+H37+H38/2+H39/2 -> 282.5 | I5: =+SUM(I12:I15)+I17+I18+I22+I23+I27+I26/2+I29/2+I37+I38/2+I39/2 -> 283 | J5: =+SUM(J12:J15)+J17+J18+J22+J23+J27+J26/2+J29/2+J37+J38/2+J39/2 -> 274.75 | K5: =+SUM(K12:K15)+K17+K18+K22+K23+K27+K26/2+K29/2+K37+K38/2+K39/2 -> 275.5 | ... Q5: =+SUM(Q12:Q15)+Q17+Q18+Q22+Q23+Q27+Q26/2+Q29/2+Q37+Q38/2+Q39/2 -> 186.65
B6: Total Gas | D6: =+D19+D24+D25+D26/2+D28+D29/2+D32+D33+D34+D35+D36+D38/2+D39/2 -> 116.5 | E6: =+E19+E24+E25+E26/2+E28+E29/2+E32+E33+E34+E35+E36+E38/2+E39/2 -> 121.5 | F6: =+F19+F24+F25+F26/2+F28+F29/2+F32+F33+F34+F35+F36+F38/2+F39/2 -> 119.5 | G6: =+G19+G24+G25+G26/2+G28+G29/2+G32+G33+G34+G35+G36+G38/2+G39/2 -> 149 | H6: =+H19+H24+H25+H26/2+H28+H29/2+H32+H33+H34+H35+H36+H38/2+H39/2 -> 137.5 | I6: =+I19+I24+I25+I26/2+I28+I29/2+I32+I33+I34+I35+I36+I38/2+I39/2 -> 136.5 | J6: =+J19+J24+J25+J26/2+J28+J29/2+J32+J33+J34+J35+J36+J38/2+J39/2 -> 130.75 | K6: =+K19+K24+K25+K26/2+K28+K29/2+K32+K33+K34+K35+K36+K38/2+K39/2 -> 125 | ... Q6: =+Q19+Q24+Q25+Q26/2+Q28+Q29/2+Q32+Q33+Q34+Q35+Q36+Q38/2+Q39/2 -> 72.15
B8: new Oil | J8: 0.5 | K8: 8.75 | L8: 31 | M8: 31.75 | N8: 29.13 | O8: 26.5 | P8: 23.88 | Q8: 21.25
B9: new Gas | J9: 3 | K9: 14.25 | L9: 19 | M9: 17.25 | N9: 15.38 | O9: 13.5 | P9: 11.63 | Q9: 9.75
B11: Balder Area | D11: =+SUM(D12:D14) -> 64 | E11: =+SUM(E12:E14) -> 63 | F11: =+SUM(F12:F14) -> 97 | G11: =+SUM(G12:G14) -> 114 | H11: =+SUM(H12:H14) -> 128 | I11: =+SUM(I12:I14) -> 132 | J11: =+SUM(J12:J14) -> 130 | K11: =+SUM(K12:K14) -> 125 | ... Q11: =+SUM(Q12:Q14) -> 86
A12: Oil | B12: Balder/Ringhorne | D12: 25 | E12: 27 | F12: 59 | G12: 81 | H12: 95 | I12: 100 | J12: 100 | K12: 97 | L12: 93 | M12: 88 | N12: 93 | O12: 78 | P12: 73 | Q12: 68
A13: Oil | B13: Grane/Svalin | D13: 12 | E13: 10 | F13: 11 | G13: 6 | H13: 9 | I13: 8 | J13: 7 | K13: 6 | L13: 5 | M13: 4 | N13: 3.5 | O13: 3 | P13: 2.5 | Q13: 2
A14: Oil | B14: Breidablikk | D14: 27 | E14: 26 | F14: 27 | G14: 27 | H14: 24 | I14: 24 | J14: 23 | K14: 22 | L14: 21 | M14: 20 | N14: 19 | O14: 18 | P14: 17 | Q14: 16
B16: Barents Sea | D16: =+SUM(D17:D19) -> 27 | E16: =+SUM(E17:E19) -> 37 | F16: =+SUM(F17:F19) -> 89 | G16: =+SUM(G17:G19) -> 79 | H16: =+SUM(H17:H19) -> 94 | I16: =+SUM(I17:I19) -> 94 | J16: =+SUM(J17:J19) -> 93 | K16: =+SUM(K17:K19) -> 97 | ... Q16: =+SUM(Q17:Q19) -> 75
A17: Oil | B17: Goliat | D17: 14 | E17: 13 | F17: 16 | G17: 15 | H17: 16 | I17: 16 | J17: 15 | K17: 19 | L17: 20 | M17: 19 | N17: 18 | O17: 17 | P17: 16 | Q17: 15
A18: Oil | B18: Johan Castberg | E18: 20 | F18: 64 | G18: 47 | H18: 66 | I18: =+H18+0 -> 66 | J18: =+I18+0 -> 66 | K18: =+J18+0 -> 66 | L18: =+K18+0 -> 66 | M18: =+L18-3 -> 63 | N18: =+M18-3 -> 60 | O18: =+N18-3 -> 57 | P18: =+O18-3 -> 54 | Q18: =+P18-3 -> 51
A19: Gas | B19: Snohvit | D19: 13 | E19: 4 | F19: 9 | G19: 17 | H19: 12 | I19: =+H19+0 -> 12 | J19: =+I19+0 -> 12 | K19: =+J19+0 -> 12 | L19: =+K19+0 -> 12 | M19: 11 | N19: 10.5 | O19: 10 | P19: 9.5 | Q19: 9
B21: North Sea | D21: =+SUM(D22:D29) -> 91 | E21: =+SUM(E22:E29) -> 84 | F21: =+SUM(F22:F29) -> 80 | G21: =+SUM(G22:G29) -> 92 | H21: =+SUM(H22:H29) -> 85 | I21: =+SUM(I22:I29) -> 80.5 | J21: =+SUM(J22:J29) -> 75 | K21: =+SUM(K22:K29) -> 76.5 | ... Q21: =+SUM(Q22:Q29) -> 40.8
A22: Oil | B22: Ekofisk Area | D22: 21 | E22: 15 | F22: 21 | G22: 21 | H22: 19 | I22: 18 | J22: 17 | K22: 22 | L22: 23 | M22: 22 | N22: 21 | O22: 19 | P22: 17 | Q22: 15
A23: Oil | B23: Snorre | D23: 16 | E23: 17 | F23: 16 | G23: 16 | H23: 16 | I23: 16 | J23: 15 | K23: 15 | L23: 14 | M23: 13 | N23: 12 | O23: 11 | P23: 10 | Q23: 9
A24: Gas | B24: Gjoa Area | D24: 15 | E24: 15 | F24: 11 | G24: 16 | H24: 14 | I24: 13 | J24: 12 | K24: 11 | L24: 10 | M24: 9 | N24: =+M24-1 -> 8 | O24: =+N24-1 -> 7 | P24: =+O24-1 -> 6 | Q24: =+P24-1 -> 5
A25: Gas | B25: Gudrun | D25: 6 | E25: 7 | F25: 4 | G25: 6 | H25: =+G25-0.5 -> 5.5 | I25: =+H25-0.5 -> 5 | J25: =+I25-0.5 -> 4.5 | K25: =+J25-0.5 -> 4 | L25: =+K25-0.5 -> 3.5 | M25: =+L25-0.5 -> 3 | N25: =+M25-0.5 -> 2.5 | O25: =+N25-0.5 -> 2 | ... Q25: =+P25-0.5 -> 1
A26: Mix | B26: Statfjord Area | D26: 12 | E26: 10 | F26: 10 | G26: 10 | H26: 10 | I26: =+H26-1 -> 9 | J26: =+I26-1 -> 8 | K26: =+J26-1 -> 7 | L26: =+K26-1 -> 6 | M26: =+L26-1 -> 5 | N26: =+M26-1 -> 4 | O26: =+N26-1 -> 3 | P26: =+O26-1 -> 2 | Q26: 1.5
A27: Oil | B27: Fram | D27: 13 | E27: 12 | F27: 11 | G27: 13 | H27: 12 | I27: 11 | J27: =+I27-1 -> 10 | K27: =+J27-1 -> 9 | L27: =+K27-1 -> 8 | M27: =+L27-1 -> 7 | N27: =+M27-1 -> 6 | O27: =+N27-1 -> 5 | P27: =+O27-1 -> 4 | Q27: =+P27-1 -> 3
A28: Gas | B28: Sleipner Area | D28: 3 | E28: 3 | F28: 2 | G28: 4 | H28: 3.5 | I28: =+H28+0 -> 3.5 | J28: =+I28+0 -> 3.5 | K28: =+J28+0 -> 3.5 | L28: =+K28+0 -> 3.5 | M28: =+L28-0.2 -> 3.3 | N28: =+M28-0.2 -> 3.1 | O28: =+N28-0.2 -> 2.9 | P28: =+O28-0.2 -> 2.7 | Q28: =+P28-0.2 -> 2.5
A29: Mix | B29: Other | D29: 5 | E29: 5 | F29: 5 | G29: 6 | H29: 5 | I29: 5 | J29: 5 | K29: 5 | L29: =+K29-0.2 -> 4.8 | M29: =+L29-0.2 -> 4.6 | N29: =+M29-0.2 -> 4.4 | O29: =+N29-0.2 -> 4.2 | P29: =+O29-0.2 -> 4 | Q29: =+P29-0.2 -> 3.8
B31: Norwegian Sea | D31: =+SUM(D32:D39) -> 90 | E31: =+SUM(E32:E39) -> 105 | F31: =+SUM(F32:F39) -> 102 | G31: =+SUM(G32:G39) -> 116 | H31: =+SUM(H32:H39) -> 113 | I31: =+SUM(I32:I39) -> 113 | J31: =+SUM(J32:J39) -> 107.5 | K31: =+SUM(K32:K39) -> 102 | ... Q31: =+SUM(Q32:Q39) -> 57
A32: Gas | B32: Asgard Area | D32: 32 | E32: 36 | F32: 36 | G32: 45 | H32: 42 | I32: 43 | J32: 43 | K32: 42 | L32: 41 | M32: 39 | N32: 37 | O32: 35 | P32: 33 | Q32: 31
A33: Gas | B33: Mikkel | D33: 10 | E33: 10 | F33: 7 | G33: 13 | H33: 11 | I33: 11 | J33: 10 | K33: 10 | L33: 9 | M33: 8 | N33: 7 | O33: 6 | P33: 5 | Q33: 4
A34: Gas | B34: Tyrihans | D34: 13 | E34: 13 | F34: 11 | G34: 11 | H34: 12 | I34: 12 | J34: 11 | K34: 10 | L34: 9 | M34: 8 | N34: 7 | O34: 6 | P34: 5 | Q34: 4
A35: Gas | B35: Halten Ost | D35: 1 | E35: 11 | F35: 13 | G35: 7 | H35: 10 | I35: 10 | J35: =+I35-1 -> 9 | K35: =+J35-1 -> 8 | L35: =+K35-1 -> 7 | M35: =+L35-1 -> 6 | N35: =+M35-1 -> 5 | O35: =+N35-1 -> 4 | P35: =+O35-1 -> 3 | Q35: =+P35-1 -> 2
A36: Gas | B36: Orman Lange | D36: 8 | E36: 6 | F36: 10 | G36: 11 | H36: 10 | I36: 10 | J36: 10 | K36: 10 | L36: =+K36-0.5 -> 9.5 | M36: =+L36-0.5 -> 9 | N36: =+M36-0.5 -> 8.5 | O36: =+N36-0.5 -> 8 | P36: =+O36-0.5 -> 7.5 | Q36: =+P36-0.5 -> 7
A37: Oil | B37: Fenja | D37: 12 | E37: 11 | F37: 7 | G37: 7 | H37: 8 | I37: 7 | J37: 6 | K37: 5 | L37: =+K37-1 -> 4 | M37: =+L37-1 -> 3 | N37: =+M37-0.5 -> 2.5 | O37: =+N37-0.5 -> 2 | P37: =+O37-0.5 -> 1.5 | Q37: =+P37-0.5 -> 1
A38: Mix | B38: Njord Area | D38: 6 | E38: 9 | F38: 10 | G38: 13 | H38: 11 | I38: 11 | J38: 10 | K38: 9 | L38: 8 | M38: 7 | N38: 6 | O38: 5 | P38: 4 | Q38: 3
A39: Mix | B39: Other | D39: 8 | E39: 9 | F39: 8 | G39: 9 | H39: 9 | I39: 9 | J39: =+I39-0.5 -> 8.5 | K39: =+J39-0.5 -> 8 | L39: =+K39-0.5 -> 7.5 | M39: =+L39-0.5 -> 7 | N39: =+M39-0.5 -> 6.5 | O39: =+N39-0.5 -> 6 | P39: =+O39-0.5 -> 5.5 | Q39: =+P39-0.5 -> 5
B41: Total Injury 12M | D41: 3.3 | E41: 2.7 | F41: 3 | G41: 3
B42: Serious Incident | D42: 0 | E42: 0 | F42: 0 | G42: 0
B43: CO2 emissions | D43: 9.9 | E43: 10.6 | F43: 9.5 | G43: 8.6

Sheet Graphs

Sheet Map
